Workbook
Name CROCLAS: '[1]6-CRO'!$B$4:$E$61
Name DATOS5: '[2]55555'!$B$1:$AA$65536
Name DRSCLAS: '[1]1-DRS'!$B$4:$E$81
Name INSCRIP: '[2]W-Inscripcions'!$C$1:$M$65536
Name POSCURSA: [2]TicTacSlot!$O$1:$AX$61
Name POSMANEGA: [2]TicTacSlot!$N$62:$S$142
Name S4UCLAS: '[1]2-S4U'!$B$4:$E$83
Name SLCCLAS: '[1]5-SLC'!$B$4:$E$61
Name SLMCLAS: '[1]4-SLM'!$B$4:$E$65
Name SOTCLAS: '[1]3-SOT'!$B$4:$E$83
Name T_CARS: [2]Tablas!$A$1:$F$65536
Name T_MARCAS: [2]Tablas!$H$1:$I$65536
Name TICTACSLOT: [2]TicTacSlot!$A$1:$J$65536

Sheet Inscritos_Mangas_ELSOT
B5: PITLOTOS INSCRITOS | G5: JUEVES
B7: # | C7: PILOTOS | D7: PTOS. | E7: DIA | G7: # | H7: PILOTO | I7: P SALIDA | J7: PTOS. | L7: # | M7: PILOTO | N7: P SALIDA | O7: PTOS.
B8: 1 | C8: Jose Maria Martinez | D8: =IFERROR(VLOOKUP(Tabla13151617[[#This Row],[PILOTOS]],Clasificacion_final_2019!$C$3:$I$43,7,0),0) -> 0 | E8: Jueves | G8: 1 | H8: Carles Carreño | J8: =IFERROR(VLOOKUP(H8,Tabla13151617[[PILOTOS]:[PTOS.]],2,0),0) -> 188 | L8: 1 | M8: Jose Maria Martinez | O8: =IFERROR(VLOOKUP(M8,Tabla13151617[[PILOTOS]:[PTOS.]],2,0),0) -> 0
B9: =+B8+1 -> 2 | C9: Oscar Capel | D9: =IFERROR(VLOOKUP(Tabla13151617[[#This Row],[PILOTOS]],Clasificacion_final_2019!$C$3:$I$43,7,0),0) -> 0 | E9: Jueves | G9: 2 | H9: Richard Arredondo | J9: =IFERROR(VLOOKUP(H9,Tabla13151617[[PILOTOS]:[PTOS.]],2,0),0) -> 154 | L9: 2 | M9: Oscar Capel | O9: =IFERROR(VLOOKUP(M9,Tabla13151617[[PILOTOS]:[PTOS.]],2,0),0) -> 0
B10: =+B9+1 -> 3 | C10: Alberto Bolsa | D10: =IFERROR(VLOOKUP(Tabla13151617[[#This Row],[PILOTOS]],Clasificacion_final_2019!$C$3:$I$43,7,0),0) -> 0 | E10: Jueves | G10: 3 | H10: David Izquierdo | J10: =IFERROR(VLOOKUP(H10,Tabla13151617[[PILOTOS]:[PTOS.]],2,0),0) -> 151 | L10: 3 | M10: Alberto Bolsa | O10: =IFERROR(VLOOKUP(M10,Tabla13151617[[PILOTOS]:[PTOS.]],2,0),0) -> 0
B11: =+B10+1 -> 4 | C11: Jose Luis Cortijos | D11: =IFERROR(VLOOKUP(Tabla13151617[[#This Row],[PILOTOS]],Clasificacion_final_2019!$C$3:$I$43,7,0),0) -> 0 | E11: Jueves | G11: 4 | H11: Marc Casanovas | J11: =IFERROR(VLOOKUP(H11,Tabla13151617[[PILOTOS]:[PTOS.]],2,0),0) -> 147 | L11: 4 | M11: Jose Luis Cortijos | O11: =IFERROR(VLOOKUP(M11,Tabla13151617[[PILOTOS]:[PTOS.]],2,0),0) -> 0
B12: =+B11+1 -> 5 | C12: Sergi Martinez | D12: =IFERROR(VLOOKUP(Tabla13151617[[#This Row],[PILOTOS]],Clasificacion_final_2019!$C$3:$I$43,7,0),0) -> 0 | E12: Jueves | G12: 5 | H12: Jordi Simo | J12: =IFERROR(VLOOKUP(H12,Tabla13151617[[PILOTOS]:[PTOS.]],2,0),0) -> 138 | L12: 5 | M12: Sergi Martinez | O12: =IFERROR(VLOOKUP(M12,Tabla13151617[[PILOTOS]:[PTOS.]],2,0),0) -> 0
B13: =+B12+1 -> 6 | C13: Luis Aldea | D13: =IFERROR(VLOOKUP(Tabla13151617[[#This Row],[PILOTOS]],Clasificacion_final_2019!$C$3:$I$43,7,0),0) -> 0 | E13: Jueves | G13: 6 | H13: Manel Soriano | J13: =IFERROR(VLOOKUP(H13,Tabla13151617[[PILOTOS]:[PTOS.]],2,0),0) -> 126 | L13: 6 | M13: Luis Aldea | O13: =IFERROR(VLOOKUP(M13,Tabla13151617[[PILOTOS]:[PTOS.]],2,0),0) -> 0
B14: =+B13+1 -> 7 | C14: David Mercader | D14: =IFERROR(VLOOKUP(Tabla13151617[[#This Row],[PILOTOS]],Clasificacion_final_2019!$C$3:$I$43,7,0),0) -> 0 | E14: Jueves | G14: 7 | H14: Victor Gonzalez | J14: =IFERROR(VLOOKUP(H14,Tabla13151617[[PILOTOS]:[PTOS.]],2,0),0) -> 111 | L14: 7 | M14: David Mercader | O14: =IFERROR(VLOOKUP(M14,Tabla13151617[[PILOTOS]:[PTOS.]],2,0),0) -> 0
B15: =+B14+1 -> 8 | C15: Xavier Vernet | D15: =IFERROR(VLOOKUP(Tabla13151617[[#This Row],[PILOTOS]],Clasificacion_final_2019!$C$3:$I$43,7,0),0) -> 0 | E15: Jueves | G15: 8 | H15: Israel Nevado | J15: =IFERROR(VLOOKUP(H15,Tabla13151617[[PILOTOS]:[PTOS.]],2,0),0) -> 102 | L15: 8 | M15: Xavier Vernet | O15: =IFERROR(VLOOKUP(M15,Tabla13151617[[PILOTOS]:[PTOS.]],2,0),0) -> 0
B16: =+B15+1 -> 9 | C16: Carles Carreño | D16: =IFERROR(VLOOKUP(Tabla13151617[[#This Row],[PILOTOS]],Clasificacion_final_2019!$C$3:$I$43,7,0),0) -> 188 | E16: Jueves
B17: =+B16+1 -> 10 | C17: Richard Arredondo | D17: =IFERROR(VLOOKUP(Tabla13151617[[#This Row],[PILOTOS]],Clasificacion_final_2019!$C$3:$I$43,7,0),0) -> 154 | E17: Jueves
B18: =+B17+1 -> 11 | C18: David Izquierdo | D18: =IFERROR(VLOOKUP(Tabla13151617[[#This Row],[PILOTOS]],Clasificacion_final_2019!$C$3:$I$43,7,0),0) -> 151 | E18: Jueves | G18: VIERNES
B19: =+B18+1 -> 12 | C19: Marc Casanovas | D19: =IFERROR(VLOOKUP(Tabla13151617[[#This Row],[PILOTOS]],Clasificacion_final_2019!$C$3:$I$43,7,0),0) -> 147 | E19: Jueves
B20: =+B19+1 -> 13 | C20: Jordi Simo | D20: =IFERROR(VLOOKUP(Tabla13151617[[#This Row],[PILOTOS]],Clasificacion_final_2019!$C$3:$I$43,7,0),0) -> 138 | E20: Jueves | G20: # | H20: PILOTO | I20: P SALIDA | J20: PTOS. | L20: # | M20: PILOTO | N20: P SALIDA | O20: PTOS.
B21: =+B20+1 -> 14 | C21: Manel Soriano | D21: =IFERROR(VLOOKUP(Tabla13151617[[#This Row],[PILOTOS]],Clasificacion_final_2019!$C$3:$I$43,7,0),0) -> 126 | E21: Jueves | G21: 1 | H21: Eduard Cerda | J21: =IFERROR(VLOOKUP(H21,Tabla13151617[[PILOTOS]:[PTOS.]],2,0),0) -> 213 | L21: 9 | M21: Albert Tomas | O21: =IFERROR(VLOOKUP(M21,Tabla13151617[[PILOTOS]:[PTOS.]],2,0),0) -> 132
B22: =+B21+1 -> 15 | C22: Victor Gonzalez | D22: =IFERROR(VLOOKUP(Tabla13151617[[#This Row],[PILOTOS]],Clasificacion_final_2019!$C$3:$I$43,7,0),0) -> 111 | E22: Jueves | G22: 2 | H22: JM Sererols | J22: =IFERROR(VLOOKUP(H22,Tabla13151617[[PILOTOS]:[PTOS.]],2,0),0) -> 198 | L22: 10 | M22: Gabriel Rodriguez | O22: =IFERROR(VLOOKUP(M22,Tabla13151617[[PILOTOS]:[PTOS.]],2,0),0) -> 131
B23: =+B22+1 -> 16 | C23: Israel Nevado | D23: =IFERROR(VLOOKUP(Tabla13151617[[#This Row],[PILOTOS]],Clasificacion_final_2019!$C$3:$I$43,7,0),0) -> 102 | E23: Jueves | G23: 3 | H23: Marc Lansac | J23: =IFERROR(VLOOKUP(H23,Tabla13151617[[PILOTOS]:[PTOS.]],2,0),0) -> 180 | L23: 11 | M23: Vicens Febrero | O23: =IFERROR(VLOOKUP(M23,Tabla13151617[[PILOTOS]:[PTOS.]],2,0),0) -> 128
B24: =+B23+1 -> 17 | C24: Lorenzo Rodriguez | D24: =IFERROR(VLOOKUP(Tabla13151617[[#This Row],[PILOTOS]],Clasificacion_final_2019!$C$3:$I$43,7,0),0) -> 0 | E24: Viernes | G24: 4 | H24: Joel Mendizabal | J24: =IFERROR(VLOOKUP(H24,Tabla13151617[[PILOTOS]:[PTOS.]],2,0),0) -> 167 | L24: 12 | M24: Angel Navarro | O24: =IFERROR(VLOOKUP(M24,Tabla13151617[[PILOTOS]:[PTOS.]],2,0),0) -> 126
B25: =+B24+1 -> 18 | C25: Carlos Repiso | D25: =IFERROR(VLOOKUP(Tabla13151617[[#This Row],[PILOTOS]],Clasificacion_final_2019!$C$3:$I$43,7,0),0) -> 0 | E25: Viernes | G25: 5 | H25: Jordi Robles | J25: =IFERROR(VLOOKUP(H25,Tabla13151617[[PILOTOS]:[PTOS.]],2,0),0) -> 163 | L25: 13 | M25: Germa Portet | O25: =IFERROR(VLOOKUP(M25,Tabla13151617[[PILOTOS]:[PTOS.]],2,0),0) -> 122
B26: =+B25+1 -> 19 | C26: Valeri Jonama | D26: =IFERROR(VLOOKUP(Tabla13151617[[#This Row],[PILOTOS]],Clasificacion_final_2019!$C$3:$I$43,7,0),0) -> 0 | E26: Viernes | G26: 6 | H26: Adam Parera | J26: =IFERROR(VLOOKUP(H26,Tabla13151617[[PILOTOS]:[PTOS.]],2,0),0) -> 155 | L26: 14 | M26: Israel Gomez | O26: =IFERROR(VLOOKUP(M26,Tabla13151617[[PILOTOS]:[PTOS.]],2,0),0) -> 93
B27: =+B26+1 -> 20 | C27: Cristian Diaz | D27: =IFERROR(VLOOKUP(Tabla13151617[[#This Row],[PILOTOS]],Clasificacion_final_2019!$C$3:$I$43,7,0),0) -> 0 | E27: Viernes | G27: 7 | H27: Julen Valbuena | J27: =IFERROR(VLOOKUP(H27,Tabla13151617[[PILOTOS]:[PTOS.]],2,0),0) -> 155 | L27: 15 | M27: Jordi Rierola | O27: =IFERROR(VLOOKUP(M27,Tabla13151617[[PILOTOS]:[PTOS.]],2,0),0) -> 84
B28: =+B27+1 -> 21 | C28: Jesus Jodar | D28: =IFERROR(VLOOKUP(Tabla13151617[[#This Row],[PILOTOS]],Clasificacion_final_2019!$C$3:$I$43,7,0),0) -> 0 | E28: Viernes | G28: 8 | H28: Sergi Sola | J28: =IFERROR(VLOOKUP(H28,Tabla13151617[[PILOTOS]:[PTOS.]],2,0),0) -> 147 | L28: 16 | M28: Victor Querol | O28: =IFERROR(VLOOKUP(M28,Tabla13151617[[PILOTOS]:[PTOS.]],2,0),0) -> 43
B29: =+B28+1 -> 22 | C29: Óscar Alarcón | D29: =IFERROR(VLOOKUP(Tabla13151617[[#This Row],[PILOTOS]],Clasificacion_final_2019!$C$3:$I$43,7,0),0) -> 0 | E29: Viernes
B30: =+B29+1 -> 23 | C30: Albert Lombarte | D30: =IFERROR(VLOOKUP(Tabla13151617[[#This Row],[PILOTOS]],Clasificacion_final_2019!$C$3:$I$43,7,0),0) -> 0 | E30: Viernes | G30: # | H30: PILOTO | I30: P SALIDA | J30: PTOS.
B31: =+B30+1 -> 24 | C31: Xavi Cortada | D31: =IFERROR(VLOOKUP(Tabla13151617[[#This Row],[PILOTOS]],Clasificacion_final_2019!$C$3:$I$43,7,0),0) -> 0 | E31: Viernes | G31: 17 | H31: Valeri Jonama | J31: =IFERROR(VLOOKUP(H31,Tabla13151617[[PILOTOS]:[PTOS.]],2,0),0) -> 0
B32: =+B31+1 -> 25 | C32: Albert Figuerola | D32: =IFERROR(VLOOKUP(Tabla13151617[[#This Row],[PILOTOS]],Clasificacion_final_2019!$C$3:$I$43,7,0),0) -> 0 | E32: Viernes | G32: 18 | H32: Cristian Diaz | J32: =IFERROR(VLOOKUP(H32,Tabla13151617[[PILOTOS]:[PTOS.]],2,0),0) -> 0
B33: =+B32+1 -> 26 | C33: Albert Tomas | D33: =IFERROR(VLOOKUP(Tabla13151617[[#This Row],[PILOTOS]],Clasificacion_final_2019!$C$3:$I$43,7,0),0) -> 132 | E33: Viernes | G33: 19 | H33: Jesus Jodar | J33: =IFERROR(VLOOKUP(H33,Tabla13151617[[PILOTOS]:[PTOS.]],2,0),0) -> 0
B34: =+B33+1 -> 27 | C34: Gabriel Rodriguez | D34: =IFERROR(VLOOKUP(Tabla13151617[[#This Row],[PILOTOS]],Clasificacion_final_2019!$C$3:$I$43,7,0),0) -> 131 | E34: Viernes | G34: 20 | H34: Óscar Alarcón | J34: =IFERROR(VLOOKUP(H34,Tabla13151617[[PILOTOS]:[PTOS.]],2,0),0) -> 0
B35: =+B34+1 -> 28 | C35: Vicens Febrero | D35: =IFERROR(VLOOKUP(Tabla13151617[[#This Row],[PILOTOS]],Clasificacion_final_2019!$C$3:$I$43,7,0),0) -> 128 | E35: Viernes | G35: 21 | H35: Albert Lombarte | J35: =IFERROR(VLOOKUP(H35,Tabla13151617[[PILOTOS]:[PTOS.]],2,0),0) -> 0
B36: =+B35+1 -> 29 | C36: Angel Navarro | D36: =IFERROR(VLOOKUP(Tabla13151617[[#This Row],[PILOTOS]],Clasificacion_final_2019!$C$3:$I$43,7,0),0) -> 126 | E36: Viernes | G36: 22 | H36: Xavi Cortada | J36: =IFERROR(VLOOKUP(H36,Tabla13151617[[PILOTOS]:[PTOS.]],2,0),0) -> 0
B37: =+B36+1 -> 30 | C37: Germa Portet | D37: =IFERROR(VLOOKUP(Tabla13151617[[#This Row],[PILOTOS]],Clasificacion_final_2019!$C$3:$I$43,7,0),0) -> 122 | E37: Viernes | G37: 23 | H37: Albert Figuerola | J37: =IFERROR(VLOOKUP(H37,Tabla13151617[[PILOTOS]:[PTOS.]],2,0),0) -> 0
B38: =+B37+1 -> 31 | C38: Israel Gomez | D38: =IFERROR(VLOOKUP(Tabla13151617[[#This Row],[PILOTOS]],Clasificacion_final_2019!$C$3:$I$43,7,0),0) -> 93 | E38: Viernes | G38: 24 | H38: Carlos Repiso | J38: =IFERROR(VLOOKUP(H38,Tabla13151617[[PILOTOS]:[PTOS.]],2,0),0) -> 0
B39: =+B38+1 -> 32 | C39: Jordi Rierola | D39: =IFERROR(VLOOKUP(Tabla13151617[[#This Row],[PILOTOS]],Clasificacion_final_2019!$C$3:$I$43,7,0),0) -> 84 | E39: Viernes | G39: 25 | H39: Lorenzo Rodriguez | J39: =IFERROR(VLOOKUP(H39,Tabla13151617[[PILOTOS]:[PTOS.]],2,0),0) -> 0
B40: =+B39+1 -> 33 | C40: Victor Querol | D40: =IFERROR(VLOOKUP(Tabla13151617[[#This Row],[PILOTOS]],Clasificacion_final_2019!$C$3:$I$43,7,0),0) -> 43 | E40: Viernes
B41: =+B40+1 -> 34 | C41: Eduard Cerda | D41: =IFERROR(VLOOKUP(Tabla13151617[[#This Row],[PILOTOS]],Clasificacion_final_2019!$C$3:$I$43,7,0),0) -> 213 | E41: Viernes
B42: =+B41+1 -> 35 | C42: JM Sererols | D42: =IFERROR(VLOOKUP(Tabla13151617[[#This Row],[PILOTOS]],Clasificacion_final_2019!$C$3:$I$43,7,0),0) -> 198 | E42: Viernes
B43: =+B42+1 -> 36 | C43: Marc Lansac | D43: =IFERROR(VLOOKUP(Tabla13151617[[#This Row],[PILOTOS]],Clasificacion_final_2019!$C$3:$I$43,7,0),0) -> 180 | E43: Viernes
B44: =+B43+1 -> 37 | C44: Joel Mendizabal | D44: =IFERROR(VLOOKUP(Tabla13151617[[#This Row],[PILOTOS]],Clasificacion_final_2019!$C$3:$I$43,7,0),0) -> 167 | E44: Viernes
B45: =+B44+1 -> 38 | C45: Jordi Robles | D45: =IFERROR(VLOOKUP(Tabla13151617[[#This Row],[PILOTOS]],Clasificacion_final_2019!$C$3:$I$43,7,0),0) -> 163 | E45: Viernes
...

Sheet Verificaciones_ELSOT
B7: DATOS COCHES PARTICIPANTES
B10: # | C10: PILOTO | D10: COCHE | E10: MOTOR | F10: PESO C. | G10: PESO MIN. | H10: PIÑÓN | I10: CORONA | J10: REL | K10: LLANTAS D | L10: DIAMETRO LL.D. | M10: LLANTAS T | N10: DIAMETRO LL.T. | O10: TRENC. | P10: SUSP. | Q10: BANCADA | R10: CHASIS | S10: NEUMATICOS | T10: OBS. VERIFICACIÓN
B11: 1 | D11: MBAGT3 | G11: 18
B12: 2 | D12: MBAGT3 | G12: 18
B13: 3 | D13: MBAGT3 | G13: 18
B14: 4 | D14: MBAGT3 | G14: 18
B15: 5 | D15: MBAGT3 | G15: 18
B16: 6 | D16: MBAGT3 | G16: 18
B17: 7 | D17: MBAGT3 | G17: 18
B18: 8 | D18: MBAGT3 | G18: 18
B19: 9 | D19: MBAGT3 | G19: 18
B20: 10 | D20: MBAGT3 | G20: 18
B21: 11 | D21: MBAGT3 | G21: 18
B22: 12 | D22: MBAGT3 | G22: 18
... B54: 44 | D54: MBAGT3 | G54: 18
B62: DETALLE DEL COCHE GANADOR

Sheet Inscritos_Mangas_S4Y
B5: PITLOTOS INSCRITOS | G5: JUEVES
B7: # | C7: PILOTOS | D7: PTOS. | E7: DIA | G7: # | H7: PILOTO | I7: P SALIDA | J7: PTOS. | L7: # | M7: PILOTO | N7: P SALIDA | O7: PTOS.
B8: 1 | D8: =IFERROR(VLOOKUP(Tabla1315161719[[#This Row],[PILOTOS]],Clasificación_General!C3:H43,6,0),0) -> 0 | G8: 1 | J8: =IFERROR(VLOOKUP(H8,Tabla1315161719[[PILOTOS]:[PTOS.]],2,0),0) -> 0 | L8: 1 | O8: =IFERROR(VLOOKUP(M8,Tabla1315161719[[PILOTOS]:[PTOS.]],2,0),0) -> 0
B9: =+B8+1 -> 2 | D9: =IFERROR(VLOOKUP(Tabla1315161719[[#This Row],[PILOTOS]],Clasificación_General!C4:H44,6,0),0) -> 0 | G9: 2 | J9: =IFERROR(VLOOKUP(H9,Tabla1315161719[[PILOTOS]:[PTOS.]],2,0),0) -> 0 | L9: 2 | O9: =IFERROR(VLOOKUP(M9,Tabla1315161719[[PILOTOS]:[PTOS.]],2,0),0) -> 0
B10: =+B9+1 -> 3 | D10: =IFERROR(VLOOKUP(Tabla1315161719[[#This Row],[PILOTOS]],Clasificación_General!C5:H45,6,0),0) -> 0 | G10: 3 | J10: =IFERROR(VLOOKUP(H10,Tabla1315161719[[PILOTOS]:[PTOS.]],2,0),0) -> 0 | L10: 3 | O10: =IFERROR(VLOOKUP(M10,Tabla1315161719[[PILOTOS]:[PTOS.]],2,0),0) -> 0
B11: =+B10+1 -> 4 | D11: =IFERROR(VLOOKUP(Tabla1315161719[[#This Row],[PILOTOS]],Clasificación_General!C6:H46,6,0),0) -> 0 | G11: 4 | J11: =IFERROR(VLOOKUP(H11,Tabla1315161719[[PILOTOS]:[PTOS.]],2,0),0) -> 0 | L11: 4 | O11: =IFERROR(VLOOKUP(M11,Tabla1315161719[[PILOTOS]:[PTOS.]],2,0),0) -> 0
B12: =+B11+1 -> 5 | D12: =IFERROR(VLOOKUP(Tabla1315161719[[#This Row],[PILOTOS]],Clasificación_General!C7:H47,6,0),0) -> 0 | G12: 5 | J12: =IFERROR(VLOOKUP(H12,Tabla1315161719[[PILOTOS]:[PTOS.]],2,0),0) -> 0 | L12: 5 | O12: =IFERROR(VLOOKUP(M12,Tabla1315161719[[PILOTOS]:[PTOS.]],2,0),0) -> 0
B13: =+B12+1 -> 6 | D13: =IFERROR(VLOOKUP(Tabla1315161719[[#This Row],[PILOTOS]],Clasificación_General!C8:H48,6,0),0) -> 0 | G13: 6 | J13: =IFERROR(VLOOKUP(H13,Tabla1315161719[[PILOTOS]:[PTOS.]],2,0),0) -> 0 | L13: 6 | O13: =IFERROR(VLOOKUP(M13,Tabla1315161719[[PILOTOS]:[PTOS.]],2,0),0) -> 0
B14: =+B13+1 -> 7 | D14: =IFERROR(VLOOKUP(Tabla1315161719[[#This Row],[PILOTOS]],Clasificación_General!C9:H49,6,0),0) -> 0 | G14: 7 | J14: =IFERROR(VLOOKUP(H14,Tabla1315161719[[PILOTOS]:[PTOS.]],2,0),0) -> 0 | L14: 7 | O14: =IFERROR(VLOOKUP(M14,Tabla1315161719[[PILOTOS]:[PTOS.]],2,0),0) -> 0
B15: =+B14+1 -> 8 | D15: =IFERROR(VLOOKUP(Tabla1315161719[[#This Row],[PILOTOS]],Clasificación_General!C10:H50,6,0),0) -> 0 | G15: 8 | J15: =IFERROR(VLOOKUP(H15,Tabla1315161719[[PILOTOS]:[PTOS.]],2,0),0) -> 0 | L15: 8 | O15: =IFERROR(VLOOKUP(M15,Tabla1315161719[[PILOTOS]:[PTOS.]],2,0),0) -> 0
B16: =+B15+1 -> 9 | D16: =IFERROR(VLOOKUP(Tabla1315161719[[#This Row],[PILOTOS]],Clasificación_General!C11:H51,6,0),0) -> 0
B17: =+B16+1 -> 10 | D17: =IFERROR(VLOOKUP(Tabla1315161719[[#This Row],[PILOTOS]],Clasificación_General!C12:H52,6,0),0) -> 0
B18: =+B17+1 -> 11 | D18: =IFERROR(VLOOKUP(Tabla1315161719[[#This Row],[PILOTOS]],Clasificación_General!C13:H53,6,0),0) -> 0 | G18: VIERNES
B19: =+B18+1 -> 12 | D19: =IFERROR(VLOOKUP(Tabla1315161719[[#This Row],[PILOTOS]],Clasificación_General!C14:H54,6,0),0) -> 0
B20: =+B19+1 -> 13 | D20: =IFERROR(VLOOKUP(Tabla1315161719[[#This Row],[PILOTOS]],Clasificación_General!C15:H55,6,0),0) -> 0 | G20: # | H20: PILOTO | I20: P SALIDA | J20: PTOS. | L20: # | M20: PILOTO | N20: P SALIDA | O20: PTOS.
B21: =+B20+1 -> 14 | D21: =IFERROR(VLOOKUP(Tabla1315161719[[#This Row],[PILOTOS]],Clasificación_General!C16:H56,6,0),0) -> 0 | G21: 1 | J21: =IFERROR(VLOOKUP(H21,Tabla1315161719[[PILOTOS]:[PTOS.]],2,0),0) -> 0 | L21: 1 | O21: =IFERROR(VLOOKUP(M21,Tabla1315161719[[PILOTOS]:[PTOS.]],2,0),0) -> 0
B22: =+B21+1 -> 15 | D22: =IFERROR(VLOOKUP(Tabla1315161719[[#This Row],[PILOTOS]],Clasificación_General!C17:H57,6,0),0) -> 0 | G22: 2 | J22: =IFERROR(VLOOKUP(H22,Tabla1315161719[[PILOTOS]:[PTOS.]],2,0),0) -> 0 | L22: 2 | O22: =IFERROR(VLOOKUP(M22,Tabla1315161719[[PILOTOS]:[PTOS.]],2,0),0) -> 0
B23: =+B22+1 -> 16 | D23: =IFERROR(VLOOKUP(Tabla1315161719[[#This Row],[PILOTOS]],Clasificación_General!C18:H58,6,0),0) -> 0 | G23: 3 | J23: =IFERROR(VLOOKUP(H23,Tabla1315161719[[PILOTOS]:[PTOS.]],2,0),0) -> 0 | L23: 3 | O23: =IFERROR(VLOOKUP(M23,Tabla1315161719[[PILOTOS]:[PTOS.]],2,0),0) -> 0
B24: =+B23+1 -> 17 | D24: =IFERROR(VLOOKUP(Tabla1315161719[[#This Row],[PILOTOS]],Clasificación_General!C19:H59,6,0),0) -> 0 | G24: 4 | J24: =IFERROR(VLOOKUP(H24,Tabla1315161719[[PILOTOS]:[PTOS.]],2,0),0) -> 0 | L24: 4 | O24: =IFERROR(VLOOKUP(M24,Tabla1315161719[[PILOTOS]:[PTOS.]],2,0),0) -> 0
B25: =+B24+1 -> 18 | D25: =IFERROR(VLOOKUP(Tabla1315161719[[#This Row],[PILOTOS]],Clasificación_General!C20:H60,6,0),0) -> 0 | G25: 5 | J25: =IFERROR(VLOOKUP(H25,Tabla1315161719[[PILOTOS]:[PTOS.]],2,0),0) -> 0 | L25: 5 | O25: =IFERROR(VLOOKUP(M25,Tabla1315161719[[PILOTOS]:[PTOS.]],2,0),0) -> 0
B26: =+B25+1 -> 19 | D26: =IFERROR(VLOOKUP(Tabla1315161719[[#This Row],[PILOTOS]],Clasificación_General!C21:H61,6,0),0) -> 0 | G26: 6 | J26: =IFERROR(VLOOKUP(H26,Tabla1315161719[[PILOTOS]:[PTOS.]],2,0),0) -> 0 | L26: 6 | O26: =IFERROR(VLOOKUP(M26,Tabla1315161719[[PILOTOS]:[PTOS.]],2,0),0) -> 0
B27: =+B26+1 -> 20 | D27: =IFERROR(VLOOKUP(Tabla1315161719[[#This Row],[PILOTOS]],Clasificación_General!C22:H62,6,0),0) -> 0 | G27: 7 | J27: =IFERROR(VLOOKUP(H27,Tabla1315161719[[PILOTOS]:[PTOS.]],2,0),0) -> 0 | L27: 7 | O27: =IFERROR(VLOOKUP(M27,Tabla1315161719[[PILOTOS]:[PTOS.]],2,0),0) -> 0
B28: =+B27+1 -> 21 | D28: =IFERROR(VLOOKUP(Tabla1315161719[[#This Row],[PILOTOS]],Clasificación_General!C23:H63,6,0),0) -> 0 | G28: 8 | J28: =IFERROR(VLOOKUP(H28,Tabla1315161719[[PILOTOS]:[PTOS.]],2,0),0) -> 0 | L28: 8 | O28: =IFERROR(VLOOKUP(M28,Tabla1315161719[[PILOTOS]:[PTOS.]],2,0),0) -> 0
B29: =+B28+1 -> 22 | D29: =IFERROR(VLOOKUP(Tabla1315161719[[#This Row],[PILOTOS]],Clasificación_General!C24:H64,6,0),0) -> 0
B30: =+B29+1 -> 23 | D30: =IFERROR(VLOOKUP(Tabla1315161719[[#This Row],[PILOTOS]],Clasificación_General!C25:H65,6,0),0) -> 0 | G30: # | H30: PILOTO | I30: P SALIDA | J30: PTOS.
B31: =+B30+1 -> 24 | D31: =IFERROR(VLOOKUP(Tabla1315161719[[#This Row],[PILOTOS]],Clasificación_General!C26:H66,6,0),0) -> 0 | G31: 1 | J31: =IFERROR(VLOOKUP(H31,Tabla1315161719[[PILOTOS]:[PTOS.]],2,0),0) -> 0
B32: =+B31+1 -> 25 | D32: =IFERROR(VLOOKUP(Tabla1315161719[[#This Row],[PILOTOS]],Clasificación_General!C27:H67,6,0),0) -> 0 | G32: 2 | J32: =IFERROR(VLOOKUP(H32,Tabla1315161719[[PILOTOS]:[PTOS.]],2,0),0) -> 0
B33: =+B32+1 -> 26 | D33: =IFERROR(VLOOKUP(Tabla1315161719[[#This Row],[PILOTOS]],Clasificación_General!C28:H68,6,0),0) -> 0 | G33: 3 | J33: =IFERROR(VLOOKUP(H33,Tabla1315161719[[PILOTOS]:[PTOS.]],2,0),0) -> 0
B34: =+B33+1 -> 27 | D34: =IFERROR(VLOOKUP(Tabla1315161719[[#This Row],[PILOTOS]],Clasificación_General!C29:H69,6,0),0) -> 0 | G34: 4 | J34: =IFERROR(VLOOKUP(H34,Tabla1315161719[[PILOTOS]:[PTOS.]],2,0),0) -> 0
B35: =+B34+1 -> 28 | D35: =IFERROR(VLOOKUP(Tabla1315161719[[#This Row],[PILOTOS]],Clasificación_General!C30:H70,6,0),0) -> 0 | G35: 5 | J35: =IFERROR(VLOOKUP(H35,Tabla1315161719[[PILOTOS]:[PTOS.]],2,0),0) -> 0
B36: =+B35+1 -> 29 | D36: =IFERROR(VLOOKUP(Tabla1315161719[[#This Row],[PILOTOS]],Clasificación_General!C31:H71,6,0),0) -> 0 | G36: 6 | J36: =IFERROR(VLOOKUP(H36,Tabla1315161719[[PILOTOS]:[PTOS.]],2,0),0) -> 0
B37: =+B36+1 -> 30 | D37: =IFERROR(VLOOKUP(Tabla1315161719[[#This Row],[PILOTOS]],Clasificación_General!C32:H72,6,0),0) -> 0 | G37: 7 | J37: =IFERROR(VLOOKUP(H37,Tabla1315161719[[PILOTOS]:[PTOS.]],2,0),0) -> 0
B38: =+B37+1 -> 31 | D38: =IFERROR(VLOOKUP(Tabla1315161719[[#This Row],[PILOTOS]],Clasificación_General!C33:H73,6,0),0) -> 0 | G38: 8 | J38: =IFERROR(VLOOKUP(H38,Tabla1315161719[[PILOTOS]:[PTOS.]],2,0),0) -> 0
B39: =+B38+1 -> 32 | D39: =IFERROR(VLOOKUP(Tabla1315161719[[#This Row],[PILOTOS]],Clasificación_General!C34:H74,6,0),0) -> 0
B40: =+B39+1 -> 33 | D40: =IFERROR(VLOOKUP(Tabla1315161719[[#This Row],[PILOTOS]],Clasificación_General!C35:H75,6,0),0) -> 0
B41: =+B40+1 -> 34 | D41: =IFERROR(VLOOKUP(Tabla1315161719[[#This Row],[PILOTOS]],Clasificación_General!C36:H76,6,0),0) -> 0
B42: =+B41+1 -> 35 | D42: =IFERROR(VLOOKUP(Tabla1315161719[[#This Row],[PILOTOS]],Clasificación_General!C37:H77,6,0),0) -> 0
B43: =+B42+1 -> 36 | D43: =IFERROR(VLOOKUP(Tabla1315161719[[#This Row],[PILOTOS]],Clasificación_General!C38:H78,6,0),0) -> 0
B44: =+B43+1 -> 37 | D44: =IFERROR(VLOOKUP(Tabla1315161719[[#This Row],[PILOTOS]],Clasificación_General!C39:H79,6,0),0) -> 0
B45: =+B44+1 -> 38 | D45: =IFERROR(VLOOKUP(Tabla1315161719[[#This Row],[PILOTOS]],Clasificación_General!C40:H80,6,0),0) -> 0
...

Sheet Verificaciones_S4Y
B7: DATOS COCHES PARTICIPANTES
B10: # | C10: PILOTO | D10: COCHE | E10: MOTOR | F10: PESO C. | G10: PESO MIN. | H10: PIÑÓN | I10: CORONA | J10: REL | K10: LLANTAS D | L10: DIAMETRO LL.D. | M10: LLANTAS T | N10: DIAMETRO LL.T. | O10: TRENC. | P10: SUSP. | Q10: BANCADA | R10: CHASIS | S10: NEUMATICOS | T10: OBS. VERIFICACIÓN
B11: 1 | D11: MBAGT3 | G11: 18
B12: 2 | D12: MBAGT3 | G12: 18
B13: 3 | D13: MBAGT3 | G13: 18
B14: 4 | D14: MBAGT3 | G14: 18
B15: 5 | D15: MBAGT3 | G15: 18
B16: 6 | D16: MBAGT3 | G16: 18
B17: 7 | D17: MBAGT3 | G17: 18
B18: 8 | D18: MBAGT3 | G18: 18
B19: 9 | D19: MBAGT3 | G19: 18
B20: 10 | D20: MBAGT3 | G20: 18
B21: 11 | D21: MBAGT3 | G21: 18
B22: 12 | D22: MBAGT3 | G22: 18
... B54: 44 | D54: MBAGT3 | G54: 18
B63: DETALLE DEL COCHE GANADOR

Sheet Inscritos_Mangas_SLOTCAR
B5: PITLOTOS INSCRITOS | G5: JUEVES
B7: # | C7: PILOTOS | D7: PTOS. | E7: DIA | G7: # | H7: PILOTO | I7: P SALIDA | J7: PTOS. | L7: # | M7: PILOTO | N7: P SALIDA | O7: PTOS.
B8: 1 | D8: =IFERROR(VLOOKUP(Tabla131516171920[[#This Row],[PILOTOS]],Clasificación_General!C3:H43,6,0),0) -> 0 | G8: 1 | J8: =IFERROR(VLOOKUP(H8,Tabla131516171920[[PILOTOS]:[PTOS.]],2,0),0) -> 0 | L8: 1 | O8: =IFERROR(VLOOKUP(M8,Tabla131516171920[[PILOTOS]:[PTOS.]],2,0),0) -> 0
B9: =+B8+1 -> 2 | D9: =IFERROR(VLOOKUP(Tabla131516171920[[#This Row],[PILOTOS]],Clasificación_General!C4:H44,6,0),0) -> 0 | G9: 2 | J9: =IFERROR(VLOOKUP(H9,Tabla131516171920[[PILOTOS]:[PTOS.]],2,0),0) -> 0 | L9: 2 | O9: =IFERROR(VLOOKUP(M9,Tabla131516171920[[PILOTOS]:[PTOS.]],2,0),0) -> 0
B10: =+B9+1 -> 3 | D10: =IFERROR(VLOOKUP(Tabla131516171920[[#This Row],[PILOTOS]],Clasificación_General!C5:H45,6,0),0) -> 0 | G10: 3 | J10: =IFERROR(VLOOKUP(H10,Tabla131516171920[[PILOTOS]:[PTOS.]],2,0),0) -> 0 | L10: 3 | O10: =IFERROR(VLOOKUP(M10,Tabla131516171920[[PILOTOS]:[PTOS.]],2,0),0) -> 0
B11: =+B10+1 -> 4 | D11: =IFERROR(VLOOKUP(Tabla131516171920[[#This Row],[PILOTOS]],Clasificación_General!C6:H46,6,0),0) -> 0 | G11: 4 | J11: =IFERROR(VLOOKUP(H11,Tabla131516171920[[PILOTOS]:[PTOS.]],2,0),0) -> 0 | L11: 4 | O11: =IFERROR(VLOOKUP(M11,Tabla131516171920[[PILOTOS]:[PTOS.]],2,0),0) -> 0
B12: =+B11+1 -> 5 | D12: =IFERROR(VLOOKUP(Tabla131516171920[[#This Row],[PILOTOS]],Clasificación_General!C7:H47,6,0),0) -> 0 | G12: 5 | J12: =IFERROR(VLOOKUP(H12,Tabla131516171920[[PILOTOS]:[PTOS.]],2,0),0) -> 0 | L12: 5 | O12: =IFERROR(VLOOKUP(M12,Tabla131516171920[[PILOTOS]:[PTOS.]],2,0),0) -> 0
B13: =+B12+1 -> 6 | D13: =IFERROR(VLOOKUP(Tabla131516171920[[#This Row],[PILOTOS]],Clasificación_General!C8:H48,6,0),0) -> 0 | G13: 6 | J13: =IFERROR(VLOOKUP(H13,Tabla131516171920[[PILOTOS]:[PTOS.]],2,0),0) -> 0 | L13: 6 | O13: =IFERROR(VLOOKUP(M13,Tabla131516171920[[PILOTOS]:[PTOS.]],2,0),0) -> 0
B14: =+B13+1 -> 7 | D14: =IFERROR(VLOOKUP(Tabla131516171920[[#This Row],[PILOTOS]],Clasificación_General!C9:H49,6,0),0) -> 0 | G14: 7 | J14: =IFERROR(VLOOKUP(H14,Tabla131516171920[[PILOTOS]:[PTOS.]],2,0),0) -> 0 | L14: 7 | O14: =IFERROR(VLOOKUP(M14,Tabla131516171920[[PILOTOS]:[PTOS.]],2,0),0) -> 0
B15: =+B14+1 -> 8 | D15: =IFERROR(VLOOKUP(Tabla131516171920[[#This Row],[PILOTOS]],Clasificación_General!C10:H50,6,0),0) -> 0 | G15: 8 | J15: =IFERROR(VLOOKUP(H15,Tabla131516171920[[PILOTOS]:[PTOS.]],2,0),0) -> 0 | L15: 8 | O15: =IFERROR(VLOOKUP(M15,Tabla131516171920[[PILOTOS]:[PTOS.]],2,0),0) -> 0
B16: =+B15+1 -> 9 | D16: =IFERROR(VLOOKUP(Tabla131516171920[[#This Row],[PILOTOS]],Clasificación_General!C11:H51,6,0),0) -> 0
B17: =+B16+1 -> 10 | D17: =IFERROR(VLOOKUP(Tabla131516171920[[#This Row],[PILOTOS]],Clasificación_General!C12:H52,6,0),0) -> 0
B18: =+B17+1 -> 11 | D18: =IFERROR(VLOOKUP(Tabla131516171920[[#This Row],[PILOTOS]],Clasificación_General!C13:H53,6,0),0) -> 0 | G18: VIERNES
B19: =+B18+1 -> 12 | D19: =IFERROR(VLOOKUP(Tabla131516171920[[#This Row],[PILOTOS]],Clasificación_General!C14:H54,6,0),0) -> 0
B20: =+B19+1 -> 13 | D20: =IFERROR(VLOOKUP(Tabla131516171920[[#This Row],[PILOTOS]],Clasificación_General!C15:H55,6,0),0) -> 0 | G20: # | H20: PILOTO | I20: P SALIDA | J20: PTOS. | L20: # | M20: PILOTO | N20: P SALIDA | O20: PTOS.
B21: =+B20+1 -> 14 | D21: =IFERROR(VLOOKUP(Tabla131516171920[[#This Row],[PILOTOS]],Clasificación_General!C16:H56,6,0),0) -> 0 | G21: 1 | J21: =IFERROR(VLOOKUP(H21,Tabla131516171920[[PILOTOS]:[PTOS.]],2,0),0) -> 0 | L21: 1 | O21: =IFERROR(VLOOKUP(M21,Tabla131516171920[[PILOTOS]:[PTOS.]],2,0),0) -> 0
B22: =+B21+1 -> 15 | D22: =IFERROR(VLOOKUP(Tabla131516171920[[#This Row],[PILOTOS]],Clasificación_General!C17:H57,6,0),0) -> 0 | G22: 2 | J22: =IFERROR(VLOOKUP(H22,Tabla131516171920[[PILOTOS]:[PTOS.]],2,0),0) -> 0 | L22: 2 | O22: =IFERROR(VLOOKUP(M22,Tabla131516171920[[PILOTOS]:[PTOS.]],2,0),0) -> 0
B23: =+B22+1 -> 16 | D23: =IFERROR(VLOOKUP(Tabla131516171920[[#This Row],[PILOTOS]],Clasificación_General!C18:H58,6,0),0) -> 0 | G23: 3 | J23: =IFERROR(VLOOKUP(H23,Tabla131516171920[[PILOTOS]:[PTOS.]],2,0),0) -> 0 | L23: 3 | O23: =IFERROR(VLOOKUP(M23,Tabla131516171920[[PILOTOS]:[PTOS.]],2,0),0) -> 0
B24: =+B23+1 -> 17 | D24: =IFERROR(VLOOKUP(Tabla131516171920[[#This Row],[PILOTOS]],Clasificación_General!C19:H59,6,0),0) -> 0 | G24: 4 | J24: =IFERROR(VLOOKUP(H24,Tabla131516171920[[PILOTOS]:[PTOS.]],2,0),0) -> 0 | L24: 4 | O24: =IFERROR(VLOOKUP(M24,Tabla131516171920[[PILOTOS]:[PTOS.]],2,0),0) -> 0
B25: =+B24+1 -> 18 | D25: =IFERROR(VLOOKUP(Tabla131516171920[[#This Row],[PILOTOS]],Clasificación_General!C20:H60,6,0),0) -> 0 | G25: 5 | J25: =IFERROR(VLOOKUP(H25,Tabla131516171920[[PILOTOS]:[PTOS.]],2,0),0) -> 0 | L25: 5 | O25: =IFERROR(VLOOKUP(M25,Tabla131516171920[[PILOTOS]:[PTOS.]],2,0),0) -> 0
B26: =+B25+1 -> 19 | D26: =IFERROR(VLOOKUP(Tabla131516171920[[#This Row],[PILOTOS]],Clasificación_General!C21:H61,6,0),0) -> 0 | G26: 6 | J26: =IFERROR(VLOOKUP(H26,Tabla131516171920[[PILOTOS]:[PTOS.]],2,0),0) -> 0 | L26: 6 | O26: =IFERROR(VLOOKUP(M26,Tabla131516171920[[PILOTOS]:[PTOS.]],2,0),0) -> 0
B27: =+B26+1 -> 20 | D27: =IFERROR(VLOOKUP(Tabla131516171920[[#This Row],[PILOTOS]],Clasificación_General!C22:H62,6,0),0) -> 0 | G27: 7 | J27: =IFERROR(VLOOKUP(H27,Tabla131516171920[[PILOTOS]:[PTOS.]],2,0),0) -> 0 | L27: 7 | O27: =IFERROR(VLOOKUP(M27,Tabla131516171920[[PILOTOS]:[PTOS.]],2,0),0) -> 0
B28: =+B27+1 -> 21 | D28: =IFERROR(VLOOKUP(Tabla131516171920[[#This Row],[PILOTOS]],Clasificación_General!C23:H63,6,0),0) -> 0 | G28: 8 | J28: =IFERROR(VLOOKUP(H28,Tabla131516171920[[PILOTOS]:[PTOS.]],2,0),0) -> 0 | L28: 8 | O28: =IFERROR(VLOOKUP(M28,Tabla131516171920[[PILOTOS]:[PTOS.]],2,0),0) -> 0
B29: =+B28+1 -> 22 | D29: =IFERROR(VLOOKUP(Tabla131516171920[[#This Row],[PILOTOS]],Clasificación_General!C24:H64,6,0),0) -> 0
B30: =+B29+1 -> 23 | D30: =IFERROR(VLOOKUP(Tabla131516171920[[#This Row],[PILOTOS]],Clasificación_General!C25:H65,6,0),0) -> 0 | G30: # | H30: PILOTO | I30: P SALIDA | J30: PTOS.
B31: =+B30+1 -> 24 | D31: =IFERROR(VLOOKUP(Tabla131516171920[[#This Row],[PILOTOS]],Clasificación_General!C26:H66,6,0),0) -> 0 | G31: 1 | J31: =IFERROR(VLOOKUP(H31,Tabla131516171920[[PILOTOS]:[PTOS.]],2,0),0) -> 0
B32: =+B31+1 -> 25 | D32: =IFERROR(VLOOKUP(Tabla131516171920[[#This Row],[PILOTOS]],Clasificación_General!C27:H67,6,0),0) -> 0 | G32: 2 | J32: =IFERROR(VLOOKUP(H32,Tabla131516171920[[PILOTOS]:[PTOS.]],2,0),0) -> 0
B33: =+B32+1 -> 26 | D33: =IFERROR(VLOOKUP(Tabla131516171920[[#This Row],[PILOTOS]],Clasificación_General!C28:H68,6,0),0) -> 0 | G33: 3 | J33: =IFERROR(VLOOKUP(H33,Tabla131516171920[[PILOTOS]:[PTOS.]],2,0),0) -> 0
B34: =+B33+1 -> 27 | D34: =IFERROR(VLOOKUP(Tabla131516171920[[#This Row],[PILOTOS]],Clasificación_General!C29:H69,6,0),0) -> 0 | G34: 4 | J34: =IFERROR(VLOOKUP(H34,Tabla131516171920[[PILOTOS]:[PTOS.]],2,0),0) -> 0
B35: =+B34+1 -> 28 | D35: =IFERROR(VLOOKUP(Tabla131516171920[[#This Row],[PILOTOS]],Clasificación_General!C30:H70,6,0),0) -> 0 | G35: 5 | J35: =IFERROR(VLOOKUP(H35,Tabla131516171920[[PILOTOS]:[PTOS.]],2,0),0) -> 0
B36: =+B35+1 -> 29 | D36: =IFERROR(VLOOKUP(Tabla131516171920[[#This Row],[PILOTOS]],Clasificación_General!C31:H71,6,0),0) -> 0 | G36: 6 | J36: =IFERROR(VLOOKUP(H36,Tabla131516171920[[PILOTOS]:[PTOS.]],2,0),0) -> 0
B37: =+B36+1 -> 30 | D37: =IFERROR(VLOOKUP(Tabla131516171920[[#This Row],[PILOTOS]],Clasificación_General!C32:H72,6,0),0) -> 0 | G37: 7 | J37: =IFERROR(VLOOKUP(H37,Tabla131516171920[[PILOTOS]:[PTOS.]],2,0),0) -> 0
B38: =+B37+1 -> 31 | D38: =IFERROR(VLOOKUP(Tabla131516171920[[#This Row],[PILOTOS]],Clasificación_General!C33:H73,6,0),0) -> 0 | G38: 8 | J38: =IFERROR(VLOOKUP(H38,Tabla131516171920[[PILOTOS]:[PTOS.]],2,0),0) -> 0
B39: =+B38+1 -> 32 | D39: =IFERROR(VLOOKUP(Tabla131516171920[[#This Row],[PILOTOS]],Clasificación_General!C34:H74,6,0),0) -> 0
B40: =+B39+1 -> 33 | D40: =IFERROR(VLOOKUP(Tabla131516171920[[#This Row],[PILOTOS]],Clasificación_General!C35:H75,6,0),0) -> 0
B41: =+B40+1 -> 34 | D41: =IFERROR(VLOOKUP(Tabla131516171920[[#This Row],[PILOTOS]],Clasificación_General!C36:H76,6,0),0) -> 0
B42: =+B41+1 -> 35 | D42: =IFERROR(VLOOKUP(Tabla131516171920[[#This Row],[PILOTOS]],Clasificación_General!C37:H77,6,0),0) -> 0
B43: =+B42+1 -> 36 | D43: =IFERROR(VLOOKUP(Tabla131516171920[[#This Row],[PILOTOS]],Clasificación_General!C38:H78,6,0),0) -> 0
B44: =+B43+1 -> 37 | D44: =IFERROR(VLOOKUP(Tabla131516171920[[#This Row],[PILOTOS]],Clasificación_General!C39:H79,6,0),0) -> 0
B45: =+B44+1 -> 38 | D45: =IFERROR(VLOOKUP(Tabla131516171920[[#This Row],[PILOTOS]],Clasificación_General!C40:H80,6,0),0) -> 0
...

Sheet Verificaciones_SLOTCAR
B7: DATOS COCHES PARTICIPANTES
B10: # | C10: PILOTO | D10: COCHE | E10: MOTOR | F10: PESO C. | G10: PESO MIN. | H10: PIÑÓN | I10: CORONA | J10: REL | K10: LLANTAS D | L10: DIAMETRO LL.D. | M10: LLANTAS T | N10: DIAMETRO LL.T. | O10: TRENC. | P10: SUSP. | Q10: BANCADA | R10: CHASIS | S10: NEUMATICOS | T10: OBS. VERIFICACIÓN
B11: 1 | D11: MBAGT3 | G11: 18
B12: 2 | D12: MBAGT3 | G12: 18
B13: 3 | D13: MBAGT3 | G13: 18
B14: 4 | D14: MBAGT3 | G14: 18
B15: 5 | D15: MBAGT3 | G15: 18
B16: 6 | D16: MBAGT3 | G16: 18
B17: 7 | D17: MBAGT3 | G17: 18
B18: 8 | D18: MBAGT3 | G18: 18
B19: 9 | D19: MBAGT3 | G19: 18
B20: 10 | D20: MBAGT3 | G20: 18
B21: 11 | D21: MBAGT3 | G21: 18
B22: 12 | D22: MBAGT3 | G22: 18
... B54: 44 | D54: MBAGT3 | G54: 18
B63: DETALLE DEL COCHE GANADOR

Sheet Inscritos_Mangas_SLOTSAB
B5: PITLOTOS INSCRITOS | G5: JUEVES
B7: # | C7: PILOTOS | D7: PTOS. | E7: DIA | G7: # | H7: PILOTO | I7: P SALIDA | J7: PTOS. | L7: # | M7: PILOTO | N7: P SALIDA | O7: PTOS.
B8: 1 | D8: =IFERROR(VLOOKUP(Tabla13151617192021[[#This Row],[PILOTOS]],Clasificación_General!C3:H43,6,0),0) -> 0 | G8: 1 | J8: =IFERROR(VLOOKUP(H8,Tabla13151617192021[[PILOTOS]:[PTOS.]],2,0),0) -> 0 | L8: 1 | O8: =IFERROR(VLOOKUP(M8,Tabla13151617192021[[PILOTOS]:[PTOS.]],2,0),0) -> 0
B9: =+B8+1 -> 2 | D9: =IFERROR(VLOOKUP(Tabla13151617192021[[#This Row],[PILOTOS]],Clasificación_General!C4:H44,6,0),0) -> 0 | G9: 2 | J9: =IFERROR(VLOOKUP(H9,Tabla13151617192021[[PILOTOS]:[PTOS.]],2,0),0) -> 0 | L9: 2 | O9: =IFERROR(VLOOKUP(M9,Tabla13151617192021[[PILOTOS]:[PTOS.]],2,0),0) -> 0
B10: =+B9+1 -> 3 | D10: =IFERROR(VLOOKUP(Tabla13151617192021[[#This Row],[PILOTOS]],Clasificación_General!C5:H45,6,0),0) -> 0 | G10: 3 | J10: =IFERROR(VLOOKUP(H10,Tabla13151617192021[[PILOTOS]:[PTOS.]],2,0),0) -> 0 | L10: 3 | O10: =IFERROR(VLOOKUP(M10,Tabla13151617192021[[PILOTOS]:[PTOS.]],2,0),0) -> 0
B11: =+B10+1 -> 4 | D11: =IFERROR(VLOOKUP(Tabla13151617192021[[#This Row],[PILOTOS]],Clasificación_General!C6:H46,6,0),0) -> 0 | G11: 4 | J11: =IFERROR(VLOOKUP(H11,Tabla13151617192021[[PILOTOS]:[PTOS.]],2,0),0) -> 0 | L11: 4 | O11: =IFERROR(VLOOKUP(M11,Tabla13151617192021[[PILOTOS]:[PTOS.]],2,0),0) -> 0
B12: =+B11+1 -> 5 | D12: =IFERROR(VLOOKUP(Tabla13151617192021[[#This Row],[PILOTOS]],Clasificación_General!C7:H47,6,0),0) -> 0 | G12: 5 | J12: =IFERROR(VLOOKUP(H12,Tabla13151617192021[[PILOTOS]:[PTOS.]],2,0),0) -> 0 | L12: 5 | O12: =IFERROR(VLOOKUP(M12,Tabla13151617192021[[PILOTOS]:[PTOS.]],2,0),0) -> 0
B13: =+B12+1 -> 6 | D13: =IFERROR(VLOOKUP(Tabla13151617192021[[#This Row],[PILOTOS]],Clasificación_General!C8:H48,6,0),0) -> 0 | G13: 6 | J13: =IFERROR(VLOOKUP(H13,Tabla13151617192021[[PILOTOS]:[PTOS.]],2,0),0) -> 0 | L13: 6 | O13: =IFERROR(VLOOKUP(M13,Tabla13151617192021[[PILOTOS]:[PTOS.]],2,0),0) -> 0
B14: =+B13+1 -> 7 | D14: =IFERROR(VLOOKUP(Tabla13151617192021[[#This Row],[PILOTOS]],Clasificación_General!C9:H49,6,0),0) -> 0 | G14: 7 | J14: =IFERROR(VLOOKUP(H14,Tabla13151617192021[[PILOTOS]:[PTOS.]],2,0),0) -> 0 | L14: 7 | O14: =IFERROR(VLOOKUP(M14,Tabla13151617192021[[PILOTOS]:[PTOS.]],2,0),0) -> 0
B15: =+B14+1 -> 8 | D15: =IFERROR(VLOOKUP(Tabla13151617192021[[#This Row],[PILOTOS]],Clasificación_General!C10:H50,6,0),0) -> 0 | G15: 8 | J15: =IFERROR(VLOOKUP(H15,Tabla13151617192021[[PILOTOS]:[PTOS.]],2,0),0) -> 0 | L15: 8 | O15: =IFERROR(VLOOKUP(M15,Tabla13151617192021[[PILOTOS]:[PTOS.]],2,0),0) -> 0
B16: =+B15+1 -> 9 | D16: =IFERROR(VLOOKUP(Tabla13151617192021[[#This Row],[PILOTOS]],Clasificación_General!C11:H51,6,0),0) -> 0
B17: =+B16+1 -> 10 | D17: =IFERROR(VLOOKUP(Tabla13151617192021[[#This Row],[PILOTOS]],Clasificación_General!C12:H52,6,0),0) -> 0
B18: =+B17+1 -> 11 | D18: =IFERROR(VLOOKUP(Tabla13151617192021[[#This Row],[PILOTOS]],Clasificación_General!C13:H53,6,0),0) -> 0 | G18: VIERNES
B19: =+B18+1 -> 12 | D19: =IFERROR(VLOOKUP(Tabla13151617192021[[#This Row],[PILOTOS]],Clasificación_General!C14:H54,6,0),0) -> 0
B20: =+B19+1 -> 13 | D20: =IFERROR(VLOOKUP(Tabla13151617192021[[#This Row],[PILOTOS]],Clasificación_General!C15:H55,6,0),0) -> 0 | G20: # | H20: PILOTO | I20: P SALIDA | J20: PTOS. | L20: # | M20: PILOTO | N20: P SALIDA | O20: PTOS.
B21: =+B20+1 -> 14 | D21: =IFERROR(VLOOKUP(Tabla13151617192021[[#This Row],[PILOTOS]],Clasificación_General!C16:H56,6,0),0) -> 0 | G21: 1 | J21: =IFERROR(VLOOKUP(H21,Tabla13151617192021[[PILOTOS]:[PTOS.]],2,0),0) -> 0 | L21: 1 | O21: =IFERROR(VLOOKUP(M21,Tabla13151617192021[[PILOTOS]:[PTOS.]],2,0),0) -> 0
B22: =+B21+1 -> 15 | D22: =IFERROR(VLOOKUP(Tabla13151617192021[[#This Row],[PILOTOS]],Clasificación_General!C17:H57,6,0),0) -> 0 | G22: 2 | J22: =IFERROR(VLOOKUP(H22,Tabla13151617192021[[PILOTOS]:[PTOS.]],2,0),0) -> 0 | L22: 2 | O22: =IFERROR(VLOOKUP(M22,Tabla13151617192021[[PILOTOS]:[PTOS.]],2,0),0) -> 0
B23: =+B22+1 -> 16 | D23: =IFERROR(VLOOKUP(Tabla13151617192021[[#This Row],[PILOTOS]],Clasificación_General!C18:H58,6,0),0) -> 0 | G23: 3 | J23: =IFERROR(VLOOKUP(H23,Tabla13151617192021[[PILOTOS]:[PTOS.]],2,0),0) -> 0 | L23: 3 | O23: =IFERROR(VLOOKUP(M23,Tabla13151617192021[[PILOTOS]:[PTOS.]],2,0),0) -> 0
B24: =+B23+1 -> 17 | D24: =IFERROR(VLOOKUP(Tabla13151617192021[[#This Row],[PILOTOS]],Clasificación_General!C19:H59,6,0),0) -> 0 | G24: 4 | J24: =IFERROR(VLOOKUP(H24,Tabla13151617192021[[PILOTOS]:[PTOS.]],2,0),0) -> 0 | L24: 4 | O24: =IFERROR(VLOOKUP(M24,Tabla13151617192021[[PILOTOS]:[PTOS.]],2,0),0) -> 0
B25: =+B24+1 -> 18 | D25: =IFERROR(VLOOKUP(Tabla13151617192021[[#This Row],[PILOTOS]],Clasificación_General!C20:H60,6,0),0) -> 0 | G25: 5 | J25: =IFERROR(VLOOKUP(H25,Tabla13151617192021[[PILOTOS]:[PTOS.]],2,0),0) -> 0 | L25: 5 | O25: =IFERROR(VLOOKUP(M25,Tabla13151617192021[[PILOTOS]:[PTOS.]],2,0),0) -> 0
B26: =+B25+1 -> 19 | D26: =IFERROR(VLOOKUP(Tabla13151617192021[[#This Row],[PILOTOS]],Clasificación_General!C21:H61,6,0),0) -> 0 | G26: 6 | J26: =IFERROR(VLOOKUP(H26,Tabla13151617192021[[PILOTOS]:[PTOS.]],2,0),0) -> 0 | L26: 6 | O26: =IFERROR(VLOOKUP(M26,Tabla13151617192021[[PILOTOS]:[PTOS.]],2,0),0) -> 0
B27: =+B26+1 -> 20 | D27: =IFERROR(VLOOKUP(Tabla13151617192021[[#This Row],[PILOTOS]],Clasificación_General!C22:H62,6,0),0) -> 0 | G27: 7 | J27: =IFERROR(VLOOKUP(H27,Tabla13151617192021[[PILOTOS]:[PTOS.]],2,0),0) -> 0 | L27: 7 | O27: =IFERROR(VLOOKUP(M27,Tabla13151617192021[[PILOTOS]:[PTOS.]],2,0),0) -> 0
B28: =+B27+1 -> 21 | D28: =IFERROR(VLOOKUP(Tabla13151617192021[[#This Row],[PILOTOS]],Clasificación_General!C23:H63,6,0),0) -> 0 | G28: 8 | J28: =IFERROR(VLOOKUP(H28,Tabla13151617192021[[PILOTOS]:[PTOS.]],2,0),0) -> 0 | L28: 8 | O28: =IFERROR(VLOOKUP(M28,Tabla13151617192021[[PILOTOS]:[PTOS.]],2,0),0) -> 0
B29: =+B28+1 -> 22 | D29: =IFERROR(VLOOKUP(Tabla13151617192021[[#This Row],[PILOTOS]],Clasificación_General!C24:H64,6,0),0) -> 0
B30: =+B29+1 -> 23 | D30: =IFERROR(VLOOKUP(Tabla13151617192021[[#This Row],[PILOTOS]],Clasificación_General!C25:H65,6,0),0) -> 0 | G30: # | H30: PILOTO | I30: P SALIDA | J30: PTOS.
B31: =+B30+1 -> 24 | D31: =IFERROR(VLOOKUP(Tabla13151617192021[[#This Row],[PILOTOS]],Clasificación_General!C26:H66,6,0),0) -> 0 | G31: 1 | J31: =IFERROR(VLOOKUP(H31,Tabla13151617192021[[PILOTOS]:[PTOS.]],2,0),0) -> 0
B32: =+B31+1 -> 25 | D32: =IFERROR(VLOOKUP(Tabla13151617192021[[#This Row],[PILOTOS]],Clasificación_General!C27:H67,6,0),0) -> 0 | G32: 2 | J32: =IFERROR(VLOOKUP(H32,Tabla13151617192021[[PILOTOS]:[PTOS.]],2,0),0) -> 0
B33: =+B32+1 -> 26 | D33: =IFERROR(VLOOKUP(Tabla13151617192021[[#This Row],[PILOTOS]],Clasificación_General!C28:H68,6,0),0) -> 0 | G33: 3 | J33: =IFERROR(VLOOKUP(H33,Tabla13151617192021[[PILOTOS]:[PTOS.]],2,0),0) -> 0
B34: =+B33+1 -> 27 | D34: =IFERROR(VLOOKUP(Tabla13151617192021[[#This Row],[PILOTOS]],Clasificación_General!C29:H69,6,0),0) -> 0 | G34: 4 | J34: =IFERROR(VLOOKUP(H34,Tabla13151617192021[[PILOTOS]:[PTOS.]],2,0),0) -> 0
B35: =+B34+1 -> 28 | D35: =IFERROR(VLOOKUP(Tabla13151617192021[[#This Row],[PILOTOS]],Clasificación_General!C30:H70,6,0),0) -> 0 | G35: 5 | J35: =IFERROR(VLOOKUP(H35,Tabla13151617192021[[PILOTOS]:[PTOS.]],2,0),0) -> 0
B36: =+B35+1 -> 29 | D36: =IFERROR(VLOOKUP(Tabla13151617192021[[#This Row],[PILOTOS]],Clasificación_General!C31:H71,6,0),0) -> 0 | G36: 6 | J36: =IFERROR(VLOOKUP(H36,Tabla13151617192021[[PILOTOS]:[PTOS.]],2,0),0) -> 0
B37: =+B36+1 -> 30 | D37: =IFERROR(VLOOKUP(Tabla13151617192021[[#This Row],[PILOTOS]],Clasificación_General!C32:H72,6,0),0) -> 0 | G37: 7 | J37: =IFERROR(VLOOKUP(H37,Tabla13151617192021[[PILOTOS]:[PTOS.]],2,0),0) -> 0
B38: =+B37+1 -> 31 | D38: =IFERROR(VLOOKUP(Tabla13151617192021[[#This Row],[PILOTOS]],Clasificación_General!C33:H73,6,0),0) -> 0 | G38: 8 | J38: =IFERROR(VLOOKUP(H38,Tabla13151617192021[[PILOTOS]:[PTOS.]],2,0),0) -> 0
B39: =+B38+1 -> 32 | D39: =IFERROR(VLOOKUP(Tabla13151617192021[[#This Row],[PILOTOS]],Clasificación_General!C34:H74,6,0),0) -> 0
B40: =+B39+1 -> 33 | D40: =IFERROR(VLOOKUP(Tabla13151617192021[[#This Row],[PILOTOS]],Clasificación_General!C35:H75,6,0),0) -> 0
B41: =+B40+1 -> 34 | D41: =IFERROR(VLOOKUP(Tabla13151617192021[[#This Row],[PILOTOS]],Clasificación_General!C36:H76,6,0),0) -> 0
B42: =+B41+1 -> 35 | D42: =IFERROR(VLOOKUP(Tabla13151617192021[[#This Row],[PILOTOS]],Clasificación_General!C37:H77,6,0),0) -> 0
B43: =+B42+1 -> 36 | D43: =IFERROR(VLOOKUP(Tabla13151617192021[[#This Row],[PILOTOS]],Clasificación_General!C38:H78,6,0),0) -> 0
B44: =+B43+1 -> 37 | D44: =IFERROR(VLOOKUP(Tabla13151617192021[[#This Row],[PILOTOS]],Clasificación_General!C39:H79,6,0),0) -> 0
B45: =+B44+1 -> 38 | D45: =IFERROR(VLOOKUP(Tabla13151617192021[[#This Row],[PILOTOS]],Clasificación_General!C40:H80,6,0),0) -> 0
...

Sheet Verificaciones_SLOTSAB
B7: DATOS COCHES PARTICIPANTES
B10: # | C10: PILOTO | D10: COCHE | E10: MOTOR | F10: PESO C. | G10: PESO MIN. | H10: PIÑÓN | I10: CORONA | J10: REL | K10: LLANTAS D | L10: DIAMETRO LL.D. | M10: LLANTAS T | N10: DIAMETRO LL.T. | O10: TRENC. | P10: SUSP. | Q10: BANCADA | R10: CHASIS | S10: NEUMATICOS | T10: OBS. VERIFICACIÓN
B11: 1 | D11: MBAGT3 | G11: 18
B12: 2 | D12: MBAGT3 | G12: 18
B13: 3 | D13: MBAGT3 | G13: 18
B14: 4 | D14: MBAGT3 | G14: 18
B15: 5 | D15: MBAGT3 | G15: 18
B16: 6 | D16: MBAGT3 | G16: 18
B17: 7 | D17: MBAGT3 | G17: 18
B18: 8 | D18: MBAGT3 | G18: 18
B19: 9 | D19: MBAGT3 | G19: 18
B20: 10 | D20: MBAGT3 | G20: 18
B21: 11 | D21: MBAGT3 | G21: 18
B22: 12 | D22: MBAGT3 | G22: 18
... B54: 44 | D54: MBAGT3 | G54: 18
B63: DETALLE DEL COCHE GANADOR

Sheet Listado Pilotos
B2: Nombre Piloto | C2: Palmares | D2: Cat. De Piloto | F2: Equipo | G2: Piloto 1 | H2: Cat. De Piloto1 | I2: Piloto 2 | J2: Cat. De Piloto2 | K2: Copa | L2: Handicap
B3: Abel Vizu | C3: Sin palmarés | D3: =VLOOKUP(C3,Tabla_de_Datos_GENERALES!$B$9:$C$21,2,0) -> Bronce | F3: UNITED SOT | G3: Victor Gonzalez | H3: =VLOOKUP(G3,Tabla6[],3,) -> Plata | I3: Israel Nevado | J3: =VLOOKUP(I3,Tabla6[],3,) -> Plata | K3: SCALEAUTO_CUP
B4: Adam Parera | C4: Scaleauto 2019-2017 | D4: =VLOOKUP(C4,Tabla_de_Datos_GENERALES!$B$9:$C$21,2,0) -> Oro | F4: EL SOT SPORT | G4: Oscar Capel | H4: =VLOOKUP(G4,Tabla6[],3,) -> Oro | I4: Albert Trafach | J4: =VLOOKUP(I4,Tabla6[],3,) -> Oro | K4: SCALEAUTO_CUP
B5: Adolfo Chico | C5: Sin palmarés | D5: =VLOOKUP(C5,Tabla_de_Datos_GENERALES!$B$9:$C$21,2,0) -> Bronce | F5: EL SOT | G5: Alberto Bolsa | H5: =VLOOKUP(G5,Tabla6[],3,) -> Plata | I5: Jorge Valdivieso | J5: =VLOOKUP(I5,Tabla6[],3,) -> Bronce | K5: GT2
B6: Agusti Gutierrez | C6: GT2 Resisbarna 2019-2003 | D6: =VLOOKUP(C6,Tabla_de_Datos_GENERALES!$B$9:$C$21,2,0) -> Plata | F6: MADERA SOT | G6: Manel Soriano | H6: =VLOOKUP(G6,Tabla6[],3,) -> Bronce | I6: David Mercader | J6: =VLOOKUP(I6,Tabla6[],3,) -> Bronce | K6: GT1
B7: Albert Atienza | C7: Sin palmarés | D7: =VLOOKUP(C7,Tabla_de_Datos_GENERALES!$B$9:$C$21,2,0) -> Bronce | H7: =VLOOKUP(G7,Tabla6[],3,) -> #N/A | J7: =VLOOKUP(I7,Tabla6[],3,) -> #N/A
B8: Albert Castellar | C8: Sin palmarés | D8: =VLOOKUP(C8,Tabla_de_Datos_GENERALES!$B$9:$C$21,2,0) -> Bronce | H8: =VLOOKUP(G8,Tabla6[],3,) -> #N/A | J8: =VLOOKUP(I8,Tabla6[],3,) -> #N/A
B9: Albert Figuerola | C9: Sin palmarés | D9: =VLOOKUP(C9,Tabla_de_Datos_GENERALES!$B$9:$C$21,2,2) -> Oro | H9: =VLOOKUP(G9,Tabla6[],3,) -> #N/A | J9: =VLOOKUP(I9,Tabla6[],3,) -> #N/A
B10: Albert Lombarte | C10: 1-4 Victorias Resisbarna 2019-2003 | D10: =VLOOKUP(C10,Tabla_de_Datos_GENERALES!$B$9:$C$21,2,0) -> Plata | H10: =VLOOKUP(G10,Tabla6[],3,) -> #N/A | J10: =VLOOKUP(I10,Tabla6[],3,) -> #N/A
B11: Albert Ranera | C11: Resisbarna 2013-2003 | D11: =VLOOKUP(C11,Tabla_de_Datos_GENERALES!$B$9:$C$21,2,0) -> Plata | H11: =VLOOKUP(G11,Tabla6[],3,) -> #N/A | J11: =VLOOKUP(I11,Tabla6[],3,) -> #N/A
B12: Albert Tomas | C12: GT2 Resisbarna 2019-2003 | D12: =VLOOKUP(C12,Tabla_de_Datos_GENERALES!$B$9:$C$21,2,0) -> Plata | H12: =VLOOKUP(G12,Tabla6[],3,) -> #N/A | J12: =VLOOKUP(I12,Tabla6[],3,) -> #N/A
B13: Albert Trafach | C13: Top 10 Resisbarna 2019 | D13: =VLOOKUP(C13,Tabla_de_Datos_GENERALES!$B$9:$C$21,2,0) -> Oro | H13: =VLOOKUP(G13,Tabla6[],3,) -> #N/A | J13: =VLOOKUP(I13,Tabla6[],3,) -> #N/A
B14: Alberto Bolsa | C14: Scaleauto 2016-2015 | D14: =VLOOKUP(C14,Tabla_de_Datos_GENERALES!$B$9:$C$21,2,0) -> Plata | H14: =VLOOKUP(G14,Tabla6[],3,) -> #N/A | J14: =VLOOKUP(I14,Tabla6[],3,) -> #N/A
B15: Alex Marin | C15: WES 2019 -2017 | D15: =VLOOKUP(C15,Tabla_de_Datos_GENERALES!$B$9:$C$21,2,0) -> Platino | H15: =VLOOKUP(G15,Tabla6[],3,) -> #N/A | J15: =VLOOKUP(I15,Tabla6[],3,) -> #N/A
B16: Alex Robles | C16: WES 2019 -2017 | D16: =VLOOKUP(C16,Tabla_de_Datos_GENERALES!$B$9:$C$21,2,0) -> Platino | H16: =VLOOKUP(G16,Tabla6[],3,) -> #N/A | J16: =VLOOKUP(I16,Tabla6[],3,) -> #N/A
B17: Alfons Barcelo | C17: Sin palmarés | D17: =VLOOKUP(C17,Tabla_de_Datos_GENERALES!$B$9:$C$21,2,0) -> Bronce | H17: =VLOOKUP(G17,Tabla6[],3,) -> #N/A | J17: =VLOOKUP(I17,Tabla6[],3,) -> #N/A
B18: Alfons Unda | C18: WES 2019 -2017 | D18: =VLOOKUP(C18,Tabla_de_Datos_GENERALES!$B$9:$C$21,2,0) -> Platino | H18: =VLOOKUP(G18,Tabla6[],3,) -> #N/A | J18: =VLOOKUP(I18,Tabla6[],3,) -> #N/A
B19: Álvaro Basanta | C19: GT2 Resisbarna 2019-2003 | D19: =VLOOKUP(C19,Tabla_de_Datos_GENERALES!$B$9:$C$21,2,0) -> Plata | H19: =VLOOKUP(G19,Tabla6[],3,) -> #N/A | J19: =VLOOKUP(I19,Tabla6[],3,) -> #N/A
B20: Álvaro Iranzo | C20: WES 2019 -2017 | D20: =VLOOKUP(C20,Tabla_de_Datos_GENERALES!$B$9:$C$21,2,0) -> Platino | H20: =VLOOKUP(G20,Tabla6[],3,) -> #N/A | J20: =VLOOKUP(I20,Tabla6[],3,) -> #N/A
B21: Amadeu Pérez | C21: 1-4 Victorias Resisbarna 2019-2003 | D21: =VLOOKUP(C21,Tabla_de_Datos_GENERALES!$B$9:$C$21,2,0) -> Plata | H21: =VLOOKUP(G21,Tabla6[],3,) -> #N/A | J21: =VLOOKUP(I21,Tabla6[],3,) -> #N/A
... B86: Jose Maria Martinez | C86: Sin palmarés | D86: =VLOOKUP(C86,Tabla_de_Datos_GENERALES!$B$9:$C$21,2,0) -> Bronce | H86: =VLOOKUP(G86,Tabla6[],3,) -> #N/A | J86: =VLOOKUP(I86,Tabla6[],3,) -> #N/A
B87: Josep Cardona | C87: Resisbarna 2013-2003 | D87: =VLOOKUP(C87,Tabla_de_Datos_GENERALES!$B$9:$C$21,2,0) -> Plata
B88: Juan Ramon Mesas | C88: Sin palmarés | D88: =VLOOKUP(C88,Tabla_de_Datos_GENERALES!$B$9:$C$21,2,0) -> Bronce
B89: Juanjo Tíscar | C89: 1-4 Victorias Resisbarna 2019-2003 | D89: =VLOOKUP(C89,Tabla_de_Datos_GENERALES!$B$9:$C$21,2,0) -> Plata
B90: Juanra Mesas | C90: 1-4 Victorias Resisbarna 2019-2003 | D90: =VLOOKUP(C90,Tabla_de_Datos_GENERALES!$B$9:$C$21,2,0) -> Plata
B91: Julen Valbuena | C91: WES 2019 -2017 | D91: =VLOOKUP(C91,Tabla_de_Datos_GENERALES!$B$9:$C$21,2,0) -> Platino
B92: Lluis Arias | C92: Resisbarna 2013-2003 | D92: =VLOOKUP(C92,Tabla_de_Datos_GENERALES!$B$9:$C$21,2,0) -> Plata
B93: Lorenzo Lera | C93: Sin palmarés | D93: =VLOOKUP(C93,Tabla_de_Datos_GENERALES!$B$9:$C$21,2,0) -> Bronce
B94: Lorenzo Rodríguez | C94: GT2 Resisbarna 2019-2003 | D94: =VLOOKUP(C94,Tabla_de_Datos_GENERALES!$B$9:$C$21,2,0) -> Plata
B95: Lorenzo Vera | C95: Sin palmarés | D95: =VLOOKUP(C95,Tabla_de_Datos_GENERALES!$B$9:$C$21,2,0) -> Bronce
B96: Luis Aldea | C96: Sin palmarés | D96: =VLOOKUP(C96,Tabla_de_Datos_GENERALES!$B$9:$C$21,2,2) -> Oro
B97: Manel Soriano | C97: Sin palmarés | D97: =VLOOKUP(C97,Tabla_de_Datos_GENERALES!$B$9:$C$21,2,0) -> Bronce
B98: Manuel Marquez | C98: Sin palmarés | D98: =VLOOKUP(C98,Tabla_de_Datos_GENERALES!$B$9:$C$21,2,0) -> Bronce
B99: Marc Andreu | C99: 1-4 Victorias Resisbarna 2019-2003 | D99: =VLOOKUP(C99,Tabla_de_Datos_GENERALES!$B$9:$C$21,2,0) -> Plata
B100: Marc Casanovas | C100: WES 2019 -2017 | D100: =VLOOKUP(C100,Tabla_de_Datos_GENERALES!$B$9:$C$21,2,0) -> Platino
B101: Marc Climent | C101: Sin palmarés | D101: =VLOOKUP(C101,Tabla_de_Datos_GENERALES!$B$9:$C$21,2,0) -> Bronce
B102: Marc Garcia | C102: 5 victorias o mas 2016-2003 | D102: =VLOOKUP(C102,Tabla_de_Datos_GENERALES!$B$9:$C$21,2,0) -> Oro
B103: Marc Lansac | C103: WES 2019 -2017 | D103: =VLOOKUP(C103,Tabla_de_Datos_GENERALES!$B$9:$C$21,2,0) -> Platino
B104: Marc Manlleu | C104: 1-4 Victorias Resisbarna 2019-2003 | D104: =VLOOKUP(C104,Tabla_de_Datos_GENERALES!$B$9:$C$21,2,0) -> Plata
B105: Marc Miró | C105: Resisbarna 2013-2003 | D105: =VLOOKUP(C105,Tabla_de_Datos_GENERALES!$B$9:$C$21,2,0) -> Plata
...

Sheet Tabla_de_Datos_GENERALES
B2: Copas | D2: Cat. Pilotos | G2: Dia Carrera
B3: GT1 | D3: Platino | G3: Jueves
B4: GT2 | D4: Oro | G4: Viernes
B5: SCALEAUTO_CUP | D5: Palta | G5: Sabado
D6: Bronce
B8: Cat. Pilotos | C8: Tipo Cat.
B9: WES 2019 -2017 | C9: Platino
B10: Resisbarna 2019-2017 | C10: Platino
B11: 5 victorias o mas 2019-2017 | C11: Platino
B12: Resisbarna 2016-2015 | C12: Oro
B13: 5 victorias o mas 2016-2003 | C13: Oro
B14: Scaleauto 2019-2017 | C14: Oro
B15: Top 10 Resisbarna 2019 | C15: Oro
B16: Scaleauto 2016-2015 | C16: Plata
B17: Resisbarna 2013-2003 | C17: Plata
B18: 1-4 Victorias Resisbarna 2019-2003 | C18: Plata
B19: Top 20 Resisbarna 2019 | C19: Plata
... B21: Sin palmarés | C21: Bronce

Sheet Tabla_de_Datos_COCHES
B3: COCHE | C3: NOMBRE COMP. COCHE | D3: BRAND | E3: MIN WEIGHT | F3: GROUP | G3: COPA | I3: BRANDS | J3: NOMBRE | L3: RELACION
B4: GT3ITALIA | C4: GT3 Italia Black Arrow | D4: BLACK ARROW | E4: 15 | F4: 1 | G4: GT1 | I4: SIT | J4: Slot.it | L4: 12_28
B5: BLACKBULL | C5: Black Bull Black Arrow | D5: BLACK ARROW | E5: 15.5 | F5: 1 | G5: GT1 | I5: SLP | J5: Sloting Plus | L5: 12_27
B6: AMDBR9 | C6: AM DBR9 Black Arrow | D6: BLACK ARROW | E6: 18 | F6: 3 | G6: GT1 | I6: SCA | J6: Scaleauto | L6: 12_30
B7: MERCEDES | C7: Mercedes Benz SLS GT3 Scal. | D7: SCALEAUTO | E7: 17 | F7: 3 | G7: GT1 | I7: MB | J7: MB Slot
B8: HONDA | C8: Honda HSV-010GT Scaleauto | D8: SCALEAUTO | E8: 17 | F8: 2 | G8: GT1 | I8: REP | J8: Reprotec | L8: LLANTAS DIAMETRO
B9: BMW | C9: BMW Z4 GT3 Scaleauto | D9: SCALEAUTO | E9: 15 | F9: 3 | G9: GT1 | I9: SID | J9: Sideways | L9: 17,5 x 8 PL
B10: SPYKER | C10: Spyker GT2 Scaleauto | D10: SCALEAUTO | E10: 15 | F10: 1 | G10: GT1 | I10: ARS | J10: Arrow Slot | L10: 17,2 x 8 PL
B11: PORSCHE 991 | C11: Porsche 991 GT3 Scaleauto | D11: SCALEAUTO | E11: 17 | F11: 2 | G11: GT1 | I11: SCX | J11: Scalextric | L11: 16,9 x 8 PL
B12: VIPER | C12: Dodge Viper SRT GTS-R Scal. | D12: SCALEAUTO | E12: 17 | F12: 2 | G12: GT1 | I12: NIN | J12: Ninco | L12: 16,5 x 8 PL
B13: CORVETTE | C13: Corvette A7R Scaleauto | D13: SCALEAUTO | E13: 17 | F13: 2 | G13: GT1 | I13: BLA | J13: Black Arrow | L13: 16,3 x 8 PL
B14: SALEEN | C14: Saleen S7R Scaleauto | D14: SCALEAUTO | E14: 15 | F14: 1 | G14: GT1 | I14: PINK | J14: Pink Car | L14: 15,8 x 8 PL
B15: LMSGT3 | C15: Audi R8 LMS GT3 Scaleauto | D15: SCALEAUTO | E15: 17 | F15: 3 | G15: GT1 | I15: HOB | J15: Hobby Slot | L15: 17,5 x 8 AL
B16: MBAGT3 | C16: Mercedes Benz MB-A GT3 Scal. | D16: SCALEAUTO | E16: 18 | F16: 3 | G16: GT1 | I16: MR | J16: MR Slotcar | L16: 17,2 x 8 AL
B17: HURACAN | C17: Lamborghini Huracan GT3 Sidew. | D17: SIDEWAYS | E17: 18 | F17: 2 | G17: GT1 | I17: SUP | J17: Superslot | L17: 16,9 x 8 AL
B18: FORD GT | C18: Ford GT Morpheus | D18: MORPHEUS | E18: 18 | F18: 1 | G18: GT1 | I18: JP | J18: JP-Slot | L18: 16,5 x 8 AL
B19: MERCEDES | C19: Mercedes Benz SLS GT3 Scal. | D19: SCALEAUTO | E19: 17 | F19: 2 | G19: SCALEAUTO_CUP | I19: 3D | J19: 3DSRP | L19: 16,3 x 8 AL
... B24: VIPER | C24: Dodge Viper SRT GTS-R Scal. | D24: SCALEAUTO | E24: 17 | F24: 2 | G24: SCALEAUTO_CUP | I24: ACM | J24: ACME | L24: 16,5 x 10 PL
B25: CORVETTE | C25: Corvette A7R Scaleauto | D25: SCALEAUTO | E25: 17 | F25: 2 | G25: SCALEAUTO_CUP | L25: 16,3 x 10 PL
B26: LMSGT3 | C26: Audi R8 LMS GT3 Scaleauto | D26: SCALEAUTO | E26: 17 | F26: 2 | G26: SCALEAUTO_CUP | L26: 15,8 x 10 PL
B27: MBAGT3 | C27: Mercedes Benz MB-A GT3 Scal. | D27: SCALEAUTO | E27: 18 | F27: 2 | G27: SCALEAUTO_CUP | I27: TYRES | J27: REFERENCIA | L27: 17,5 x 10 AL
B28: GT3ITALIA | C28: GT3 Italia Black Arrow | D28: BLACK ARROW | E28: 15 | F28: 1 | G28: GT2 | I28: SPIRITS | J28: SC-4735 "Spirits" | L28: 17,2 x 10 AL
B29: BLACKBULL | C29: Black Bull Black Arrow | D29: BLACK ARROW | E29: 15.5 | F29: 1 | G29: GT2 | I29: F22 | J29: Slot.it PT1207 "F22" | L29: 16,9 x 10 AL
B30: AMDBR9 | C30: AM DBR9 Black Arrow | D30: BLACK ARROW | E30: 18 | F30: 3 | G30: GT2 | I30: IS25 | J30: SC-4753 "I-S25" | L30: 16,5 x 10 AL
B31: MERCEDES | C31: Mercedes Benz SLS GT3 Scal. | D31: SCALEAUTO | E31: 17 | F31: 3 | G31: GT2 | I31: AS25 | J31: SC-4758 "A-S25" | L31: 16,3 x 10 AL
B32: HONDA | C32: Honda HSV-010GT Scaleauto | D32: SCALEAUTO | E32: 17 | F32: 2 | G32: GT2 | L32: 15,8 x 10 AL
B33: BMW | C33: BMW Z4 GT3 Scaleauto | D33: SCALEAUTO | E33: 15 | F33: 3 | G33: GT2 | I33: MOTOR MOUNTS | J33: ESPECS
B34: SPYKER | C34: Spyker GT2 Scaleauto | D34: SCALEAUTO | E34: 15 | F34: 1 | G34: GT2 | I34: SIT0 | J34: Slot.it 0,0
B35: PORSCHE 991 | C35: Porsche 991 GT3 Scaleauto | D35: SCALEAUTO | E35: 17 | F35: 2 | G35: GT2 | I35: SIT05 | J35: Slot.it 0,5
B36: VIPER | C36: Dodge Viper SRT GTS-R Scal. | D36: SCALEAUTO | E36: 17 | F36: 2 | G36: GT2 | I36: SIT1 | J36: Slot.it 1,0
B37: CORVETTE | C37: Corvette A7R Scaleauto | D37: SCALEAUTO | E37: 17 | F37: 2 | G37: GT2 | I37: SCA1 | J37: Scaleauto 1,0
B38: SALEEN | C38: Saleen S7R Scaleauto | D38: SCALEAUTO | E38: 15 | F38: 1 | G38: GT2 | I38: BLA05 | J38: Black Arrow 0,5
B39: LMSGT3 | C39: Audi R8 LMS GT3 Scaleauto | D39: SCALEAUTO | E39: 17 | F39: 3 | G39: GT2
B40: MBAGT3 | C40: Mercedes Benz MB-A GT3 Scal. | D40: SCALEAUTO | E40: 18 | F40: 3 | G40: GT2
B41: HURACAN | C41: Lamborghini Huracan GT3 Sidew. | D41: SIDEWAYS | E41: 18 | F41: 2 | G41: GT2
B42: FORD GT | C42: Ford GT Morpheus | D42: MORPHEUS | E42: 18 | F42: 1 | G42: GT2

Sheet CUADRO GENERAL
C2: PILOTO 1 | D2: PILOTO 2 | E2: RESISBARNA | H2: COPA SCALEAUTO | J2: GT2 | L2: HÁNDICAPS
E3: 1 AL 10 | F3: 11 AL 20 | G3: 21 o más | H3: HANDICAP | I3: EQUIPO | J3: EQUIPO
C4: PLATINO | D4: PLATINO | E4: H1 | F4: H2 | G4: H2 | H4: HS1 | I4: OK | J4: X | L4: GENERAL
M5: GRUP 1 | N5: GRUP 2 | O5: GRUP 3
C6: PLATINO | D6: ORO | E6: H1 | F6: H2 | G6: H3 | H6: HS1 | I6: OK | J6: X | L6: H1 | M6: 3 | N6: 3 | O6: 2
L7: H2 | M7: 4 | N7: 3 | O7: 1
C8: PLATINO | D8: PLATA | E8: H1 | F8: H2 | G8: H3 | H8: HS2 | I8: OK | J8: X | L8: H3 | M8: 4 | N8: 4 | O8: 0
L9: COPA SCALEAUTO
C10: PLATINO | D10: BRONCE | E10: H1 | F10: H2 | G10: H3 | H10: HS2 | I10: OK | J10: X
L11: HS1 | M11: 4 COCHES
C12: ORO | D12: ORO | E12: H1 | F12: H2 | G12: H3 | H12: HS2 | I12: OK | J12: X | L12: HS2 | M12: 3 COCHES
C14: ORO | D14: PLATA | F14: H2 | I14: OK | J14: X
C16: ORO | D16: BRONCE | F16: H2 | I16: OK | J16: OK
C18: PLATA | D18: PLATA | F18: H2 | I18: OK | J18: OK
C20: PLATA | D20: BRONCE | F20: H2 | I20: OK | J20: OK
C22: BRONCE | D22: BRONCE | I22: OK | J22: OK
C26: RELACIÓN DE HÁNDICAPS | L26: COPA SCALEAUTO
C28: H1 HÁNDICAP 1 | E28: H2 HÁNDICAP 2 | G28: H3 HÁNDICAP 3 | I28: SIN HÁNDICAP | L28: HS1 4 modelos | N28: HS2 3 modelos | P28: LIBRE ELECCIÓN
C29: Top 10 Resisbarna 2019 | E29: Top 20 Resisbarna 2019 | G29: Platino-Oro | I29: Oro-Plata | L29: Platino-Platino | N29: Platino-Plata | P29: Oro-Plata
E30: Platino-Platino | G30: Platino-Bronce | I30: Oro-Bronce | L30: Platino-Oro | N30: Platino-Bronce | P30: Oro-Bronce
G31: Platino-Plata | I31: Plata-Plata | N31: Oro-Oro | P31: Plata-Plata
G32: Oro-Oro | I32: Plata-Bronce | P32: Plata-Bronce
I33: Bronce-Bronce | P33: Bronce-Bronce
C34: RESISBARNA GT2
C36: ABIERTA | F36: VETADA
C38: Oro-Bronce | F38: Platino-Platino
C39: Bronce-Bronce | F39: Platino-Oro
C40: Plata-Plata | F40: Oro-Oro
C41: Plata-Bronce | F41: Oro-Plata
C44: INDICADORES DEL HÁNDICAP
C46: PLATINO | G46: ORO | L46: PLATA
C47: Campeones Resisbarna | E47: 2017-2018-2019 | G47: Campeones Resisbarna | I47: 2015-2019 | L47: Campeones Resisbarna | O47: 2003-20013
C48: Podios en WES 24h | E48: 2017-2018-2019 | G48: 5 o más vitorias | I48: 2003 a 2016 | L48: 1-4 Victorias Resisbarna | O48: 2003-2019
C49: 5 o más victorias | E49: 2017-2018-2019 | G49: Campeones Copa SCA | I49: 2017-2018-2019 | L49: Top 20 Resisbarna | O49: 2019
G50: Top 10 Resisbarna | I50: 2019 | L50: Campeones Copa SCALEAUTO | O50: 2015-2016
L51: Campeones Resisbarna GT2 | O51: 2003-2019

Sheet Clasificación_General
B2: POS. | C2: PILOTO | D2: EL SOT | E2: SLOT FOR YOU | F2: SLOT CAR | G2: SLOT SAB | H2: TOTAL
B3: 1 | H3: =G3+F3+E3+D3 -> 0
B4: 2 | H4: =G4+F4+E4+D4 -> 0
B5: 3 | H5: =G5+F5+E5+D5 -> 0
B6: 4 | H6: =G6+F6+E6+D6 -> 0
B7: 5 | H7: =G7+F7+E7+D7 -> 0
B8: 6 | H8: =G8+F8+E8+D8 -> 0
B9: 7 | H9: =G9+F9+E9+D9 -> 0
B10: 8 | H10: =G10+F10+E10+D10 -> 0
B11: 9 | H11: =G11+F11+E11+D11 -> 0
B12: 9 | H12: =G12+F12+E12+D12 -> 0
B13: 11 | H13: =G13+F13+E13+D13 -> 0
B14: 12 | H14: =G14+F14+E14+D14 -> 0
... B43: 41 | H43: =G43+F43+E43+D43 -> 0

Sheet Clasificacion_final_2019
B2: POS. | C2: PILOTO | D2: DREAM SLOT | E2: SLOT FOR YOU | F2: CLUB EL SOT | G2: SLOTMANIA | H2: TOTAL | I2: TOTAL FINAL
B3: 1 | C3: BESAY PORTA | D3: 70 | E3: 70 | F3: 70 | G3: 70 | H3: 280 | I3: 280
B4: 2 | C4: JM MOLINS | D4: 64 | E4: 64 | F4: 64 | G4: 64 | H4: 256 | I4: 256
B5: 3 | C5: EDUARD CERDA | D5: 44 | E5: 59 | F5: 55 | G5: 55 | H5: 213 | I5: 213
B6: 4 | C6: JM SEREROLS | D6: 50 | E6: 52 | F6: 46 | G6: 50 | H6: 198 | I6: 198
B7: 5 | C7: CARLES CARREÑO | D7: 41 | E7: 55 | F7: 44 | G7: 48 | H7: 188 | I7: 188
B8: 6 | C8: MARC LANSAC | D8: 52 | E8: 44 | F8: 42 | G8: 42 | H8: 180 | I8: 180
B9: 7 | C9: JOEL MENDIZABAL | D9: 48 | E9: 35 | F9: 38 | G9: 46 | H9: 167 | I9: 167
B10: 8 | C10: JORDI ROBLES | D10: 46 | E10: 42 | F10: 31 | G10: 44 | H10: 163 | I10: 163
B11: 9 | C11: ADAM PARERA | D11: 43 | E11: 43 | F11: 34 | G11: 35 | H11: 155 | I11: 155
B12: 9 | C12: JULEN VALBUENA | D12: 37 | E12: 40 | F12: 40 | G12: 38 | H12: 155 | I12: 155
B13: 11 | C13: RICHARD ARREDONDO | D13: 40 | E13: 37 | F13: 37 | G13: 40 | H13: 154 | I13: 154
B14: 12 | C14: DAVID IZQUIERDO | D14: 38 | E14: 38 | F14: 41 | G14: 34 | H14: 151 | I14: 151
... B18: 16 | C18: ALBERT TOMAS | D18: 31 | E18: 33 | F18: 29 | G18: 39 | H18: 132 | I18: 132
B19: 17 | C19: GABRIEL RODRIGUEZ | E19: 50 | F19: 48 | G19: 33 | H19: 131 | I19: 131
B20: 18 | C20: VICENS FEBRERO | D20: 39 | E20: 28 | F20: 24 | G20: 37 | H20: 128 | I20: 128
B21: 19 | C21: MANEL SORIANO | D21: 24 | E21: 30 | F21: 43 | G21: 29 | H21: 126 | I21: 126
B22: 19 | C22: ANGEL NAVARRO | D22: 30 | E22: 32 | F22: 28 | G22: 36 | H22: 126 | I22: 126
B23: 21 | C23: GERMA PORTET | D23: 55 | E23: 31 | F23: 36 | H23: 122 | I23: 122
B24: 22 | C24: JORDI PEREZ | D24: 33 | E24: 36 | F24: 20 | G24: 24 | H24: 113 | I24: 113
B25: 23 | C25: VICTOR GONZALEZ | D25: 27 | E25: 34 | F25: 23 | G25: 27 | H25: 111 | I25: 111
B26: 24 | C26: ISRAEL NEVADO | D26: 28 | E26: 26 | F26: 22 | G26: 26 | H26: 102 | I26: 102
B27: 25 | C27: JAUME LLOBET | D27: 25 | E27: 25 | F27: 19 | G27: 28 | H27: 97 | I27: 97
B28: 26 | C28: ISRAEL GOMEZ | F28: 50 | G28: 43 | H28: 93 | I28: 93
B29: 27 | C29: POL GARCIA | D29: 59 | F29: 26 | H29: 85 | I29: 85
B30: 28 | C30: JORDI RIEROLA | D30: 36 | E30: 48 | H30: 84 | I30: 84
B31: 29 | C31: OSCAR VILA | E31: 27 | F31: 21 | G31: 25 | H31: 73 | I31: 73
B32: 30 | C32: ERIC RUIZ | D32: 29 | F32: 33 | H32: 62 | I32: 62
B33: 31 | C33: JOSEP MARIA MARTINEZ | E33: 29 | F33: 18 | H33: 47 | I33: 47
B34: 32 | C34: VICTOR QUEROL | D34: 26 | F34: 17 | H34: 43 | I34: 43
B35: N/P | C35: OSCAR CAPEL | F35: 59 | H35: 59 | I35: 0
B36: N/P | C36: ORIOL CAPDEVILA | G36: 59 | H36: 59 | I36: 0
B37: N/P | C37: GUILLEM ROMERO | F37: 52 | H37: 52 | I37: 0
B38: N/P | C38: RUBEN SANCHEZ | G38: 52 | H38: 52 | I38: 0
B39: N/P | C39: LORENZO RODRIGUEZ | F39: 39 | H39: 39 | I39: 0
B40: N/P | C40: JORDI MIRANDA | D40: 32 | H40: 32 | I40: 0
B41: N/P | C41: IVAN GIMENO | G41: 31 | H41: 31 | I41: 0
B42: N/P | C42: ALBERTO BOLSA | F42: 30 | H42: 30 | I42: 0
B43: N/P | C43: CARLOS REPISO | F43: 27 | H43: 27 | I43: 0

Sheet OLD_Cuadros resumen
B5: Hándicap 1 | C5: Hándicap 2 | D5: Hándicap 3 | E5: Sin Hándicap
B6: Top 10 Resisbarna 2019 | C6: Top 20 Resisbarna 2019 | D6: Platino-Oro | E6: Oro-Bronce
C7: Platino-Platino | D7: Platino-Bronce | E7: Bronce-Bronce
D8: Oro-Oro | E8: Oro-Plata
D9: Platino-Plata | E9: Plata-Plata
E10: Plata-Bronce
B12: Copa Scaleauto | C12: Hándicap 4 modelos | D12: Hándicap 3 modelos | E12: Libertad de modelos
C13: Platino-Platino | D13: Platino-Plata | E13: Oro-Plata
C14: Platino-Oro | D14: Platino-Bronce | E14: Oro-Bronce
D15: Oro-Oro | E15: Plata-Plata
E16: Plata-Bronce
E17: Bronce-Bronce
B19: Resisbarna GT2 | C19: Abierta | D19: Vetada
C20: Oro-Bronce | D20: Platino-Platino
C21: Bronce-Bronce | D21: Platino-Oro
C22: Plata-Plata | D22: Oro-Oro
C23: Plata-Bronce | D23: Oro-Plata
B26: Platino | D26: Oro | F26: Plata
B27: Campeones Resisbarna | C27: 2017-2018-2019 | D27: Campeones Resisbarna | E27: 2015-2019 | F27: Campeones Resisbarna | G27: 2003-20013
B28: Podios en WES 24h | C28: 2017-2018-2019 | D28: 5 o más vitorias | E28: 2003 a 2016 | F28: Victorias Resisbarna | G28: 2003-2014
