Workbook

Sheet clasificacion2020_up2
A3: RESISBARNA 2020 - CLASIFICACION GENERAL POR PILOTOS
A7: POS | B7: PILOTO | C7: EQUIPO DEL PILOTO | D7: CLUB EL SOT | E7: SLOT 4 YOU | F7: GAS CLAVAT | G7: ESCUD. CRONO | H7: SLOT SAB | I7: SCM BDN | J7: SLOT CAR | K7: TOTAL
A8: 1 | B8: IGNASI BALDOMINOS | C8: SLOTMANIA | D8: 70 | E8: 64 | F8: 70 | G8: 70 | K8: 274
A9: 1 | B9: BESAY PORTA | C9: SLOTMANIA | D9: 70 | E9: 64 | F9: 70 | G9: 70 | K9: 274
A10: 2 | B10: JOSEP Mª SEREROLS | C10: EL SOT-TEAM | D10: 52 | E10: 50 | F10: 52 | G10: 50 | K10: 204
A11: 2 | B11: EDUARD CERDA | C11: EL SOT-TEAM | D11: 52 | E11: 50 | F11: 52 | G11: 50 | K11: 204
A12: 2 | B12: ALEX ROBLES | C12: EL SOT-FU | D12: 55 | E12: 46 | F12: 48 | G12: 55 | K12: 204
A13: 2 | B13: JORDI ROBLES | C13: EL SOT-FU | D13: 55 | E13: 46 | F13: 48 | G13: 55 | K13: 204
A14: 2 | B14: MIQUEL BONAVIDA | C14: EL SOT-HORTA | D14: 43 | E14: 48 | F14: 55 | G14: 58 | K14: 204
A15: 2 | B15: LORENZO RODRIGUEZ | C15: EL SOT-HORTA | D15: 43 | E15: 48 | F15: 55 | G15: 58 | K15: 204
A16: 3 | B16: XAVI CORTADA | C16: HOT SLOT FOR YOU | D16: 50 | E16: 55 | F16: 46 | G16: 51 | K16: 202
A17: 3 | B17: ADAM PARERA | C17: HOT SLOT FOR YOU | D17: 50 | E17: 55 | F17: 46 | G17: 51 | K17: 202
A18: 4 | B18: GABRIEL RODRIGUEZ | C18: STP-RACING | D18: 42 | E18: 44 | F18: 53 | G18: 62 | K18: 201
A19: 4 | B19: RICHARD ARREDONDO | C19: STP-RACING | D19: 42 | E19: 44 | F19: 53 | G19: 62 | K19: 201
... A21: 4 | B21: VICENS FEBRERO | C21: SLOT FOR YOU | D21: 59 | E21: 34 | F21: 44 | G21: 64 | K21: 201
A22: 5 | B22: JULEN VALBUENA | C22: ARREPLEGATS | D22: 64 | E22: 70 | F22: 59 | K22: 193
A23: 5 | B23: GERMA PORTET | C23: ARREPLEGATS | D23: 64 | E23: 70 | F23: 59 | K23: 193
A24: 6 | B24: MARC LANSAC | C24: ARREPLEGATS TECH | D24: 36 | E24: 59 | F24: 64 | K24: 159
A25: 7 | B25: ISRAEL NEVADO | C25: DZERO SOT | D25: 40 | E25: 32 | F25: 34 | G25: 40 | K25: 146
A26: 7 | B26: VICTOR GONZALEZ | C26: DZERO SOT | D26: 40 | E26: 32 | F26: 34 | G26: 40 | K26: 146
A27: 8 | B27: MANEL SORIANO | C27: OSOTNA | D27: 38 | E27: 28 | F27: 30 | G27: 47 | K27: 143
A28: 8 | B28: DAVID MERCADER | C28: OSOTNA | D28: 38 | E28: 28 | F28: 30 | G28: 47 | K28: 143
A29: 9 | B29: JORGE VALDIVIESO | C29: EL SOT-CALAVERAS | D29: 33 | E29: 36 | F29: 35 | G29: 38 | K29: 142
A30: 9 | B30: ALBERTO BOLSA | C30: EL SOT-CALAVERAS | D30: 33 | E30: 36 | F30: 35 | G30: 38 | K30: 142
A31: 10 | B31: XAVI BELLOT | C31: GASCLAVAT-FEELGOOD | D31: 28 | E31: 31 | F31: 43 | G31: 39 | K31: 141
A32: 10 | B32: CRISTIAN DIAZ | C32: GASCLAVAT-FEELGOOD | D32: 28 | E32: 31 | F32: 43 | G32: 39 | K32: 141
A33: 11 | B33: ALBERT FIGUEROLA | C33: TRELEC | D33: 32 | E33: 30 | F33: 33 | G33: 41 | K33: 136
A34: 12 | B34: CESC FIGUERAS | C34: TRELEC | D34: 32 | E34: 30 | F34: 33 | G34: 41 | K34: 136
A35: 12 | B35: OSCAR CAPEL | C35: EL SOT-SPORT | D35: 44 | E35: 52 | G35: 37 | K35: 133
A36: 13 | B36: SERGI SALADRIGAS | C36: SLOT FOR YOU-CUIDADIN | E36: 38 | F36: 42 | G36: 46 | K36: 126
A37: 13 | B37: MARC CASANOVAS | C37: SLOT FOR YOU-CUIDADIN | E37: 38 | F37: 42 | G37: 46 | K37: 126
A38: 14 | B38: OSCAR VILA | C38: SLOTFOURMANIA | D38: 25 | E38: 26 | F38: 34 | G38: 40 | K38: 125
A39: 15 | B39: JORDI SIMO | C39: ESTEL·LATS | D39: 39 | E39: 43 | G39: 42 | K39: 124
A40: 15 | B40: ENRIC ILLA | C40: ESTEL·LATS | D40: 39 | E40: 43 | G40: 42 | K40: 124
A41: 16 | B41: JORDI PEREZ | C41: ARREPLEGATS TECH | E41: 59 | F41: 64 | K41: 123
A42: 16 | B42: SERGI MARTINEZ | C42: SLOTSAB-JUNIOR | D42: 37 | E42: 42 | G42: 44 | K42: 123
A43: 16 | B43: VICTOR LEON | C43: SLOTSAB-JUNIOR | D43: 37 | E43: 42 | G43: 44 | K43: 123
A44: 17 | B44: CARLES CARREÑO | C44: ARREPLEGATS RALLY | D44: 36 | E44: 42 | F44: 43 | K44: 121
A45: 18 | B45: RAUL RAMIREZ | C45: TOAD TEAM | E45: 35 | F45: 37 | G45: 46 | K45: 118
A46: 19 | B46: EDUARD GIL | C46: SLOTMANIA-CAR | D46: 29 | E46: 40 | G46: 37 | K46: 106
...

Sheet Mangas_slotsab_Web 
A2: RESISBARNA 2020 - 5A. CARRERA
A3: SLOTSAB 1 - 3 OCTUBRE
A6: COMPOSICION MANGAS
A7: ACTUALIZADAS 14/9/2020
A10: VERIFICACIÓN Y WARM UP CON MULETO DE 20:00 a 20:30
A11: MANGA JUEVES 20:30 Horas
A13: # | B13: EQUIPO | C13: PILOTO | D13: PTOS. | E13: PILOTO | F13: PTOS. | G13: TOTAL | H13: COPA | I13: CARIL SALIDA
A14: 1 | B14: DZERO SOT | C14: Israel Nevado | D14: 146 | E14: Victor Gonzalez | F14: 146 | G14: 292 | H14: SCALEAUTO_CUP | I14: 1
A15: 2 | B15: SLOTFOURMANIA | C15: Jaume Llobet | D15: 85 | E15: Oscar Vila | F15: 125 | G15: 210 | H15: GT2 | I15: 2
A16: 3 | B16: SLOTSAB JOOS | C16: Oscar Sanchez | D16: 89 | E16: Jose Maria Martinez | F16: 89 | G16: 178 | H16: SCALEAUTO_CUP | I16: 6
A17: 4 | B17: NOUTEAM SLOT_ | C17: Jordi Muñoz | D17: 82 | E17: David Vendrell | F17: 54 | G17: 136 | H17: GT2 | I17: 4
A18: 5 | B18: MILLUI | C18: Lluis aldea | D18: 79 | E18: Miki Teres | F18: 31 | G18: 110 | H18: GT2
A19: 6 | B19: SAB ARRAS | C19: Raul Egea | D19: 50 | E19: Abel Vizu | F19: 50 | G19: 100 | H19: SCALEAUTO_CUP | I19: 3
A22: VERIFICACIÓN Y WARM UP CON MULETO DE 22:40 a 23:10
A23: MANGA JUEVES 23:10 Horas
A25: # | B25: EQUIPO | C25: PILOTO | D25: PTOS. | E25: PILOTO | F25: PTOS. | G25: TOTAL | H25: COPA | I25: CARIL SALIDA
A26: 1
A27: 2
A28: 3
A29: 4
A30: 5
A31: 6
A34: VERIFICACIÓN Y WARM UP CON MULETO DE 20:30 a 21:00
A35: MANGA VIERNES 21:00 Horas
A37: # | B37: EQUIPO | C37: PILOTO | D37: PTOS. | E37: PILOTO | F37: PTOS. | G37: TOTAL | H37: COPA | I37: CARIL SALIDA
A38: 1 | B38: EL SOT CALAVERAS | C38: Jorge Valdivieso | D38: 142 | E38: Alberto Bolsa | F38: 142 | G38: 284 | H38: GT2 | I38: D2
A39: 2 | B39: SLOT4YOU CUIDADIN | C39: Sergi Saladrigas | D39: 126 | E39: Marc Casanovas | F39: 126 | G39: 252 | H39: SCALEAUTO_CUP | I39: D1
A40: 3 | B40: ESTEL·LATS | C40: Enric Illa | D40: 124 | E40: Jordi Simo | F40: 124 | G40: 248 | H40: RESISBARNA | I40: 4
A41: 4 | B41: SLOTSAB JUNIOR | C41: Sergi Martinez | D41: 123 | E41: Victor Leon | F41: 123 | G41: 246 | H41: SCALEAUTO_CUP | I41: 1
A42: 5 | B42: TOAD TEAM | C42: Raul Ramírez | D42: 118 | E42: Joan Fontanals | F42: 72 | G42: 190 | H42: GT2 | I42: 2
A43: 6 | B43: SLOTMANIA CAR | C43: Eduard Gil | D43: 106 | E43: Adolfo Chico | F43: 37 | G43: 143 | H43: RESISBARNA | I43: 6
A44: 7 | B44: EQUIP VALLES | C44: Dani Gonzalez | D44: 38 | E44: Valeri Jonama | F44: 84 | G44: 122 | H44: RESISBARNA | I44: 5
A45: 8 | B45: CRONO1_ | C45: Javier Muñoz | D45: 85 | E45: Marius Magro | F45: 24 | G45: 109 | H45: SCALEAUTO_CUP | I45: 3
A48: VERIFICACIÓN Y WARM UP CON MULETO DE 23:00 a 23:30
A49: MANGA VIERNES 23:30 Horas
A51: # | B51: EQUIPO | C51: PILOTO | D51: PTOS. | E51: PILOTO | F51: PTOS. | G51: TOTAL | H51: COPA | I51: CARIL SALIDA
A52: 1 | B52: SLOTMANIA | C52: Besay Porta | D52: 274 | E52: Ignasi Baldominos | F52: 274 | G52: 548 | H52: RESISBARNA | I52: D1
A53: 2 | B53: EL SOT FU | C53: Alex Robles | D53: 204 | E53: Jordi Robles | F53: 204 | G53: 408 | H53: RESISBARNA | I53: 1
A54: 3 | B54: EL SOT TEAM | C54: JM Sererols | D54: 204 | E54: Eduard Cerda | F54: 204 | G54: 408 | H54: SCALEAUTO_CUP | I54: 2
A55: 4 | B55: EL SOT HORTA | C55: Miquel Bonavida | D55: 204 | E55: Lorenzo Rodriguez | F55: 204 | G55: 408 | H55: RESISBARNA | I55: 4
...

Sheet Inscritos_ENTRENOS_SLOTSAB
B3: ENTRENAMIENTOS SLOTSAB
B7: LUNES 17:00 | C7: LUNES 20:00 | D7: MARTES 17:00 | E7: MARTES 20:00 | F7: MIERCOLES 17:00 | G7: MIERCOLES 20:00 | H7: JUEVES DIA CARRERA | I7: VIERNES DIA CARRERA | J7: SABADO DIA CARRERA
A8: 1 | B8: ALBERT FIGUEROLA | C8: CRISTIAN DIAZ | D8: ALBERT FIGUEROLA | E8: JORDI SIMO | F8: EDUARD CERDA | G8: JORDI SIMO | H8: DAVID VENDRELL | I8: JAVI MUÑOZ | J8: RAFA
A9: 2 | B9: CESC FIGUERAS | C9: XAVI BELLOT | D9: CESC FIGUERAS | E9: ADAM PARERA | F9: JM SEREROLS | G9: EDUARD CERDA | H9: JORDI MUÑOZ | I9: MARIUS | J9: VICTOR LOPEZ
A10: 3 | B10: CRISTIAN DIAZ | C10: VICTOR GONZALEZ | D10: ALEX ROBLES | E10: XAVI CORTADA | F10: LORENZO RODRIGUEZ | G10: JM SEREROLS | H10: JAUME LLOBET | I10: VALERI | J10: EDU GIL
A11: 4 | B11: XAVI BELLOT | C11: ISRAEL NEVADO | D11: JORDI ROBLES | E11: JOEL MENDIZABAL | F11: MIQUEL BONAVIDA | G11: VICTOR GONZALEZ | I11: DANI GONZALEZ | J11: ADOLFO CHICO
A12: 5 | B12: ALEX ROBLES | C12: RICHARD ARREDONDO | D12: LLUIS ALDEA | E12: VICENS FEBRERO | F12: ALBERTO BOLSA | G12: ISRAEL NEVADO
A13: 6 | B13: JORDI ROBLES | C13: GABRIEL RODRIGUEZ | D13: MIKI TERES | E13: LLUIS ALDEA | G13: ADAM PARERA
A14: 7 | B14: LORENZO RODRIGUEZ | C14: TONI TORO | D14: MANEL SORIANO | E14: MIKI TERES | G14: XAVI CORTADA | I14: MARC CASANOVAS
A15: 8 | D15: DAVID MERCADER | E15: MANEL SORIANO | G15: JOEL MENDIZABAL | I15: SERGI SALADRIGAS
A16: 9 | D16: JOAN FONTANALS | E16: DAVID MERCADER | G16: VICENS FEBRERO | I16: ENRIC ILLA
A17: 10 | D17: RAUL RAMIEZ | E17: JOAN FONTANALS | G17: RICHARD ARREDONDO | I17: BESAY PORTA
A18: 11 | E18: RAUL RAMIEZ | G18: GABRIEL RODRIGUEZ | I18: IGNASI BALDOMINOS
A19: 12 | E19: OSCAR VILA | G19: MIQUEL BONAVIDA
A20: 13 | G20: ALBERTO BOLSA
A21: 14
I23: RAUL EGEA
I24: ABEL VIZUETE

Sheet Mangas_SCM_Web
A2: RESISBARNA 2020 - 6A. CARRERA
A3: SCM 15-16-17 OCTUBRE 2020
A6: COMPOSICION MANGAS (Act. 12/07/2020)
A10: VERIFICACIÓN Y WARM UP CON MULETO DE 20:30 a 21:00
A11: MANGA JUEVES 21:10 Horas
A13: # | B13: EQUIPO | C13: PILOTO | D13: PTOS. | E13: PILOTO | F13: PTOS. | G13: TOTAL
A14: 1 | B14: TRELEC | C14: Albert Figuerola | D14: 185 | E14: Cesc Figueras | F14: 185 | G14: 370 | H14: GT2
A15: 2 | B15: GASCLAVAT FEELGOOD | C15: Xavi Bellot | D15: 180 | E15: Cristian Diaz | F15: 180 | G15: 360 | H15: GT2
A16: 3 | B16: DZERO SOT | C16: Israel Nevado | D16: 178 | E16: Victor Gonzalez | F16: 178 | G16: 356 | H16: SCALEAUTO_CUP
A17: 4 | B17: EL SOT CALAVERAS | C17: Jorge Valdivieso | D17: 178 | E17: Alberto Bolsa | F17: 178 | G17: 356 | H17: GT2
A18: 5 | B18: SLOTFOURMANIA | C18: Jaume Llobet | D18: 116 | E18: Oscar Vila | F18: 156 | G18: 272 | H18: GT2
A19: 6 | B19: NOUTEAM SLOT_ | C19: Jordi Muñoz | D19: 111 | E19: David Vendrell | F19: 83 | G19: 194 | H19: GT2
A20: 7 | B20: SCM | C20: Edgar Carmona | D20: 58 | E20: Jordi Cantos | F20: 136 | G20: 194 | H20: GT2
A21: 8 | B21: SLOTSAB OSJO | C21: Jose Maria Martinez | D21: 128 | E21: Guillem Asins | F21: 0 | G21: 128 | H21: SCALEAUTO_CUP
A22: 9 | B22: SCM BIKES | C22: Fede Sanchez | D22: 0 | E22: Sergio Diaz | F22: 0 | G22: 0 | H22: GT2
A26: VERIFICACIÓN Y WARM UP CON MULETO DE 20:00 a 20:30
A27: MANGA VIERNES 20:30 Horas
A29: # | B29: EQUIPO | C29: PILOTO | D29: PTOS. | E29: PILOTO | F29: PTOS. | G29: TOTAL
A30: 1 | B30: STP RACING | C30: Richard Arredondo | D30: 201 | E30: Gabriel Rodriguez | F30: 241 | G30: 442 | H30: RESISBARNA
A31: 2 | B31: SLOTSAB JUNIOR | C31: Sergi Martinez | D31: 187 | E31: Victor Leon | F31: 187 | G31: 374 | H31: SCALEAUTO_CUP
A32: 3 | B32: OSOTNA | C32: Manel Soriano | D32: 186 | E32: David Mercader | F32: 186 | G32: 372 | H32: RESISBARNA
A33: 4 | B33: ESTEL·LATS | C33: Enric Illa | D33: 175 | E33: Jordi Simo | F33: 175 | G33: 350 | H33: RESISBARNA
A34: 5 | B34: SLOT4YOU CUIDADIN | C34: Sergi Saladrigas | D34: 168 | E34: Marc Casanovas | F34: 168 | G34: 336 | H34: SCALEAUTO_CUP
A35: 6 | B35: TOAD TEAM | C35: Raul Ramírez | D35: 159 | E35: Joan Fontanals | F35: 113 | G35: 272 | H35: GT2
A36: 7 | B36: SAB ARRAS | C36: Raul Egea | D36: 85 | E36: Abel Vizu | F36: 85 | G36: 170 | H36: SCALEAUTO_CUP
A38: VERIFICACIÓN Y WARM UP CON MULETO DE 22:40 a 23:10
A39: MANGA VIERNES 23:10 Horas
A41: # | B41: EQUIPO | C41: PILOTO | D41: PTOS. | E41: PILOTO | F41: PTOS. | G41: TOTAL
A42: 1 | B42: SLOTMANIA | C42: Besay Porta | D42: 344 | E42: Ignasi Baldominos | F42: 344 | G42: 688 | H42: RESISBARNA
A43: 2 | B43: EL SOT HORTA | C43: Miquel Bonavida | D43: 260 | E43: Lorenzo Rodriguez | F43: 260 | G43: 520 | H43: RESISBARNA
A44: 3 | B44: EL SOT TEAM | C44: JM Sererols | D44: 259 | E44: Eduard Cerda | F44: 259 | G44: 518 | H44: SCALEAUTO_CUP
A45: 4 | B45: EL SOT FU | C45: Alex Robles | D45: 251 | E45: Jordi Robles | F45: 251 | G45: 502 | H45: RESISBARNA
A46: 5 | B46: SLOTFORYOU | C46: Joel Mendizabal | D46: 251 | E46: Vicens Febrero | F46: 251 | G46: 502 | H46: RESISBARNA
A47: 6 | B47: HOT SLOT FOR YOU | C47: Xavi Cortada | D47: 245 | E47: Adam Parera | F47: 245 | G47: 490 | H47: RESISBARNA

Sheet Inscritos_ENTRENOS_SCM
B7: VIERNES 9 20:00 | C7: MARTES 13 17:00 | D7: MARTES 13 20:00 | E7: MIERCOLES 14 17:00 | F7: MIERCOLES 14 20:00 | G7: JUEVES DIA CARRERA | H7: VIERNES DIA CARRERA
A8: 1 | B8: RAUL RAMIREZ | C8: CESC FIGUERES | D8: OSCAR VILA | E8: CESC FIGUERES | F8: ISRAEL NEVADO | G8: JAUME LLOBET | H8: JOAN FONTANALS
A9: 2 | B9: CRISTIAN DIAZ | C9: ALBERT FIGUEROLA | D9: ISRAEL NEVADO | E9: ALBERT FIGUEROLA | F9: VICTOR GONZALEZ | G9: JORDI MUÑOZ | H9: ENRIC ILLA
A10: 3 | B10: XAVI BELLOT | C10: MIQUEL BONAVIDA | D10: VICTOR GONZALEZ | E10: ALBERTO BOLSA | F10: XAVI CORTADA | G10: DAVID VENDRELL | H10: RAUL EGEA
A11: 4 | B11: JORGE VALDIVIESO | C11: JORDI ROBLES | D11: XAVI CORTADA | E11: LORENZO RODRIGUEZ | F11: ALBERTO BOLSA | H11: ABEL VIZU
A12: 5 | B12: JOEL MENDIZABAL | C12: ALEX ROBLES | D12: ADAM PARERA | E12: JM SERELOS | F12: JM SERELOS | H12: SERGI MARTINEZ
A13: 6 | B13: VICENS FEBRERO | C13: ADAM PARERA | D13: MIQUEL BONAVIDA | E13: BESAY PORTA | F13: EDUARD CERDA | H13: VICTOR LEON
A14: 7 | B14: EDUARD CERDA | D14: LORENZO RODRIGUEZ | E14: JORDI ROBLES | F14: BESAY PORTA | H14: IGNASI BALDOMINOS
A15: 8 | D15: JORDI SIMO | E15: ALEX ROBLES | F15: JOEL MENDIZABAL
A16: 9 | D16: RICHARD AREDONDO | E16: DAVID MERCADER | F16: VICENS FEBRERO
A17: 10 | D17: GABRI RODRIGUEZ | E17: MANEL SORIANO | F17: JORDI SIMO
A18: 11 | F18: DAVID MERCADER
A19: 12 | F19: JORGE VALIDIVIESO
A20: 13 | F20: MANEL SORIANO
A21: 14

Sheet Inscritos_SCM
B5: EQUIPOS INSCRITOS PARA CARRERA SCM
B7: # | C7: EQUIPO | D7: PILOTO | E7: PTOS. | F7: PILOTO2 | G7: PTOS | H7: TOTAL | I7: COPA | J7: DIA
B8: 1 | C8: DZERO SOT | D8: =IFERROR(VLOOKUP(C8,'Listado Pilotos y Equipos'!$B$3:$M$86,2,0),"") -> Israel Nevado | E8: =IFERROR(VLOOKUP(Inscritos_SCM!$D8,Clasificaicon_Pilotos!$B$7:$M$91,12,0),0) -> 178 | F8: =IFERROR(VLOOKUP(C8,'Listado Pilotos y Equipos'!$B$3:$M$86,7,0),"") -> Victor Gonzalez | G8: =IFERROR(VLOOKUP(Inscritos_SCM!$F8,Clasificaicon_Pilotos!$B$7:$M$91,12,0),0) -> 178 | H8: =IF(ISTEXT(E8),0,E8)+IF(ISTEXT(G8),0,G8) -> 356 | I8: =IFERROR(VLOOKUP(C8,'Listado Pilotos y Equipos'!$B$3:$P$86,12,0),"") -> SCALEAUTO_CUP | J8: Jueves
B9: 2 | C9: TOAD TEAM | D9: =IFERROR(VLOOKUP(C9,'Listado Pilotos y Equipos'!$B$3:$M$86,2,0),"") -> Raul Ramírez | E9: =IFERROR(VLOOKUP(Inscritos_SCM!$D9,Clasificaicon_Pilotos!$B$7:$M$91,12,0),0) -> 159 | F9: =IFERROR(VLOOKUP(C9,'Listado Pilotos y Equipos'!$B$3:$M$86,7,0),"") -> Joan Fontanals | G9: =IFERROR(VLOOKUP(Inscritos_SCM!$F9,Clasificaicon_Pilotos!$B$7:$M$91,12,0),0) -> 113 | H9: =IF(ISTEXT(E9),0,E9)+IF(ISTEXT(G9),0,G9) -> 272 | I9: =IFERROR(VLOOKUP(C9,'Listado Pilotos y Equipos'!$B$3:$P$86,12,0),"") -> GT2 | J9: Viernes
B10: 3 | C10: EL SOT FU | D10: =IFERROR(VLOOKUP(C10,'Listado Pilotos y Equipos'!$B$3:$M$86,2,0),"") -> Alex Robles | E10: =IFERROR(VLOOKUP(Inscritos_SCM!$D10,Clasificaicon_Pilotos!$B$7:$M$91,12,0),0) -> 251 | F10: =IFERROR(VLOOKUP(C10,'Listado Pilotos y Equipos'!$B$3:$M$86,7,0),"") -> Jordi Robles | G10: =IFERROR(VLOOKUP(Inscritos_SCM!$F10,Clasificaicon_Pilotos!$B$7:$M$91,12,0),0) -> 251 | H10: =IF(ISTEXT(E10),0,E10)+IF(ISTEXT(G10),0,G10) -> 502 | I10: =IFERROR(VLOOKUP(C10,'Listado Pilotos y Equipos'!$B$3:$P$86,12,0),"") -> RESISBARNA | J10: Viernes
B11: 4 | C11: STP RACING | D11: =IFERROR(VLOOKUP(C11,'Listado Pilotos y Equipos'!$B$3:$M$86,2,0),"") -> Richard Arredondo | E11: =IFERROR(VLOOKUP(Inscritos_SCM!$D11,Clasificaicon_Pilotos!$B$7:$M$91,12,0),0) -> 201 | F11: =IFERROR(VLOOKUP(C11,'Listado Pilotos y Equipos'!$B$3:$M$86,7,0),"") -> Gabriel Rodriguez | G11: =IFERROR(VLOOKUP(Inscritos_SCM!$F11,Clasificaicon_Pilotos!$B$7:$M$91,12,0),0) -> 241 | H11: =IF(ISTEXT(E11),0,E11)+IF(ISTEXT(G11),0,G11) -> 442 | I11: =IFERROR(VLOOKUP(C11,'Listado Pilotos y Equipos'!$B$3:$P$86,12,0),"") -> RESISBARNA | J11: Viernes
B12: 5 | C12: SLOTFOURMANIA | D12: =IFERROR(VLOOKUP(C12,'Listado Pilotos y Equipos'!$B$3:$M$86,2,0),"") -> Jaume Llobet | E12: =IFERROR(VLOOKUP(Inscritos_SCM!$D12,Clasificaicon_Pilotos!$B$7:$M$91,12,0),0) -> 116 | F12: =IFERROR(VLOOKUP(C12,'Listado Pilotos y Equipos'!$B$3:$M$86,7,0),"") -> Oscar Vila | G12: =IFERROR(VLOOKUP(Inscritos_SCM!$F12,Clasificaicon_Pilotos!$B$7:$M$91,12,0),0) -> 156 | H12: =IF(ISTEXT(E12),0,E12)+IF(ISTEXT(G12),0,G12) -> 272 | I12: =IFERROR(VLOOKUP(C12,'Listado Pilotos y Equipos'!$B$3:$P$86,12,0),"") -> GT2 | J12: Jueves
B13: 6 | C13: HOT SLOT FOR YOU | D13: =IFERROR(VLOOKUP(C13,'Listado Pilotos y Equipos'!$B$3:$M$86,2,0),"") -> Xavi Cortada | E13: =IFERROR(VLOOKUP(Inscritos_SCM!$D13,Clasificaicon_Pilotos!$B$7:$M$91,12,0),0) -> 245 | F13: =IFERROR(VLOOKUP(C13,'Listado Pilotos y Equipos'!$B$3:$M$86,7,0),"") -> Adam Parera | G13: =IFERROR(VLOOKUP(Inscritos_SCM!$F13,Clasificaicon_Pilotos!$B$7:$M$91,12,0),0) -> 245 | H13: =IF(ISTEXT(E13),0,E13)+IF(ISTEXT(G13),0,G13) -> 490 | I13: =IFERROR(VLOOKUP(C13,'Listado Pilotos y Equipos'!$B$3:$P$86,12,0),"") -> RESISBARNA | J13: Viernes
B14: 7 | C14: GASCLAVAT FEELGOOD | D14: =IFERROR(VLOOKUP(C14,'Listado Pilotos y Equipos'!$B$3:$M$86,2,0),"") -> Xavi Bellot | E14: =IFERROR(VLOOKUP(Inscritos_SCM!$D14,Clasificaicon_Pilotos!$B$7:$M$91,12,0),0) -> 180 | F14: =IFERROR(VLOOKUP(C14,'Listado Pilotos y Equipos'!$B$3:$M$86,7,0),"") -> Cristian Diaz | G14: =IFERROR(VLOOKUP(Inscritos_SCM!$F14,Clasificaicon_Pilotos!$B$7:$M$91,12,0),0) -> 180 | H14: =IF(ISTEXT(E14),0,E14)+IF(ISTEXT(G14),0,G14) -> 360 | I14: =IFERROR(VLOOKUP(C14,'Listado Pilotos y Equipos'!$B$3:$P$86,12,0),"") -> GT2 | J14: Jueves
B15: 8 | C15: TRELEC | D15: =IFERROR(VLOOKUP(C15,'Listado Pilotos y Equipos'!$B$3:$M$86,2,0),"") -> Albert Figuerola | E15: =IFERROR(VLOOKUP(Inscritos_SCM!$D15,Clasificaicon_Pilotos!$B$7:$M$91,12,0),0) -> 185 | F15: =IFERROR(VLOOKUP(C15,'Listado Pilotos y Equipos'!$B$3:$M$86,7,0),"") -> Cesc Figueras | G15: =IFERROR(VLOOKUP(Inscritos_SCM!$F15,Clasificaicon_Pilotos!$B$7:$M$91,12,0),0) -> 185 | H15: =IF(ISTEXT(E15),0,E15)+IF(ISTEXT(G15),0,G15) -> 370 | I15: =IFERROR(VLOOKUP(C15,'Listado Pilotos y Equipos'!$B$3:$P$86,12,0),"") -> GT2 | J15: Jueves
B16: 9 | C16: EL SOT CALAVERAS | D16: =IFERROR(VLOOKUP(C16,'Listado Pilotos y Equipos'!$B$3:$M$86,2,0),"") -> Jorge Valdivieso | E16: =IFERROR(VLOOKUP(Inscritos_SCM!$D16,Clasificaicon_Pilotos!$B$7:$M$91,12,0),0) -> 178 | F16: =IFERROR(VLOOKUP(C16,'Listado Pilotos y Equipos'!$B$3:$M$86,7,0),"") -> Alberto Bolsa | G16: =IFERROR(VLOOKUP(Inscritos_SCM!$F16,Clasificaicon_Pilotos!$B$7:$M$91,12,0),0) -> 178 | H16: =IF(ISTEXT(E16),0,E16)+IF(ISTEXT(G16),0,G16) -> 356 | I16: =IFERROR(VLOOKUP(C16,'Listado Pilotos y Equipos'!$B$3:$P$86,12,0),"") -> GT2 | J16: Jueves
B17: 10 | C17: EL SOT HORTA | D17: =IFERROR(VLOOKUP(C17,'Listado Pilotos y Equipos'!$B$3:$M$86,2,0),"") -> Miquel Bonavida | E17: =IFERROR(VLOOKUP(Inscritos_SCM!$D17,Clasificaicon_Pilotos!$B$7:$M$91,12,0),0) -> 260 | F17: =IFERROR(VLOOKUP(C17,'Listado Pilotos y Equipos'!$B$3:$M$86,7,0),"") -> Lorenzo Rodriguez | G17: =IFERROR(VLOOKUP(Inscritos_SCM!$F17,Clasificaicon_Pilotos!$B$7:$M$91,12,0),0) -> 260 | H17: =IF(ISTEXT(E17),0,E17)+IF(ISTEXT(G17),0,G17) -> 520 | I17: =IFERROR(VLOOKUP(C17,'Listado Pilotos y Equipos'!$B$3:$P$86,12,0),"") -> RESISBARNA | J17: Viernes
B18: 11 | C18: OSOTNA | D18: =IFERROR(VLOOKUP(C18,'Listado Pilotos y Equipos'!$B$3:$M$86,2,0),"") -> Manel Soriano | E18: =IFERROR(VLOOKUP(Inscritos_SCM!$D18,Clasificaicon_Pilotos!$B$7:$M$91,12,0),0) -> 186 | F18: =IFERROR(VLOOKUP(C18,'Listado Pilotos y Equipos'!$B$3:$M$86,7,0),"") -> David Mercader | G18: =IFERROR(VLOOKUP(Inscritos_SCM!$F18,Clasificaicon_Pilotos!$B$7:$M$91,12,0),0) -> 186 | H18: =IF(ISTEXT(E18),0,E18)+IF(ISTEXT(G18),0,G18) -> 372 | I18: =IFERROR(VLOOKUP(C18,'Listado Pilotos y Equipos'!$B$3:$P$86,12,0),"") -> RESISBARNA | J18: Viernes
B19: 12 | C19: ESTEL·LATS | D19: =IFERROR(VLOOKUP(C19,'Listado Pilotos y Equipos'!$B$3:$M$86,2,0),"") -> Enric Illa | E19: =IFERROR(VLOOKUP(Inscritos_SCM!$D19,Clasificaicon_Pilotos!$B$7:$M$91,12,0),0) -> 175 | F19: =IFERROR(VLOOKUP(C19,'Listado Pilotos y Equipos'!$B$3:$M$86,7,0),"") -> Jordi Simo | G19: =IFERROR(VLOOKUP(Inscritos_SCM!$F19,Clasificaicon_Pilotos!$B$7:$M$91,12,0),0) -> 175 | H19: =IF(ISTEXT(E19),0,E19)+IF(ISTEXT(G19),0,G19) -> 350 | I19: =IFERROR(VLOOKUP(C19,'Listado Pilotos y Equipos'!$B$3:$P$86,12,0),"") -> RESISBARNA | J19: Viernes
... B29: 22 | C29: SLOTSAB OSJO | D29: =IFERROR(VLOOKUP(C29,'Listado Pilotos y Equipos'!$B$3:$M$86,2,0),"") -> Jose Maria Martinez | E29: =IFERROR(VLOOKUP(Inscritos_SCM!$D29,Clasificaicon_Pilotos!$B$7:$M$91,12,0),0) -> 128 | F29: =IFERROR(VLOOKUP(C29,'Listado Pilotos y Equipos'!$B$3:$M$86,7,0),"") -> Guillem Asins | G29: =IFERROR(VLOOKUP(Inscritos_SCM!$F29,Clasificaicon_Pilotos!$B$7:$M$91,12,0),0) -> 0 | H29: =IF(ISTEXT(E29),0,E29)+IF(ISTEXT(G29),0,G29) -> 128 | I29: =IFERROR(VLOOKUP(C29,'Listado Pilotos y Equipos'!$B$3:$P$86,12,0),"") -> SCALEAUTO_CUP | J29: Jueves
B30: 23 | D30: =IFERROR(VLOOKUP(C30,'Listado Pilotos y Equipos'!$B$3:$M$86,2,0),"") | E30: =IFERROR(VLOOKUP(Inscritos_SCM!$D30,Clasificaicon_Pilotos!$B$7:$M$91,12,0),0) -> 0 | F30: =IFERROR(VLOOKUP(C30,'Listado Pilotos y Equipos'!$B$3:$M$86,7,0),"") | G30: =IFERROR(VLOOKUP(Inscritos_SCM!$F30,Clasificaicon_Pilotos!$B$7:$M$91,12,0),0) -> 0 | H30: =IF(ISTEXT(E30),0,E30)+IF(ISTEXT(G30),0,G30) -> 0 | I30: =IFERROR(VLOOKUP(C30,'Listado Pilotos y Equipos'!$B$3:$P$86,12,0),"")
B31: 24 | D31: =IFERROR(VLOOKUP(C31,'Listado Pilotos y Equipos'!$B$3:$M$86,2,0),"") | E31: =IFERROR(VLOOKUP(Inscritos_SCM!$D31,Clasificaicon_Pilotos!$B$7:$M$91,12,0),0) -> 0 | F31: =IFERROR(VLOOKUP(C31,'Listado Pilotos y Equipos'!$B$3:$M$86,7,0),"") | G31: =IFERROR(VLOOKUP(Inscritos_SCM!$F31,Clasificaicon_Pilotos!$B$7:$M$91,12,0),0) -> 0 | H31: =IF(ISTEXT(E31),0,E31)+IF(ISTEXT(G31),0,G31) -> 0 | I31: =IFERROR(VLOOKUP(C31,'Listado Pilotos y Equipos'!$B$3:$P$86,12,0),"")
B32: 25 | D32: =IFERROR(VLOOKUP(C32,'Listado Pilotos y Equipos'!$B$3:$M$86,2,0),"") | E32: =IFERROR(VLOOKUP(Inscritos_SCM!$D32,Clasificaicon_Pilotos!$B$7:$M$91,12,0),0) -> 0 | F32: =IFERROR(VLOOKUP(C32,'Listado Pilotos y Equipos'!$B$3:$M$86,7,0),"") | G32: =IFERROR(VLOOKUP(Inscritos_SCM!$F32,Clasificaicon_Pilotos!$B$7:$M$91,12,0),0) -> 0 | H32: =IF(ISTEXT(E32),0,E32)+IF(ISTEXT(G32),0,G32) -> 0 | I32: =IFERROR(VLOOKUP(C32,'Listado Pilotos y Equipos'!$B$3:$P$86,12,0),"")
B33: 26 | D33: =IFERROR(VLOOKUP(C33,'Listado Pilotos y Equipos'!$B$3:$M$86,2,0),"") | E33: =IFERROR(VLOOKUP(Inscritos_SCM!$D33,Clasificaicon_Pilotos!$B$7:$M$91,12,0),0) -> 0 | F33: =IFERROR(VLOOKUP(C33,'Listado Pilotos y Equipos'!$B$3:$M$86,7,0),"") | G33: =IFERROR(VLOOKUP(Inscritos_SCM!$F33,Clasificaicon_Pilotos!$B$7:$M$91,12,0),0) -> 0 | H33: =IF(ISTEXT(E33),0,E33)+IF(ISTEXT(G33),0,G33) -> 0 | I33: =IFERROR(VLOOKUP(C33,'Listado Pilotos y Equipos'!$B$3:$P$86,12,0),"")
B34: 27 | D34: =IFERROR(VLOOKUP(C34,'Listado Pilotos y Equipos'!$B$3:$M$86,2,0),"") | E34: =IFERROR(VLOOKUP(Inscritos_SCM!$D34,Clasificaicon_Pilotos!$B$7:$M$91,12,0),0) -> 0 | F34: =IFERROR(VLOOKUP(C34,'Listado Pilotos y Equipos'!$B$3:$M$86,7,0),"") | G34: =IFERROR(VLOOKUP(Inscritos_SCM!$F34,Clasificaicon_Pilotos!$B$7:$M$91,12,0),0) -> 0 | H34: =IF(ISTEXT(E34),0,E34)+IF(ISTEXT(G34),0,G34) -> 0 | I34: =IFERROR(VLOOKUP(C34,'Listado Pilotos y Equipos'!$B$3:$P$86,12,0),"")
B35: 28 | D35: =IFERROR(VLOOKUP(C35,'Listado Pilotos y Equipos'!$B$3:$M$86,2,0),"") | E35: =IFERROR(VLOOKUP(Inscritos_SCM!$D35,Clasificaicon_Pilotos!$B$7:$M$91,12,0),0) -> 0 | F35: =IFERROR(VLOOKUP(C35,'Listado Pilotos y Equipos'!$B$3:$M$86,7,0),"") | G35: =IFERROR(VLOOKUP(Inscritos_SCM!$F35,Clasificaicon_Pilotos!$B$7:$M$91,12,0),0) -> 0 | H35: =IF(ISTEXT(E35),0,E35)+IF(ISTEXT(G35),0,G35) -> 0 | I35: =IFERROR(VLOOKUP(C35,'Listado Pilotos y Equipos'!$B$3:$P$86,12,0),"")
B36: 29 | D36: =IFERROR(VLOOKUP(C36,'Listado Pilotos y Equipos'!$B$3:$M$86,2,0),"") | E36: =IFERROR(VLOOKUP(Inscritos_SCM!$D36,Clasificaicon_Pilotos!$B$7:$M$91,12,0),0) -> 0 | F36: =IFERROR(VLOOKUP(C36,'Listado Pilotos y Equipos'!$B$3:$M$86,7,0),"") | G36: =IFERROR(VLOOKUP(Inscritos_SCM!$F36,Clasificaicon_Pilotos!$B$7:$M$91,12,0),0) -> 0 | H36: =IF(ISTEXT(E36),0,E36)+IF(ISTEXT(G36),0,G36) -> 0 | I36: =IFERROR(VLOOKUP(C36,'Listado Pilotos y Equipos'!$B$3:$P$86,12,0),"")
B37: 30 | D37: =IFERROR(VLOOKUP(C37,'Listado Pilotos y Equipos'!$B$3:$M$86,2,0),"") | E37: =IFERROR(VLOOKUP(Inscritos_SCM!$D37,Clasificaicon_Pilotos!$B$7:$M$91,12,0),0) -> 0 | F37: =IFERROR(VLOOKUP(C37,'Listado Pilotos y Equipos'!$B$3:$M$86,7,0),"") | G37: =IFERROR(VLOOKUP(Inscritos_SCM!$F37,Clasificaicon_Pilotos!$B$7:$M$91,12,0),0) -> 0 | H37: =IF(ISTEXT(E37),0,E37)+IF(ISTEXT(G37),0,G37) -> 0 | I37: =IFERROR(VLOOKUP(C37,'Listado Pilotos y Equipos'!$B$3:$P$86,12,0),"")
B38: 31 | D38: =IFERROR(VLOOKUP(C38,'Listado Pilotos y Equipos'!$B$3:$M$86,2,0),"") | E38: =IFERROR(VLOOKUP(Inscritos_SCM!$D38,Clasificaicon_Pilotos!$B$7:$M$91,12,0),0) -> 0 | F38: =IFERROR(VLOOKUP(C38,'Listado Pilotos y Equipos'!$B$3:$M$86,7,0),"") | G38: =IFERROR(VLOOKUP(Inscritos_SCM!$F38,Clasificaicon_Pilotos!$B$7:$M$91,12,0),0) -> 0 | H38: =IF(ISTEXT(E38),0,E38)+IF(ISTEXT(G38),0,G38) -> 0 | I38: =IFERROR(VLOOKUP(C38,'Listado Pilotos y Equipos'!$B$3:$P$86,12,0),"")
B39: 32 | D39: =IFERROR(VLOOKUP(C39,'Listado Pilotos y Equipos'!$B$3:$M$86,2,0),"") | E39: =IFERROR(VLOOKUP(Inscritos_SCM!$D39,Clasificaicon_Pilotos!$B$7:$M$91,12,0),0) -> 0 | F39: =IFERROR(VLOOKUP(C39,'Listado Pilotos y Equipos'!$B$3:$M$86,7,0),"") | G39: =IFERROR(VLOOKUP(Inscritos_SCM!$F39,Clasificaicon_Pilotos!$B$7:$M$91,12,0),0) -> 0 | H39: =IF(ISTEXT(E39),0,E39)+IF(ISTEXT(G39),0,G39) -> 0 | I39: =IFERROR(VLOOKUP(C39,'Listado Pilotos y Equipos'!$B$3:$P$86,12,0),"")
B40: 33 | D40: =IFERROR(VLOOKUP(C40,'Listado Pilotos y Equipos'!$B$3:$M$86,2,0),"") | E40: =IFERROR(VLOOKUP(Inscritos_SCM!$D40,Clasificaicon_Pilotos!$B$7:$M$91,12,0),0) -> 0 | F40: =IFERROR(VLOOKUP(C40,'Listado Pilotos y Equipos'!$B$3:$M$86,7,0),"") | G40: =IFERROR(VLOOKUP(Inscritos_SCM!$F40,Clasificaicon_Pilotos!$B$7:$M$91,12,0),0) -> 0 | H40: =IF(ISTEXT(E40),0,E40)+IF(ISTEXT(G40),0,G40) -> 0 | I40: =IFERROR(VLOOKUP(C40,'Listado Pilotos y Equipos'!$B$3:$P$86,12,0),"")
B41: 34 | D41: =IFERROR(VLOOKUP(C41,'Listado Pilotos y Equipos'!$B$3:$M$86,2,0),"") | E41: =IFERROR(VLOOKUP(Inscritos_SCM!$D41,Clasificaicon_Pilotos!$B$7:$M$91,12,0),0) -> 0 | F41: =IFERROR(VLOOKUP(C41,'Listado Pilotos y Equipos'!$B$3:$M$86,7,0),"") | G41: =IFERROR(VLOOKUP(Inscritos_SCM!$F41,Clasificaicon_Pilotos!$B$7:$M$91,12,0),0) -> 0 | H41: =IF(ISTEXT(E41),0,E41)+IF(ISTEXT(G41),0,G41) -> 0 | I41: =IFERROR(VLOOKUP(C41,'Listado Pilotos y Equipos'!$B$3:$P$86,12,0),"")
... B51: 44 | D51: =IFERROR(VLOOKUP(C51,'Listado Pilotos y Equipos'!$B$3:$M$86,2,0),"") | E51: =IFERROR(VLOOKUP(Inscritos_SCM!$D51,Clasificaicon_Pilotos!$B$7:$M$91,12,0),0) -> 0 | F51: =IFERROR(VLOOKUP(C51,'Listado Pilotos y Equipos'!$B$3:$M$86,7,0),"") | G51: =IFERROR(VLOOKUP(Inscritos_SCM!$F51,Clasificaicon_Pilotos!$B$7:$M$91,12,0),0) -> 0 | H51: =IF(ISTEXT(E51),0,E51)+IF(ISTEXT(G51),0,G51) -> 0 | I51: =IFERROR(VLOOKUP(C51,'Listado Pilotos y Equipos'!$B$3:$P$86,12,0),"")

Sheet Inscritos_SLOTSAB
B5: EQUIPOS INSCRITOS PARA CARRERA SLOTSAB
B7: # | C7: EQUIPO | D7: PILOTO | E7: PTOS. | F7: PILOTO2 | G7: PTOS | H7: TOTAL | I7: COPA | J7: DIA
B8: 27 | C8: SLOTMANIA | D8: =IFERROR(VLOOKUP(C8,'Listado Pilotos y Equipos'!$B$3:$M$86,2,0),"") -> Besay Porta | E8: =IFERROR(VLOOKUP(Inscritos_SLOTSAB!$D8,Clasificaicon_Pilotos!$B$7:$M$91,12,0),0) -> 344 | F8: =IFERROR(VLOOKUP(C8,'Listado Pilotos y Equipos'!$B$3:$M$86,7,0),"") -> Ignasi Baldominos | G8: =IFERROR(VLOOKUP(Inscritos_SLOTSAB!$F8,Clasificaicon_Pilotos!$B$7:$M$91,12,0),0) -> 344 | H8: =IF(ISTEXT(E8),0,E8)+IF(ISTEXT(G8),0,G8) -> 688 | I8: =IFERROR(VLOOKUP(C8,'Listado Pilotos y Equipos'!$B$3:$P$86,12,0),"") -> RESISBARNA | J8: VIERNES
B9: 2 | C9: EL SOT FU | D9: =IFERROR(VLOOKUP(C9,'Listado Pilotos y Equipos'!$B$3:$M$86,2,0),"") -> Alex Robles | E9: =IFERROR(VLOOKUP(Inscritos_SLOTSAB!$D9,Clasificaicon_Pilotos!$B$7:$M$91,12,0),0) -> 251 | F9: =IFERROR(VLOOKUP(C9,'Listado Pilotos y Equipos'!$B$3:$M$86,7,0),"") -> Jordi Robles | G9: =IFERROR(VLOOKUP(Inscritos_SLOTSAB!$F9,Clasificaicon_Pilotos!$B$7:$M$91,12,0),0) -> 251 | H9: =IF(ISTEXT(E9),0,E9)+IF(ISTEXT(G9),0,G9) -> 502 | I9: =IFERROR(VLOOKUP(C9,'Listado Pilotos y Equipos'!$B$3:$P$86,12,0),"") -> RESISBARNA | J9: VIERNES
B10: 3 | C10: EL SOT TEAM | D10: =IFERROR(VLOOKUP(C10,'Listado Pilotos y Equipos'!$B$3:$M$86,2,0),"") -> JM Sererols | E10: =IFERROR(VLOOKUP(Inscritos_SLOTSAB!$D10,Clasificaicon_Pilotos!$B$7:$M$91,12,0),0) -> 259 | F10: =IFERROR(VLOOKUP(C10,'Listado Pilotos y Equipos'!$B$3:$M$86,7,0),"") -> Eduard Cerda | G10: =IFERROR(VLOOKUP(Inscritos_SLOTSAB!$F10,Clasificaicon_Pilotos!$B$7:$M$91,12,0),0) -> 259 | H10: =IF(ISTEXT(E10),0,E10)+IF(ISTEXT(G10),0,G10) -> 518 | I10: =IFERROR(VLOOKUP(C10,'Listado Pilotos y Equipos'!$B$3:$P$86,12,0),"") -> SCALEAUTO_CUP | J10: VIERNES
B11: 4 | C11: EL SOT HORTA | D11: =IFERROR(VLOOKUP(C11,'Listado Pilotos y Equipos'!$B$3:$M$86,2,0),"") -> Miquel Bonavida | E11: =IFERROR(VLOOKUP(Inscritos_SLOTSAB!$D11,Clasificaicon_Pilotos!$B$7:$M$91,12,0),0) -> 260 | F11: =IFERROR(VLOOKUP(C11,'Listado Pilotos y Equipos'!$B$3:$M$86,7,0),"") -> Lorenzo Rodriguez | G11: =IFERROR(VLOOKUP(Inscritos_SLOTSAB!$F11,Clasificaicon_Pilotos!$B$7:$M$91,12,0),0) -> 260 | H11: =IF(ISTEXT(E11),0,E11)+IF(ISTEXT(G11),0,G11) -> 520 | I11: =IFERROR(VLOOKUP(C11,'Listado Pilotos y Equipos'!$B$3:$P$86,12,0),"") -> RESISBARNA | J11: VIERNES
B12: 8 | C12: HOT SLOT FOR YOU | D12: =IFERROR(VLOOKUP(C12,'Listado Pilotos y Equipos'!$B$3:$M$86,2,0),"") -> Xavi Cortada | E12: =IFERROR(VLOOKUP(Inscritos_SLOTSAB!$D12,Clasificaicon_Pilotos!$B$7:$M$91,12,0),0) -> 245 | F12: =IFERROR(VLOOKUP(C12,'Listado Pilotos y Equipos'!$B$3:$M$86,7,0),"") -> Adam Parera | G12: =IFERROR(VLOOKUP(Inscritos_SLOTSAB!$F12,Clasificaicon_Pilotos!$B$7:$M$91,12,0),0) -> 245 | H12: =IF(ISTEXT(E12),0,E12)+IF(ISTEXT(G12),0,G12) -> 490 | I12: =IFERROR(VLOOKUP(C12,'Listado Pilotos y Equipos'!$B$3:$P$86,12,0),"") -> RESISBARNA | J12: VIERNES
B13: 9 | C13: SLOTFORYOU | D13: =IFERROR(VLOOKUP(C13,'Listado Pilotos y Equipos'!$B$3:$M$86,2,0),"") -> Joel Mendizabal | E13: =IFERROR(VLOOKUP(Inscritos_SLOTSAB!$D13,Clasificaicon_Pilotos!$B$7:$M$91,12,0),0) -> 251 | F13: =IFERROR(VLOOKUP(C13,'Listado Pilotos y Equipos'!$B$3:$M$86,7,0),"") -> Vicens Febrero | G13: =IFERROR(VLOOKUP(Inscritos_SLOTSAB!$F13,Clasificaicon_Pilotos!$B$7:$M$91,12,0),0) -> 251 | H13: =IF(ISTEXT(E13),0,E13)+IF(ISTEXT(G13),0,G13) -> 502 | I13: =IFERROR(VLOOKUP(C13,'Listado Pilotos y Equipos'!$B$3:$P$86,12,0),"") -> RESISBARNA | J13: VIERNES
B14: 10 | C14: STP RACING | D14: =IFERROR(VLOOKUP(C14,'Listado Pilotos y Equipos'!$B$3:$M$86,2,0),"") -> Richard Arredondo | E14: =IFERROR(VLOOKUP(Inscritos_SLOTSAB!$D14,Clasificaicon_Pilotos!$B$7:$M$91,12,0),0) -> 201 | F14: =IFERROR(VLOOKUP(C14,'Listado Pilotos y Equipos'!$B$3:$M$86,7,0),"") -> Gabriel Rodriguez | G14: =IFERROR(VLOOKUP(Inscritos_SLOTSAB!$F14,Clasificaicon_Pilotos!$B$7:$M$91,12,0),0) -> 241 | H14: =IF(ISTEXT(E14),0,E14)+IF(ISTEXT(G14),0,G14) -> 442 | I14: =IFERROR(VLOOKUP(C14,'Listado Pilotos y Equipos'!$B$3:$P$86,12,0),"") -> RESISBARNA | J14: VIERNES
B15: 1 | C15: DZERO SOT | D15: =IFERROR(VLOOKUP(C15,'Listado Pilotos y Equipos'!$B$3:$M$86,2,0),"") -> Israel Nevado | E15: =IFERROR(VLOOKUP(Inscritos_SLOTSAB!$D15,Clasificaicon_Pilotos!$B$7:$M$91,12,0),0) -> 178 | F15: =IFERROR(VLOOKUP(C15,'Listado Pilotos y Equipos'!$B$3:$M$86,7,0),"") -> Victor Gonzalez | G15: =IFERROR(VLOOKUP(Inscritos_SLOTSAB!$F15,Clasificaicon_Pilotos!$B$7:$M$91,12,0),0) -> 178 | H15: =IF(ISTEXT(E15),0,E15)+IF(ISTEXT(G15),0,G15) -> 356 | I15: =IFERROR(VLOOKUP(C15,'Listado Pilotos y Equipos'!$B$3:$P$86,12,0),"") -> SCALEAUTO_CUP | J15: JUEVES
B16: 13 | C16: OSOTNA | D16: =IFERROR(VLOOKUP(C16,'Listado Pilotos y Equipos'!$B$3:$M$86,2,0),"") -> Manel Soriano | E16: =IFERROR(VLOOKUP(Inscritos_SLOTSAB!$D16,Clasificaicon_Pilotos!$B$7:$M$91,12,0),0) -> 186 | F16: =IFERROR(VLOOKUP(C16,'Listado Pilotos y Equipos'!$B$3:$M$86,7,0),"") -> David Mercader | G16: =IFERROR(VLOOKUP(Inscritos_SLOTSAB!$F16,Clasificaicon_Pilotos!$B$7:$M$91,12,0),0) -> 186 | H16: =IF(ISTEXT(E16),0,E16)+IF(ISTEXT(G16),0,G16) -> 372 | I16: =IFERROR(VLOOKUP(C16,'Listado Pilotos y Equipos'!$B$3:$P$86,12,0),"") -> RESISBARNA | J16: VIERNES
B17: 14 | C17: EL SOT CALAVERAS | D17: =IFERROR(VLOOKUP(C17,'Listado Pilotos y Equipos'!$B$3:$M$86,2,0),"") -> Jorge Valdivieso | E17: =IFERROR(VLOOKUP(Inscritos_SLOTSAB!$D17,Clasificaicon_Pilotos!$B$7:$M$91,12,0),0) -> 178 | F17: =IFERROR(VLOOKUP(C17,'Listado Pilotos y Equipos'!$B$3:$M$86,7,0),"") -> Alberto Bolsa | G17: =IFERROR(VLOOKUP(Inscritos_SLOTSAB!$F17,Clasificaicon_Pilotos!$B$7:$M$91,12,0),0) -> 178 | H17: =IF(ISTEXT(E17),0,E17)+IF(ISTEXT(G17),0,G17) -> 356 | I17: =IFERROR(VLOOKUP(C17,'Listado Pilotos y Equipos'!$B$3:$P$86,12,0),"") -> GT2 | J17: VIERNES
B18: 6 | C18: GASCLAVAT FEELGOOD | D18: =IFERROR(VLOOKUP(C18,'Listado Pilotos y Equipos'!$B$3:$M$86,2,0),"") -> Xavi Bellot | E18: =IFERROR(VLOOKUP(Inscritos_SLOTSAB!$D18,Clasificaicon_Pilotos!$B$7:$M$91,12,0),0) -> 180 | F18: =IFERROR(VLOOKUP(C18,'Listado Pilotos y Equipos'!$B$3:$M$86,7,0),"") -> Cristian Diaz | G18: =IFERROR(VLOOKUP(Inscritos_SLOTSAB!$F18,Clasificaicon_Pilotos!$B$7:$M$91,12,0),0) -> 180 | H18: =IF(ISTEXT(E18),0,E18)+IF(ISTEXT(G18),0,G18) -> 360 | I18: =IFERROR(VLOOKUP(C18,'Listado Pilotos y Equipos'!$B$3:$P$86,12,0),"") -> GT2 | J18: SABADO
B19: 5 | C19: TRELEC | D19: =IFERROR(VLOOKUP(C19,'Listado Pilotos y Equipos'!$B$3:$M$86,2,0),"") -> Albert Figuerola | E19: =IFERROR(VLOOKUP(Inscritos_SLOTSAB!$D19,Clasificaicon_Pilotos!$B$7:$M$91,12,0),0) -> 185 | F19: =IFERROR(VLOOKUP(C19,'Listado Pilotos y Equipos'!$B$3:$M$86,7,0),"") -> Cesc Figueras | G19: =IFERROR(VLOOKUP(Inscritos_SLOTSAB!$F19,Clasificaicon_Pilotos!$B$7:$M$91,12,0),0) -> 185 | H19: =IF(ISTEXT(E19),0,E19)+IF(ISTEXT(G19),0,G19) -> 370 | I19: =IFERROR(VLOOKUP(C19,'Listado Pilotos y Equipos'!$B$3:$P$86,12,0),"") -> GT2 | J19: SABADO
... B28: 19 | C28: NOUTEAM SLOT_ | D28: =IFERROR(VLOOKUP(C28,'Listado Pilotos y Equipos'!$B$3:$M$86,2,0),"") -> Jordi Muñoz | E28: =IFERROR(VLOOKUP(Inscritos_SLOTSAB!$D28,Clasificaicon_Pilotos!$B$7:$M$91,12,0),0) -> 111 | F28: =IFERROR(VLOOKUP(C28,'Listado Pilotos y Equipos'!$B$3:$M$86,7,0),"") -> David Vendrell | G28: =IFERROR(VLOOKUP(Inscritos_SLOTSAB!$F28,Clasificaicon_Pilotos!$B$7:$M$91,12,0),0) -> 83 | H28: =IF(ISTEXT(E28),0,E28)+IF(ISTEXT(G28),0,G28) -> 194 | I28: =IFERROR(VLOOKUP(C28,'Listado Pilotos y Equipos'!$B$3:$P$86,12,0),"") -> GT2 | J28: JUEVES
B29: 12 | C29: SCM | D29: =IFERROR(VLOOKUP(C29,'Listado Pilotos y Equipos'!$B$3:$M$86,2,0),"") -> Edgar Carmona | E29: 24 | F29: =IFERROR(VLOOKUP(C29,'Listado Pilotos y Equipos'!$B$3:$M$86,7,0),"") -> Jordi Cantos | G29: =IFERROR(VLOOKUP(Inscritos_SLOTSAB!$F29,Clasificaicon_Pilotos!$B$7:$M$91,12,0),0) -> 136 | H29: =IF(ISTEXT(E29),0,E29)+IF(ISTEXT(G29),0,G29) -> 160 | I29: =IFERROR(VLOOKUP(C29,'Listado Pilotos y Equipos'!$B$3:$P$86,12,0),"") -> GT2 | J29: SABADO
B30: 23 | C30: EQUIP VALLES | D30: =IFERROR(VLOOKUP(C30,'Listado Pilotos y Equipos'!$B$3:$M$86,2,0),"") -> Dani Gonzalez | E30: =IFERROR(VLOOKUP(Inscritos_SLOTSAB!$D30,Clasificaicon_Pilotos!$B$7:$M$91,12,0),0) -> 93 | F30: =IFERROR(VLOOKUP(C30,'Listado Pilotos y Equipos'!$B$3:$M$86,7,0),"") -> Valeri Jonama | G30: =IFERROR(VLOOKUP(Inscritos_SLOTSAB!$F30,Clasificaicon_Pilotos!$B$7:$M$91,12,0),0) -> 139 | H30: =IF(ISTEXT(E30),0,E30)+IF(ISTEXT(G30),0,G30) -> 232 | I30: =IFERROR(VLOOKUP(C30,'Listado Pilotos y Equipos'!$B$3:$P$86,12,0),"") -> RESISBARNA | J30: VIERNES
B31: 11 | C31: MILLUI | D31: =IFERROR(VLOOKUP(C31,'Listado Pilotos y Equipos'!$B$3:$M$86,2,0),"") -> Lluis aldea | E31: =IFERROR(VLOOKUP(Inscritos_SLOTSAB!$D31,Clasificaicon_Pilotos!$B$7:$M$91,12,0),0) -> 79 | F31: =IFERROR(VLOOKUP(C31,'Listado Pilotos y Equipos'!$B$3:$M$86,7,0),"") -> Miki Teres | G31: =IFERROR(VLOOKUP(Inscritos_SLOTSAB!$F31,Clasificaicon_Pilotos!$B$7:$M$91,12,0),0) -> 31 | H31: =IF(ISTEXT(E31),0,E31)+IF(ISTEXT(G31),0,G31) -> 110 | I31: =IFERROR(VLOOKUP(C31,'Listado Pilotos y Equipos'!$B$3:$P$86,12,0),"") -> GT2 | J31: JUEVES
B32: 22 | C32: CRONO1_ | D32: =IFERROR(VLOOKUP(C32,'Listado Pilotos y Equipos'!$B$3:$M$86,2,0),"") -> Javier Muñoz | E32: =IFERROR(VLOOKUP(Inscritos_SLOTSAB!$D32,Clasificaicon_Pilotos!$B$7:$M$91,12,0),0) -> 115 | F32: =IFERROR(VLOOKUP(C32,'Listado Pilotos y Equipos'!$B$3:$M$86,7,0),"") -> Marius Magro | G32: =IFERROR(VLOOKUP(Inscritos_SLOTSAB!$F32,Clasificaicon_Pilotos!$B$7:$M$91,12,0),0) -> 54 | H32: =IF(ISTEXT(E32),0,E32)+IF(ISTEXT(G32),0,G32) -> 169 | I32: =IFERROR(VLOOKUP(C32,'Listado Pilotos y Equipos'!$B$3:$P$86,12,0),"") -> SCALEAUTO_CUP | J32: VIERNES
B33: 20 | C33: SAB ARRAS | D33: =IFERROR(VLOOKUP(C33,'Listado Pilotos y Equipos'!$B$3:$M$86,2,0),"") -> Raul Egea | E33: =IFERROR(VLOOKUP(Inscritos_SLOTSAB!$D33,Clasificaicon_Pilotos!$B$7:$M$91,12,0),0) -> 85 | F33: =IFERROR(VLOOKUP(C33,'Listado Pilotos y Equipos'!$B$3:$M$86,7,0),"") -> Abel Vizu | G33: =IFERROR(VLOOKUP(Inscritos_SLOTSAB!$F33,Clasificaicon_Pilotos!$B$7:$M$91,12,0),0) -> 85 | H33: =IF(ISTEXT(E33),0,E33)+IF(ISTEXT(G33),0,G33) -> 170 | I33: =IFERROR(VLOOKUP(C33,'Listado Pilotos y Equipos'!$B$3:$P$86,12,0),"") -> SCALEAUTO_CUP | J33: JUEVES
B34: 25 | C34: SLOTSAB TEAM PIQUERAS | D34: =IFERROR(VLOOKUP(C34,'Listado Pilotos y Equipos'!$B$3:$M$86,2,0),"") -> Ismael Piqueras | E34: =IFERROR(VLOOKUP(Inscritos_SLOTSAB!$D34,Clasificaicon_Pilotos!$B$7:$M$91,12,0),0) -> 31 | F34: =IFERROR(VLOOKUP(C34,'Listado Pilotos y Equipos'!$B$3:$M$86,7,0),"") -> Eric Piqueras | G34: =IFERROR(VLOOKUP(Inscritos_SLOTSAB!$F34,Clasificaicon_Pilotos!$B$7:$M$91,12,0),0) -> 0 | H34: =IF(ISTEXT(E34),0,E34)+IF(ISTEXT(G34),0,G34) -> 31 | I34: RESISBARNA | J34: SABADO
B35: 28 | D35: =IFERROR(VLOOKUP(C35,'Listado Pilotos y Equipos'!$B$3:$M$86,2,0),"") | E35: =IFERROR(VLOOKUP(Inscritos_SLOTSAB!$D35,Clasificaicon_Pilotos!$B$7:$M$91,12,0),0) -> 0 | F35: =IFERROR(VLOOKUP(C35,'Listado Pilotos y Equipos'!$B$3:$M$86,7,0),"") | G35: =IFERROR(VLOOKUP(Inscritos_SLOTSAB!$F35,Clasificaicon_Pilotos!$B$7:$M$91,12,0),0) -> 0 | H35: =IF(ISTEXT(E35),0,E35)+IF(ISTEXT(G35),0,G35) -> 0 | I35: =IFERROR(VLOOKUP(C35,'Listado Pilotos y Equipos'!$B$3:$P$86,12,0),"")
B36: 29 | D36: =IFERROR(VLOOKUP(C36,'Listado Pilotos y Equipos'!$B$3:$M$86,2,0),"") | E36: =IFERROR(VLOOKUP(Inscritos_SLOTSAB!$D36,Clasificaicon_Pilotos!$B$7:$M$91,13,0),0) -> 0 | F36: =IFERROR(VLOOKUP(C36,'Listado Pilotos y Equipos'!$B$3:$M$86,7,0),"") | G36: =IFERROR(VLOOKUP(Inscritos_SLOTSAB!$F36,Clasificaicon_Pilotos!$B$7:$M$91,12,0),0) -> 0 | H36: =IF(ISTEXT(E36),0,E36)+IF(ISTEXT(G36),0,G36) -> 0 | I36: =IFERROR(VLOOKUP(C36,'Listado Pilotos y Equipos'!$B$3:$P$86,12,0),"")
B37: 30 | D37: =IFERROR(VLOOKUP(C37,'Listado Pilotos y Equipos'!$B$3:$M$86,2,0),"") | E37: =IFERROR(VLOOKUP(Inscritos_SLOTSAB!$D37,Clasificaicon_Pilotos!$B$7:$M$91,13,0),0) -> 0 | F37: =IFERROR(VLOOKUP(C37,'Listado Pilotos y Equipos'!$B$3:$M$86,7,0),"") | G37: =IFERROR(VLOOKUP(Inscritos_SLOTSAB!$F37,Clasificaicon_Pilotos!$B$7:$M$91,12,0),0) -> 0 | H37: =IF(ISTEXT(E37),0,E37)+IF(ISTEXT(G37),0,G37) -> 0 | I37: =IFERROR(VLOOKUP(C37,'Listado Pilotos y Equipos'!$B$3:$P$86,12,0),"")
B38: 31 | D38: =IFERROR(VLOOKUP(C38,'Listado Pilotos y Equipos'!$B$3:$M$86,2,0),"") | E38: =IFERROR(VLOOKUP(Inscritos_SLOTSAB!$D38,Clasificaicon_Pilotos!$B$7:$M$91,13,0),0) -> 0 | F38: =IFERROR(VLOOKUP(C38,'Listado Pilotos y Equipos'!$B$3:$M$86,7,0),"") | G38: =IFERROR(VLOOKUP(Inscritos_SLOTSAB!$F38,Clasificaicon_Pilotos!$B$7:$M$91,13,0),0) -> 0 | H38: =IF(ISTEXT(E38),0,E38)+IF(ISTEXT(G38),0,G38) -> 0 | I38: =IFERROR(VLOOKUP(C38,'Listado Pilotos y Equipos'!$B$3:$P$86,12,0),"")
B39: 32 | D39: =IFERROR(VLOOKUP(C39,'Listado Pilotos y Equipos'!$B$3:$M$86,2,0),"") | E39: =IFERROR(VLOOKUP(Inscritos_SLOTSAB!$D39,Clasificaicon_Pilotos!$B$7:$M$91,13,0),0) -> 0 | F39: =IFERROR(VLOOKUP(C39,'Listado Pilotos y Equipos'!$B$3:$M$86,7,0),"") | G39: =IFERROR(VLOOKUP(Inscritos_SLOTSAB!$F39,Clasificaicon_Pilotos!$B$7:$M$91,13,0),0) -> 0 | H39: =IF(ISTEXT(E39),0,E39)+IF(ISTEXT(G39),0,G39) -> 0 | I39: =IFERROR(VLOOKUP(C39,'Listado Pilotos y Equipos'!$B$3:$P$86,12,0),"")
B40: 33 | D40: =IFERROR(VLOOKUP(C40,'Listado Pilotos y Equipos'!$B$3:$M$86,2,0),"") | E40: =IFERROR(VLOOKUP(Inscritos_SLOTSAB!$D40,Clasificaicon_Pilotos!$B$7:$M$96,13,0),0) -> 0 | F40: =IFERROR(VLOOKUP(C40,'Listado Pilotos y Equipos'!$B$3:$M$86,7,0),"") | G40: =IFERROR(VLOOKUP(Inscritos_SLOTSAB!$F40,Clasificaicon_Pilotos!$B$7:$M$96,13,0),0) -> 0 | H40: =IF(ISTEXT(E40),0,E40)+IF(ISTEXT(G40),0,G40) -> 0 | I40: =IFERROR(VLOOKUP(C40,'Listado Pilotos y Equipos'!$B$3:$P$86,12,0),"")
B41: 34 | D41: =IFERROR(VLOOKUP(C41,'Listado Pilotos y Equipos'!$B$3:$M$86,2,0),"") | E41: =IFERROR(VLOOKUP(Inscritos_SLOTSAB!$D41,Clasificaicon_Pilotos!$B$7:$M$91,13,0),0) -> 0 | F41: =IFERROR(VLOOKUP(C41,'Listado Pilotos y Equipos'!$B$3:$M$86,7,0),"") | G41: =IFERROR(VLOOKUP(Inscritos_SLOTSAB!$F41,Clasificaicon_Pilotos!$B$7:$M$91,13,0),0) -> 0 | H41: =IF(ISTEXT(E41),0,E41)+IF(ISTEXT(G41),0,G41) -> 0 | I41: =IFERROR(VLOOKUP(C41,'Listado Pilotos y Equipos'!$B$3:$P$86,12,0),"")
B42: 35 | D42: =IFERROR(VLOOKUP(C42,'Listado Pilotos y Equipos'!$B$3:$M$86,2,0),"") | E42: =IFERROR(VLOOKUP(Inscritos_SLOTSAB!$D42,Clasificaicon_Pilotos!$B$7:$M$91,13,0),0) -> 0 | F42: =IFERROR(VLOOKUP(C42,'Listado Pilotos y Equipos'!$B$3:$M$86,7,0),"") | G42: =IFERROR(VLOOKUP(Inscritos_SLOTSAB!$F42,Clasificaicon_Pilotos!$B$7:$M$91,13,0),0) -> 0 | H42: =IF(ISTEXT(E42),0,E42)+IF(ISTEXT(G42),0,G42) -> 0 | I42: =IFERROR(VLOOKUP(C42,'Listado Pilotos y Equipos'!$B$3:$P$86,12,0),"")
B43: 36 | D43: =IFERROR(VLOOKUP(C43,'Listado Pilotos y Equipos'!$B$3:$M$86,2,0),"") | E43: =IFERROR(VLOOKUP(Inscritos_SLOTSAB!$D43,Clasificaicon_Pilotos!$B$7:$M$91,13,0),0) -> 0 | F43: =IFERROR(VLOOKUP(C43,'Listado Pilotos y Equipos'!$B$3:$M$86,7,0),"") | G43: =IFERROR(VLOOKUP(Inscritos_SLOTSAB!$F43,Clasificaicon_Pilotos!$B$7:$M$91,13,0),0) -> 0 | H43: =IF(ISTEXT(E43),0,E43)+IF(ISTEXT(G43),0,G43) -> 0 | I43: =IFERROR(VLOOKUP(C43,'Listado Pilotos y Equipos'!$B$3:$P$86,12,0),"")
B44: 37 | D44: =IFERROR(VLOOKUP(C44,'Listado Pilotos y Equipos'!$B$3:$M$86,2,0),"") | E44: =IFERROR(VLOOKUP(Inscritos_SLOTSAB!$D44,Clasificaicon_Pilotos!$B$7:$M$91,13,0),0) -> 0 | F44: =IFERROR(VLOOKUP(C44,'Listado Pilotos y Equipos'!$B$3:$M$86,7,0),"") | G44: =IFERROR(VLOOKUP(Inscritos_SLOTSAB!$F44,Clasificaicon_Pilotos!$B$7:$M$91,13,0),0) -> 0 | H44: =IF(ISTEXT(E44),0,E44)+IF(ISTEXT(G44),0,G44) -> 0 | I44: =IFERROR(VLOOKUP(C44,'Listado Pilotos y Equipos'!$B$3:$P$86,12,0),"")
B45: 38 | D45: =IFERROR(VLOOKUP(C45,'Listado Pilotos y Equipos'!$B$3:$M$86,2,0),"") | E45: =IFERROR(VLOOKUP(Inscritos_SLOTSAB!$D45,Clasificaicon_Pilotos!$B$7:$M$91,13,0),0) -> 0 | F45: =IFERROR(VLOOKUP(C45,'Listado Pilotos y Equipos'!$B$3:$M$86,7,0),"") | G45: =IFERROR(VLOOKUP(Inscritos_SLOTSAB!$F45,Clasificaicon_Pilotos!$B$7:$M$91,13,0),0) -> 0 | H45: =IF(ISTEXT(E45),0,E45)+IF(ISTEXT(G45),0,G45) -> 0 | I45: =IFERROR(VLOOKUP(C45,'Listado Pilotos y Equipos'!$B$3:$P$86,12,0),"")
B46: 39 | D46: =IFERROR(VLOOKUP(C46,'Listado Pilotos y Equipos'!$B$3:$M$86,2,0),"") | E46: =IFERROR(VLOOKUP(Inscritos_SLOTSAB!$D46,Clasificaicon_Pilotos!$B$7:$M$91,13,0),0) -> 0 | F46: =IFERROR(VLOOKUP(C46,'Listado Pilotos y Equipos'!$B$3:$M$86,7,0),"") | G46: =IFERROR(VLOOKUP(Inscritos_SLOTSAB!$F46,Clasificaicon_Pilotos!$B$7:$M$91,13,0),0) -> 0 | H46: =IF(ISTEXT(E46),0,E46)+IF(ISTEXT(G46),0,G46) -> 0 | I46: =IFERROR(VLOOKUP(C46,'Listado Pilotos y Equipos'!$B$3:$P$86,12,0),"")
B47: 40 | D47: =IFERROR(VLOOKUP(C47,'Listado Pilotos y Equipos'!$B$3:$M$86,2,0),"") | E47: =IFERROR(VLOOKUP(Inscritos_SLOTSAB!$D47,Clasificaicon_Pilotos!$B$7:$M$91,13,0),0) -> 0 | F47: =IFERROR(VLOOKUP(C47,'Listado Pilotos y Equipos'!$B$3:$M$86,7,0),"") | G47: =IFERROR(VLOOKUP(Inscritos_SLOTSAB!$F47,Clasificaicon_Pilotos!$B$7:$M$91,13,0),0) -> 0 | H47: =IF(ISTEXT(E47),0,E47)+IF(ISTEXT(G47),0,G47) -> 0 | I47: =IFERROR(VLOOKUP(C47,'Listado Pilotos y Equipos'!$B$3:$P$86,12,0),"")
B48: 41 | D48: =IFERROR(VLOOKUP(C48,'Listado Pilotos y Equipos'!$B$3:$M$86,2,0),"") | E48: =IFERROR(VLOOKUP(Inscritos_SLOTSAB!$D48,Clasificaicon_Pilotos!$B$7:$M$91,13,0),0) -> 0 | F48: =IFERROR(VLOOKUP(C48,'Listado Pilotos y Equipos'!$B$3:$M$86,7,0),"") | G48: =IFERROR(VLOOKUP(Inscritos_SLOTSAB!$F48,Clasificaicon_Pilotos!$B$7:$M$96,13,0),0) -> 0 | H48: =IF(ISTEXT(E48),0,E48)+IF(ISTEXT(G48),0,G48) -> 0 | I48: =IFERROR(VLOOKUP(C48,'Listado Pilotos y Equipos'!$B$3:$P$86,12,0),"")
B49: 42 | D49: =IFERROR(VLOOKUP(C49,'Listado Pilotos y Equipos'!$B$3:$M$86,2,0),"") | E49: =IFERROR(VLOOKUP(Inscritos_SLOTSAB!$D49,Clasificaicon_Pilotos!$B$7:$M$91,13,0),0) -> 0 | F49: =IFERROR(VLOOKUP(C49,'Listado Pilotos y Equipos'!$B$3:$M$86,7,0),"") | G49: =IFERROR(VLOOKUP(Inscritos_SLOTSAB!$F49,Clasificaicon_Pilotos!$B$7:$M$91,13,0),0) -> 0 | H49: =IF(ISTEXT(E49),0,E49)+IF(ISTEXT(G49),0,G49) -> 0 | I49: =IFERROR(VLOOKUP(C49,'Listado Pilotos y Equipos'!$B$3:$P$86,12,0),"")
B50: 43 | D50: =IFERROR(VLOOKUP(C50,'Listado Pilotos y Equipos'!$B$3:$M$86,2,0),"") | E50: =IFERROR(VLOOKUP(Inscritos_SLOTSAB!$D50,Clasificaicon_Pilotos!$B$7:$M$91,13,0),0) -> 0 | F50: =IFERROR(VLOOKUP(C50,'Listado Pilotos y Equipos'!$B$3:$M$86,7,0),"") | G50: =IFERROR(VLOOKUP(Inscritos_SLOTSAB!$F50,Clasificaicon_Pilotos!$B$7:$M$91,13,0),0) -> 0 | H50: =IF(ISTEXT(E50),0,E50)+IF(ISTEXT(G50),0,G50) -> 0 | I50: =IFERROR(VLOOKUP(C50,'Listado Pilotos y Equipos'!$B$3:$P$86,12,0),"")
B51: 44 | D51: =IFERROR(VLOOKUP(C51,'Listado Pilotos y Equipos'!$B$3:$M$86,2,0),"") | E51: =IFERROR(VLOOKUP(Inscritos_SLOTSAB!$D51,Clasificaicon_Pilotos!$B$7:$M$91,13,0),0) -> 0 | F51: =IFERROR(VLOOKUP(C51,'Listado Pilotos y Equipos'!$B$3:$M$86,7,0),"") | G51: =IFERROR(VLOOKUP(Inscritos_SLOTSAB!$F51,Clasificaicon_Pilotos!$B$7:$M$91,13,0),0) -> 0 | H51: =IF(ISTEXT(E51),0,E51)+IF(ISTEXT(G51),0,G51) -> 0 | I51: =IFERROR(VLOOKUP(C51,'Listado Pilotos y Equipos'!$B$3:$P$86,12,0),"")

Sheet Verificaciones_SLOTSAB_OK
A7: DATOS COCHES PARTICIPANTES
A10: # | B10: EQUIPO | C10: COPA | D10: COCHE | E10: MOTOR | F10: PESO C. | G10: PESO MIN. | H10: PIÑÓN | I10: CORONA | J10: REL | K10: LLANTAS D | L10: DIAMETRO LL.D. | M10: LLANTAS T | N10: DIAMETRO LL.T. | O10: TRENC. | P10: SUSP. | Q10: BANCADA | R10: CHASIS | S10: NEUMATICOS | T10: PESO INICIO-FINAL | U10: OBS. VERIFICACIÓN
A11: 1 | B11: DZERO SOT | C11: =IFERROR(VLOOKUP(Verificaciones_SLOTSAB_OK!B11,'Listado Pilotos y Equipos'!$B$3:$P$86,12,0),"") -> SCALEAUTO_CUP | D11: CORVETTE | E11: 18 | F11: 17.04 | G11: =IF(D11="",0,IF(C11=Tabla_de_Datos_COPA_PALMARES!$B$3,VLOOKUP(D11,Tabla_de_Datos_COCHES!$B$21:$G$37,4,0),IF(C11=Tabla_de_Datos_COPA_PALMARES!$B$4,VLOOKUP(D11,Tabla_de_Datos_COCHES!$B$4:$G$20,4,0),IF(C11=Tabla_de_Datos_COPA_PALMARES!$B$5,VLOOKUP(D11,Tabla_de_Datos_COCHES!$B$38:$G$46,4,0))))) -> 17 | H11: SCA | I11: SCA | J11: 12_28 | K11: SIT | L11: 16,5 x 8 PL | M11: SCA | N11: 16,5 x 10 AL | O11: MB | P11: 0-0-I | Q11: SCA1 | R11: SCA | T11: 80,4-80,44
A12: 2 | B12: SLOTFOURMANIA | C12: =IFERROR(VLOOKUP(Verificaciones_SLOTSAB_OK!B12,'Listado Pilotos y Equipos'!$B$3:$P$86,12,0),"") -> GT2 | D12: HURACAN | E12: 33 | F12: 18.02 | G12: =IF(D12="",0,IF(C12=Tabla_de_Datos_COPA_PALMARES!$B$3,VLOOKUP(D12,Tabla_de_Datos_COCHES!$B$21:$G$37,4,0),IF(C12=Tabla_de_Datos_COPA_PALMARES!$B$4,VLOOKUP(D12,Tabla_de_Datos_COCHES!$B$4:$G$20,4,0),IF(C12=Tabla_de_Datos_COPA_PALMARES!$B$5,VLOOKUP(D12,Tabla_de_Datos_COCHES!$B$38:$G$46,4,0))))) -> 18 | H12: SIT | I12: SIT | J12: 12_30 | K12: SLP | L12: 15,8 x 8 AL | M12: SLP | N12: 16,9 x 10 AL | O12: MB | P12: 0-0-M | Q12: SIT05 | R12: SID | T12: 79,32-79,01
A13: 3 | B13: SLOTSAB JOOS | C13: =IFERROR(VLOOKUP(Verificaciones_SLOTSAB_OK!B13,'Listado Pilotos y Equipos'!$B$3:$P$86,12,0),"") -> SCALEAUTO_CUP | D13: MERCEDES | E13: 7 | F13: 18.25 | G13: =IF(D13="",0,IF(C13=Tabla_de_Datos_COPA_PALMARES!$B$3,VLOOKUP(D13,Tabla_de_Datos_COCHES!$B$21:$G$37,4,0),IF(C13=Tabla_de_Datos_COPA_PALMARES!$B$4,VLOOKUP(D13,Tabla_de_Datos_COCHES!$B$4:$G$20,4,0),IF(C13=Tabla_de_Datos_COPA_PALMARES!$B$5,VLOOKUP(D13,Tabla_de_Datos_COCHES!$B$38:$G$46,4,0))))) -> 17 | H13: SCA | I13: SCA | J13: 12_28 | K13: SCA | L13: 15,8 x 8 AL | M13: SCA | N13: 16,5 x 10 AL | O13: SLP | P13: 0-0-I | Q13: SCA1 | R13: SCA | T13: 81,42-81,52
A14: 4 | B14: NOUTEAM SLOT_ | C14: =IFERROR(VLOOKUP(Verificaciones_SLOTSAB_OK!B14,'Listado Pilotos y Equipos'!$B$3:$P$86,12,0),"") -> GT2 | D14: BLACKBULL | E14: 11 | F14: 16.02 | G14: =IF(D14="",0,IF(C14=Tabla_de_Datos_COPA_PALMARES!$B$3,VLOOKUP(D14,Tabla_de_Datos_COCHES!$B$21:$G$37,4,0),IF(C14=Tabla_de_Datos_COPA_PALMARES!$B$4,VLOOKUP(D14,Tabla_de_Datos_COCHES!$B$4:$G$20,4,0),IF(C14=Tabla_de_Datos_COPA_PALMARES!$B$5,VLOOKUP(D14,Tabla_de_Datos_COCHES!$B$38:$G$46,4,0))))) -> 15.5 | H14: SLP | I14: SIT | J14: 12_30 | K14: SLP | L14: 15,8 x 8 AL | M14: SIT | N14: 15,8 x 10 AL | O14: MB | P14: M-M-M | Q14: BLA05 | R14: BLA | T14: 77,80-77,85 | U14: CORONA DE 29
A16: 6 | B16: SAB ARRAS | C16: =IFERROR(VLOOKUP(Verificaciones_SLOTSAB_OK!B16,'Listado Pilotos y Equipos'!$B$3:$P$86,12,0),"") -> SCALEAUTO_CUP | D16: VIPER | E16: 1 | F16: 17.14 | G16: =IF(D16="",0,IF(C16=Tabla_de_Datos_COPA_PALMARES!$B$3,VLOOKUP(D16,Tabla_de_Datos_COCHES!$B$21:$G$37,4,0),IF(C16=Tabla_de_Datos_COPA_PALMARES!$B$4,VLOOKUP(D16,Tabla_de_Datos_COCHES!$B$4:$G$20,4,0),IF(C16=Tabla_de_Datos_COPA_PALMARES!$B$5,VLOOKUP(D16,Tabla_de_Datos_COCHES!$B$38:$G$46,4,0))))) -> 17 | H16: SCA | I16: SCA | J16: 12_28 | K16: SCA | L16: 15,8 x 8 AL | M16: SCA | N16: 16,5 x 10 AL | O16: MB | P16: 0-0-M | Q16: SCA1 | R16: SCA | T16: 79,36-79,89
C17: =IFERROR(VLOOKUP(Verificaciones_SLOTSAB_OK!B17,'Listado Pilotos y Equipos'!$B$3:$P$86,12,0),"") | G17: =IF(D17="",0,IF(C17=Tabla_de_Datos_COPA_PALMARES!$B$3,VLOOKUP(D17,Tabla_de_Datos_COCHES!$B$21:$G$37,4,0),IF(C17=Tabla_de_Datos_COPA_PALMARES!$B$4,VLOOKUP(D17,Tabla_de_Datos_COCHES!$B$4:$G$20,4,0),IF(C17=Tabla_de_Datos_COPA_PALMARES!$B$5,VLOOKUP(D17,Tabla_de_Datos_COCHES!$B$38:$G$46,4,0))))) -> 0
A18: 7 | B18: EL SOT CALAVERAS | C18: =IFERROR(VLOOKUP(Verificaciones_SLOTSAB_OK!B18,'Listado Pilotos y Equipos'!$B$3:$P$86,12,0),"") -> GT2 | D18: HURACAN | E18: 43 | F18: 18.15 | G18: =IF(D18="",0,IF(C18=Tabla_de_Datos_COPA_PALMARES!$B$3,VLOOKUP(D18,Tabla_de_Datos_COCHES!$B$21:$G$37,4,0),IF(C18=Tabla_de_Datos_COPA_PALMARES!$B$4,VLOOKUP(D18,Tabla_de_Datos_COCHES!$B$4:$G$20,4,0),IF(C18=Tabla_de_Datos_COPA_PALMARES!$B$5,VLOOKUP(D18,Tabla_de_Datos_COCHES!$B$38:$G$46,4,0))))) -> 18 | H18: SIT | I18: SIT | J18: 12_30 | K18: SCA | L18: 15,8 x 8 PL | M18: SLP | N18: 16,9 x 10 AL | O18: SLP | P18: 0-M-I | Q18: SIT1 | R18: SID | T18: 78,32-78.32
A19: 8 | B19: SLOT4YOU CUIDADIN | C19: =IFERROR(VLOOKUP(Verificaciones_SLOTSAB_OK!B19,'Listado Pilotos y Equipos'!$B$3:$P$86,12,0),"") -> SCALEAUTO_CUP | D19: VIPER | E19: 47 | F19: 17.01 | G19: =IF(D19="",0,IF(C19=Tabla_de_Datos_COPA_PALMARES!$B$3,VLOOKUP(D19,Tabla_de_Datos_COCHES!$B$21:$G$37,4,0),IF(C19=Tabla_de_Datos_COPA_PALMARES!$B$4,VLOOKUP(D19,Tabla_de_Datos_COCHES!$B$4:$G$20,4,0),IF(C19=Tabla_de_Datos_COPA_PALMARES!$B$5,VLOOKUP(D19,Tabla_de_Datos_COCHES!$B$38:$G$46,4,0))))) -> 17 | H19: SIT | I19: SCA | J19: 12_28 | K19: SIT | L19: 15,8 x 8 PL | M19: SCA | N19: 16,5 x 10 AL | O19: SCA | P19: 0-0-M | Q19: SCA1 | R19: SCA | T19: 80,72-80,67
A20: 9 | B20: ESTEL·LATS | C20: =IFERROR(VLOOKUP(Verificaciones_SLOTSAB_OK!B20,'Listado Pilotos y Equipos'!$B$3:$P$86,12,0),"") -> RESISBARNA | D20: SPYKER | E20: 59 | F20: 15.12 | G20: =IF(D20="",0,IF(C20=Tabla_de_Datos_COPA_PALMARES!$B$3,VLOOKUP(D20,Tabla_de_Datos_COCHES!$B$21:$G$37,4,0),IF(C20=Tabla_de_Datos_COPA_PALMARES!$B$4,VLOOKUP(D20,Tabla_de_Datos_COCHES!$B$4:$G$20,4,0),IF(C20=Tabla_de_Datos_COPA_PALMARES!$B$5,VLOOKUP(D20,Tabla_de_Datos_COCHES!$B$38:$G$46,4,0))))) -> 15 | H20: SLP | I20: SID | J20: 12_28 | K20: SCA | L20: 15,8 x 8 AL | M20: SLP | N20: 16,9 x 10 AL | O20: SCA | P20: 0-0-I | Q20: SIT1 | R20: SCA | T20: 75,40-75.22
A21: 10 | B21: SLOTSAB JUNIOR | C21: =IFERROR(VLOOKUP(Verificaciones_SLOTSAB_OK!B21,'Listado Pilotos y Equipos'!$B$3:$P$86,12,0),"") -> SCALEAUTO_CUP | D21: VIPER | E21: 31 | F21: 17 | G21: =IF(D21="",0,IF(C21=Tabla_de_Datos_COPA_PALMARES!$B$3,VLOOKUP(D21,Tabla_de_Datos_COCHES!$B$21:$G$37,4,0),IF(C21=Tabla_de_Datos_COPA_PALMARES!$B$4,VLOOKUP(D21,Tabla_de_Datos_COCHES!$B$4:$G$20,4,0),IF(C21=Tabla_de_Datos_COPA_PALMARES!$B$5,VLOOKUP(D21,Tabla_de_Datos_COCHES!$B$38:$G$46,4,0))))) -> 17 | H21: SCA | I21: SCA | J21: 12_28 | K21: SLP | L21: 15,8 x 8 PL | M21: SCA | N21: 16,5 x 10 AL | O21: MB | P21: 0-0-I | Q21: SCA1 | R21: SCA | T21: 77,67-77,55
A22: 11 | B22: TOAD TEAM | C22: =IFERROR(VLOOKUP(Verificaciones_SLOTSAB_OK!B22,'Listado Pilotos y Equipos'!$B$3:$P$86,12,0),"") -> GT2 | D22: VIPER | E22: 52 | F22: 17.02 | G22: =IF(D22="",0,IF(C22=Tabla_de_Datos_COPA_PALMARES!$B$3,VLOOKUP(D22,Tabla_de_Datos_COCHES!$B$21:$G$37,4,0),IF(C22=Tabla_de_Datos_COPA_PALMARES!$B$4,VLOOKUP(D22,Tabla_de_Datos_COCHES!$B$4:$G$20,4,0),IF(C22=Tabla_de_Datos_COPA_PALMARES!$B$5,VLOOKUP(D22,Tabla_de_Datos_COCHES!$B$38:$G$46,4,0))))) -> 17 | H22: SIT | I22: SIT | J22: 12_30 | K22: SLP | L22: 15,8 x 8 NY | M22: SLP | N22: 16,5 x 10 AL | O22: MB | P22: 0-0-M | Q22: SCA1 | R22: SCA | T22: 78,37-78.34
A23: 12 | B23: SLOTMANIA CAR | C23: =IFERROR(VLOOKUP(Verificaciones_SLOTSAB_OK!B23,'Listado Pilotos y Equipos'!$B$3:$P$86,12,0),"") -> RESISBARNA | D23: FORD GT | E23: 8 | F23: 18.37 | G23: =IF(D23="",0,IF(C23=Tabla_de_Datos_COPA_PALMARES!$B$3,VLOOKUP(D23,Tabla_de_Datos_COCHES!$B$21:$G$37,4,0),IF(C23=Tabla_de_Datos_COPA_PALMARES!$B$4,VLOOKUP(D23,Tabla_de_Datos_COCHES!$B$4:$G$20,4,0),IF(C23=Tabla_de_Datos_COPA_PALMARES!$B$5,VLOOKUP(D23,Tabla_de_Datos_COCHES!$B$38:$G$46,4,0))))) -> 18 | H23: SIT | I23: SIT | J23: 12_28 | K23: SLP | L23: 15,8 x 8 AL | M23: SLP | N23: 17,2 x 10 AL | O23: MB | P23: 0-0-I | Q23: SIT1 | R23: MR | T23: 77,51-77.54
A24: 13 | B24: EQUIP VALLES | C24: =IFERROR(VLOOKUP(Verificaciones_SLOTSAB_OK!B24,'Listado Pilotos y Equipos'!$B$3:$P$86,12,0),"") -> RESISBARNA | D24: CORVETTE | E24: 25 | F24: 17.02 | G24: =IF(D24="",0,IF(C24=Tabla_de_Datos_COPA_PALMARES!$B$3,VLOOKUP(D24,Tabla_de_Datos_COCHES!$B$21:$G$37,4,0),IF(C24=Tabla_de_Datos_COPA_PALMARES!$B$4,VLOOKUP(D24,Tabla_de_Datos_COCHES!$B$4:$G$20,4,0),IF(C24=Tabla_de_Datos_COPA_PALMARES!$B$5,VLOOKUP(D24,Tabla_de_Datos_COCHES!$B$38:$G$46,4,0))))) -> 17 | H24: SLP | I24: SIT | J24: 12_28 | K24: SIT | L24: 15,8 x 8 PL | M24: SLP | N24: 16,5 x 10 AL | O24: MB | P24: 0-0-I | Q24: SIT1 | R24: SCA | T24: 77,63-77.58
A25: 14 | B25: CRONO1_ | C25: =IFERROR(VLOOKUP(Verificaciones_SLOTSAB_OK!B25,'Listado Pilotos y Equipos'!$B$3:$P$86,12,0),"") -> SCALEAUTO_CUP | D25: VIPER | E25: 56 | F25: 17 | G25: =IF(D25="",0,IF(C25=Tabla_de_Datos_COPA_PALMARES!$B$3,VLOOKUP(D25,Tabla_de_Datos_COCHES!$B$21:$G$37,4,0),IF(C25=Tabla_de_Datos_COPA_PALMARES!$B$4,VLOOKUP(D25,Tabla_de_Datos_COCHES!$B$4:$G$20,4,0),IF(C25=Tabla_de_Datos_COPA_PALMARES!$B$5,VLOOKUP(D25,Tabla_de_Datos_COCHES!$B$38:$G$46,4,0))))) -> 17 | H25: SIT | I25: SCA | J25: 12_28 | K25: SCA | L25: 15,8 x 8 AL | M25: SCA | N25: 17,2 x 8 AL | O25: BLA | P25: 0-0-M | Q25: SCA075 | R25: SCA | T25: 80,23-80.14
C26: =IFERROR(VLOOKUP(Verificaciones_SLOTSAB_OK!B26,'Listado Pilotos y Equipos'!$B$3:$P$86,12,0),"")
A27: 15 | B27: SLOTMANIA | C27: =IFERROR(VLOOKUP(Verificaciones_SLOTSAB_OK!B27,'Listado Pilotos y Equipos'!$B$3:$P$86,12,0),"") -> RESISBARNA | D27: BLACKBULL | E27: 15 | F27: 15 | G27: =IF(D27="",0,IF(C27=Tabla_de_Datos_COPA_PALMARES!$B$3,VLOOKUP(D27,Tabla_de_Datos_COCHES!$B$21:$G$37,4,0),IF(C27=Tabla_de_Datos_COPA_PALMARES!$B$4,VLOOKUP(D27,Tabla_de_Datos_COCHES!$B$4:$G$20,4,0),IF(C27=Tabla_de_Datos_COPA_PALMARES!$B$5,VLOOKUP(D27,Tabla_de_Datos_COCHES!$B$38:$G$46,4,0))))) -> 15.5 | H27: SCA | I27: SIT | J27: 12_27 | K27: SLP | L27: 15,8 x 8 AL | M27: SIT | N27: 15,8 x 10 AL | O27: MB | P27: I-M-M | Q27: BLA05 | R27: BLA | T27: 76,03-76,03
A28: 16 | B28: EL SOT FU | C28: =IFERROR(VLOOKUP(Verificaciones_SLOTSAB_OK!B28,'Listado Pilotos y Equipos'!$B$3:$P$86,12,0),"") -> RESISBARNA | D28: BMW M6 | E28: 30 | F28: 19.46 | G28: =IF(D28="",0,IF(C28=Tabla_de_Datos_COPA_PALMARES!$B$3,VLOOKUP(D28,Tabla_de_Datos_COCHES!$B$21:$G$37,4,0),IF(C28=Tabla_de_Datos_COPA_PALMARES!$B$4,VLOOKUP(D28,Tabla_de_Datos_COCHES!$B$4:$G$20,4,0),IF(C28=Tabla_de_Datos_COPA_PALMARES!$B$5,VLOOKUP(D28,Tabla_de_Datos_COCHES!$B$38:$G$46,4,0))))) -> 18 | H28: SIT | I28: SID | J28: 12_28 | K28: SIT | L28: 15,8 x 8 PL | M28: SLP | N28: 16,9 x 10 AL | O28: SIT | P28: 0-0-I | Q28: SIT1 | R28: SID | T28: 81,1-80,99
A29: 17 | B29: EL SOT TEAM | C29: =IFERROR(VLOOKUP(Verificaciones_SLOTSAB_OK!B29,'Listado Pilotos y Equipos'!$B$3:$P$86,12,0),"") -> SCALEAUTO_CUP | D29: VIPER | E29: 45 | F29: 17 | G29: =IF(D29="",0,IF(C29=Tabla_de_Datos_COPA_PALMARES!$B$3,VLOOKUP(D29,Tabla_de_Datos_COCHES!$B$21:$G$37,4,0),IF(C29=Tabla_de_Datos_COPA_PALMARES!$B$4,VLOOKUP(D29,Tabla_de_Datos_COCHES!$B$4:$G$20,4,0),IF(C29=Tabla_de_Datos_COPA_PALMARES!$B$5,VLOOKUP(D29,Tabla_de_Datos_COCHES!$B$38:$G$46,4,0))))) -> 17 | H29: SIT | I29: SCA | J29: 12_28 | K29: SIT | L29: 15,8 x 8 PL | M29: SCA | N29: 16,5 x 8 AL | O29: MB | P29: 0-0-M | Q29: SCA1 | R29: SCA | T29: 79-14-79,26
A30: 18 | B30: EL SOT HORTA | C30: =IFERROR(VLOOKUP(Verificaciones_SLOTSAB_OK!B30,'Listado Pilotos y Equipos'!$B$3:$P$86,12,0),"") -> RESISBARNA | D30: SPYKER | E30: 37 | F30: 15.14 | G30: =IF(D30="",0,IF(C30=Tabla_de_Datos_COPA_PALMARES!$B$3,VLOOKUP(D30,Tabla_de_Datos_COCHES!$B$21:$G$37,4,0),IF(C30=Tabla_de_Datos_COPA_PALMARES!$B$4,VLOOKUP(D30,Tabla_de_Datos_COCHES!$B$4:$G$20,4,0),IF(C30=Tabla_de_Datos_COPA_PALMARES!$B$5,VLOOKUP(D30,Tabla_de_Datos_COCHES!$B$38:$G$46,4,0))))) -> 15 | H30: SIT | I30: SID | J30: 12_28 | K30: SLP | L30: 15,8 x 8 NY | M30: SLP | N30: 16,9 x 10 AL | O30: MB | P30: 0-0-I | Q30: SIT1 | R30: SCA | T30: 74,10-74,18
A31: 19 | B31: HOT SLOT FOR YOU | C31: =IFERROR(VLOOKUP(Verificaciones_SLOTSAB_OK!B31,'Listado Pilotos y Equipos'!$B$3:$P$86,12,0),"") -> RESISBARNA | D31: HURACAN | E31: 42 | F31: 18 | G31: =IF(D31="",0,IF(C31=Tabla_de_Datos_COPA_PALMARES!$B$3,VLOOKUP(D31,Tabla_de_Datos_COCHES!$B$21:$G$37,4,0),IF(C31=Tabla_de_Datos_COPA_PALMARES!$B$4,VLOOKUP(D31,Tabla_de_Datos_COCHES!$B$4:$G$20,4,0),IF(C31=Tabla_de_Datos_COPA_PALMARES!$B$5,VLOOKUP(D31,Tabla_de_Datos_COCHES!$B$38:$G$46,4,0))))) -> 18 | H31: SLP | I31: MR | J31: 12_28 | K31: SIT | L31: 15,8 x 8 PL | M31: SLP | N31: 16,5 x 10 AL | O31: SCA | P31: 0-0-0 | Q31: SIT1 | R31: SID | T31: 76,73-76,79
A32: 20 | B32: SLOTFORYOU | C32: =IFERROR(VLOOKUP(Verificaciones_SLOTSAB_OK!B32,'Listado Pilotos y Equipos'!$B$3:$P$86,12,0),"") -> RESISBARNA | D32: BMW M6 | E32: 9 | F32: 18.75 | G32: =IF(D32="",0,IF(C32=Tabla_de_Datos_COPA_PALMARES!$B$3,VLOOKUP(D32,Tabla_de_Datos_COCHES!$B$21:$G$37,4,0),IF(C32=Tabla_de_Datos_COPA_PALMARES!$B$4,VLOOKUP(D32,Tabla_de_Datos_COCHES!$B$4:$G$20,4,0),IF(C32=Tabla_de_Datos_COPA_PALMARES!$B$5,VLOOKUP(D32,Tabla_de_Datos_COCHES!$B$38:$G$46,4,0))))) -> 18 | H32: MR | I32: SID | J32: 12_28 | K32: SLP | L32: 15,8 x 8 PL | M32: SLP | N32: 16,9 x 10 AL | O32: MB | P32: 0-0-I | Q32: SIT1 | R32: SID | T32: 78,76-78,73
A33: 21 | B33: STP RACING | C33: =IFERROR(VLOOKUP(Verificaciones_SLOTSAB_OK!B33,'Listado Pilotos y Equipos'!$B$3:$P$86,12,0),"") -> RESISBARNA | G33: =IF(D33="",0,IF(C33=Tabla_de_Datos_COPA_PALMARES!$B$3,VLOOKUP(D33,Tabla_de_Datos_COCHES!$B$21:$G$37,4,0),IF(C33=Tabla_de_Datos_COPA_PALMARES!$B$4,VLOOKUP(D33,Tabla_de_Datos_COCHES!$B$4:$G$20,4,0),IF(C33=Tabla_de_Datos_COPA_PALMARES!$B$5,VLOOKUP(D33,Tabla_de_Datos_COCHES!$B$38:$G$46,4,0))))) -> 0
